Workbook
Name afril: #REF!
Name BS: #REF!
Name costaa: #REF!
Name F: #REF!
Name fs: #REF!
Name GGGG: #REF!
Name groupincome: #REF!
Name MANS: #REF!
Name OLDMAN: #REF!
Name PAC: #REF!
Name PL: #REF!
Name REGISTRAR: #REF!
Name SCHD3: #REF!
Name SCHED1: #REF!
Name SCHED2: #REF!
Name SCHED3: #REF!
Name SCHED4: #REF!
Name SEMI: #REF!
Name SSES: #REF!
Name SUMMARY: #REF!
Name yyy: #REF!

Sheet Assumption-(MedSupplies)
B1: Assumptions-Inputs
D3: Jan | E3: Feb | F3: Mar | G3: Apr | H3: May | I3: Jun | J3: Jul | K3: Aug | L3: Sep | M3: Oct | N3: Nov | O3: Dec | P3: Total
B4: Live_Case
B5: Wellness Packages | D5: =SUM(D6:D11) -> 0 | E5: =SUM(E6:E11) -> 0 | F5: =SUM(F6:F11) -> 0 | G5: =SUM(G6:G11) -> 0 | H5: =SUM(H6:H11) -> 0 | I5: =SUM(I6:I11) -> 0 | J5: =SUM(J6:J11) -> 0 | K5: =SUM(K6:K11) -> 0 | ... O5: =SUM(O6:O11) -> 0 | P5: =SUM(D5:O5) -> 0
B6: IV micronutrient Therapy (Vitamins, Amino Acids,(in clinic & Home) | D6: =D26*D46 -> 0 | E6: =E46*E26 -> 0 | F6: =F46*F26 -> 0 | G6: =G46*G26 -> 0 | H6: =H46*H26 -> 0 | I6: =I46*I26 -> 0 | J6: =J46*J26 -> 0 | K6: =K46*K26 -> 0 | L6: =L46*L26 -> 0 | ... O6: =O46*O26 -> 0 | P6: =SUM(D6:O6) -> 0
B7: IV micronutrient Therapy Weight loss (Slim boost(in clinic & Home) | D7: =D27*D47 -> 0 | E7: =E47*E27 -> 0 | F7: =F47*F27 -> 0 | G7: =G47*G27 -> 0 | H7: =H47*H27 -> 0 | I7: =I47*I27 -> 0 | J7: =J47*J27 -> 0 | K7: =K47*K27 -> 0 | L7: =L47*L27 -> 0 | ... O7: =O47*O27 -> 0 | P7: =SUM(D7:O7) -> 0
B8: Weight loss programs (Meal Plans, etc) | D8: =D28*D48 -> 0 | E8: =E48*E28 -> 0 | F8: =F48*F28 -> 0 | G8: =G48*G28 -> 0 | H8: =H48*H28 -> 0 | I8: =I48*I28 -> 0 | J8: =J48*J28 -> 0 | K8: =K48*K28 -> 0 | L8: =L48*L28 -> 0 | ... O8: =O48*O28 -> 0 | P8: =SUM(D8:O8) -> 0
B9: Medical Weight loss programs (Mounjaro, etc) | D9: =D29*D49 -> 0 | E9: =E29*E49 -> 0 | F9: =F29*F49 -> 0 | G9: =G29*G49 -> 0 | H9: =H29*H49 -> 0 | I9: =I29*I49 -> 0 | J9: =J29*J49 -> 0 | K9: =K29*K49 -> 0 | ... O9: =O29*O49 -> 0 | P9: =SUM(D9:O9) -> 0
B13: Medsupplies | D13: =SUM(D14:D21) -> 36000000 | E13: =SUM(E14:E21) -> 36000000 | F13: =SUM(F14:F21) -> 248000000 | G13: =SUM(G14:G21) -> 36000000 | H13: =SUM(H14:H21) -> 36000000 | I13: =SUM(I14:I21) -> 248000000 | J13: =SUM(J14:J21) -> 36000000 | K13: =SUM(K14:K21) -> 36000000 | ... P13: =SUM(P14:P21) -> 1280000000
B14: Revenue - Medical Supplies | D14: =D34*D54 -> 12000000 | E14: =E34*E54 -> 12000000 | F14: =F34*F54 -> 12000000 | G14: =G34*G54 -> 12000000 | H14: =H34*H54 -> 12000000 | I14: =I34*I54 -> 12000000 | J14: =J34*J54 -> 12000000 | K14: =K34*K54 -> 12000000 | ... O14: =O34*O54 -> 12000000 | P14: =SUM(D14:O14) -> 144000000
B15: Revenue - Medbury Intergrated Services - Non Medicals Supplies | D15: =D35*D55 -> 0 | E15: =E35*E55 -> 0 | F15: =F35*F55 -> 50000000 | G15: =G35*G55 -> 0 | H15: =H35*H55 -> 0 | I15: =I35*I55 -> 50000000 | J15: =J35*J55 -> 0 | K15: =K35*K55 -> 0 | ... O15: =O35*O55 -> 50000000 | P15: =SUM(D15:O15) -> 200000000
B16: Revenue - Supply of Drugs | D16: =D36*D56 -> 24000000 | E16: =E36*E56 -> 24000000 | F16: =F36*F56 -> 24000000 | G16: =G36*G56 -> 24000000 | H16: =H36*H56 -> 24000000 | I16: =I36*I56 -> 24000000 | J16: =J36*J56 -> 24000000 | K16: =K36*K56 -> 24000000 | ... O16: =O36*O56 -> 24000000 | P16: =SUM(D16:O16) -> 288000000
B17: Revenue - Supply of Equipments & Machineries | D17: =D37*D57 -> 0 | E17: =E37*E57 -> 0 | F17: =F37*F57 -> 27000000 | G17: =G37*G57 -> 0 | H17: =H37*H57 -> 0 | I17: =I37*I57 -> 27000000 | J17: =J37*J57 -> 0 | K17: =K37*K57 -> 0 | ... O17: =O37*O57 -> 27000000 | P17: =SUM(D17:O17) -> 108000000
B18: Revenue- PPEs | D18: =D38*D57 -> 0 | E18: =E38*E57 -> 0 | F18: =F38*F57 -> 135000000 | G18: =G38*G57 -> 0 | H18: =H38*H57 -> 0 | I18: =I38*I57 -> 135000000 | J18: =J38*J57 -> 0 | K18: =K38*K57 -> 0 | ... O18: =O38*O57 -> 135000000 | P18: =SUM(D18:O18) -> 540000000
B19: Revenue- In- House Sales (Project) | D19: =D39*D58*0 -> 0 | E19: =E39*E58*0 -> 0 | F19: =F39*F58*0 -> 0 | G19: =G39*G58*0 -> 0 | H19: =H39*H58*0 -> 0 | I19: =I39*I58*0 -> 0 | J19: =J39*J58*0 -> 0 | K19: =K39*K58*0 -> 0 | ... O19: =O39*O58*0 -> 0 | P19: =SUM(D19:O19) -> 0
B20: Revenue- In- House Sales | D20: =D40*D59*0 -> 0 | E20: =E40*E59*0 -> 0 | F20: =F40*F59*0 -> 0 | G20: =G40*G59*0 -> 0 | H20: =H40*H59*0 -> 0 | I20: =I40*I59*0 -> 0 | J20: =J40*J59*0 -> 0 | K20: =K40*K59*0 -> 0 | ... O20: =O40*O59*0 -> 0 | P20: =SUM(D20:O20) -> 0
B24: Average no of Patient
B25: Wellness Packages
B26: IV micronutrient Therapy (Vitamins, Amino Acids,(in clinic & Home) | P26: =SUM(D26:O26) -> 0 | R26: 30 | S26: 31 | T26: 32 | V26: 33 | W26: 34 | X26: 35 | Y26: 36 | Z26: 37 | AA26: 38 | AB26: 39 | AC26: 40 | AD26: 41
B27: IV micronutrient Therapy Weight loss (Slim boost(in clinic & Home) | P27: =SUM(D27:O27) -> 0 | R27: 30 | S27: 30 | T27: 30 | V27: 30 | W27: 30 | X27: 30 | Y27: 30 | Z27: 30 | AA27: 30 | AB27: 30 | AC27: 30 | AD27: 30
B28: Weight loss programs (Meal Plans, etc) | P28: =SUM(D28:O28) -> 0 | R28: 30 | S28: 30 | T28: 30 | V28: 30 | W28: 30 | X28: 30 | Y28: 30 | Z28: 30 | AA28: 30 | AB28: 30 | AC28: 30 | AD28: 30
B29: Medical Weight loss programs (Mounjaro, etc) | P29: =SUM(D29:O29) -> 0 | R29: 20 | S29: 20 | T29: 20 | V29: 20 | W29: 20 | X29: 20 | Y29: 20 | Z29: 20 | AA29: 20 | AB29: 20 | AC29: 20 | AD29: 20
B33: Medsupplies
B34: Revenue - Medical Supplies | D34: 6 | E34: =D34 -> 6 | F34: =E34 -> 6 | G34: =F34 -> 6 | H34: =G34 -> 6 | I34: =H34 -> 6 | J34: =I34 -> 6 | K34: =J34 -> 6 | L34: =K34 -> 6 | ... O34: =N34 -> 6 | P34: =SUM(D34:O34) -> 72 | R34: =(P34-2358)/2358 -> -0.96946565 | S34: =P34/1.3 -> 55.384615
B35: Revenue - Medbury Intergrated Services - Non Medicals Supplies | F35: 1 | I35: 1 | L35: 1 | O35: 1 | P35: =SUM(D35:O35) -> 4 | R35: =(P35-1729)/1729 -> -0.99768652 | S35: =P35/1.3 -> 3.0769231
B36: Revenue - Supply of Drugs | D36: 6 | E36: =D36 -> 6 | F36: =E36 -> 6 | G36: =F36 -> 6 | H36: =G36 -> 6 | I36: =H36 -> 6 | J36: =I36 -> 6 | K36: =J36 -> 6 | L36: =K36 -> 6 | ... O36: =N36 -> 6 | P36: =SUM(D36:O36) -> 72 | R36: =(P36-315)/315 -> -0.77142857 | S36: =P36/1.3 -> 55.384615
B37: Revenue - Supply of Equipments & Machineries | F37: 1 | I37: 1 | L37: 1 | O37: 1 | P37: =SUM(D37:O37) -> 4 | S37: =P37/1.3 -> 3.0769231 | T37: 50
B38: Revenue- PPEs | D38: 5 | E38: 5 | F38: 5 | G38: 5 | H38: 5 | I38: 5 | J38: 5 | K38: 5 | L38: 5 | M38: 5 | N38: 5 | O38: 5 | P38: =SUM(D38:O38) -> 60 | S38: =P38/1.3 -> 46.153846 | T38: 60
B39: Revenue- In- House Sales (Project) | D39: 1 | E39: 1 | F39: 1 | G39: 1 | H39: 1 | I39: 1 | J39: 1 | K39: 1 | L39: 1 | M39: 1 | N39: 1 | O39: 1 | P39: =SUM(D39:O39) -> 12 | R39: =(P39-379)/379 -> -0.96833773 | S39: =P39/1.3 -> 9.2307692 | T39: 120
B40: Revenue- In- House Sales | D40: 1 | E40: 1 | F40: 1 | G40: 1 | H40: 1 | I40: 1 | J40: 1 | K40: 1 | L40: 1 | M40: 1 | N40: 1 | O40: 1 | P40: =SUM(D40:O40) -> 12 | S40: =P40/1.3 -> 9.2307692 | T40: 80
B44: Average case - Price
B45: Corporate | D45: Average price spent per person
B46: IV micronutrient Therapy (Vitamins, Amino Acids,(in clinic & Home) | R46: 200000 | S46: =R46 -> 200000 | T46: =S46 -> 200000 | V46: =T46 -> 200000 | W46: =V46 -> 200000 | X46: =W46 -> 200000 | Y46: =X46 -> 200000 | Z46: =Y46 -> 200000 | AA46: =Z46 -> 200000 | AB46: =AA46 -> 200000 | AC46: =AB46 -> 200000 | AD46: =AC46 -> 200000
B47: IV micronutrient Therapy Weight loss (Slim boost(in clinic & Home) | R47: 100000 | S47: =R47 -> 100000 | T47: =S47 -> 100000 | V47: =T47 -> 100000 | W47: =V47 -> 100000 | X47: =W47 -> 100000 | Y47: =X47 -> 100000 | Z47: =Y47 -> 100000 | AA47: =Z47 -> 100000 | AB47: =AA47 -> 100000 | AC47: =AB47 -> 100000 | AD47: =AC47 -> 100000
B48: Weight loss programs (Meal Plans, etc) | R48: 50000 | S48: 50000 | T48: 50000 | V48: 50000 | W48: 50000 | X48: 50000 | Y48: 50000 | Z48: 50000 | AA48: 50000 | AB48: 50000 | AC48: 50000 | AD48: 50000
B49: Medical Weight loss programs (Mounjaro, etc) | R49: 2000000 | S49: 2000000 | T49: 2000000 | V49: 2000000 | W49: 2000000 | X49: 2000000 | Y49: 2000000 | Z49: 2000000 | AA49: 2000000 | AB49: 2000000 | AC49: 2000000 | AD49: 2000000
D53: Average price per case
B54: Revenue - Medical Supplies | D54: 2000000 | E54: =D54 -> 2000000 | F54: =E54 -> 2000000 | G54: =F54 -> 2000000 | H54: =G54 -> 2000000 | I54: =H54 -> 2000000 | J54: =I54 -> 2000000 | K54: =J54 -> 2000000 | L54: =K54 -> 2000000 | ... O54: =N54 -> 2000000 | P54: =SUM(D54:O54) -> 24000000
B55: Revenue - Medbury Intergrated Services - Non Medicals Supplies | F55: 50000000 | I55: =F55 -> 50000000 | L55: =I55 -> 50000000 | O55: =F55 -> 50000000 | P55: =SUM(D55:O55) -> 200000000
B56: Revenue - Supply of Drugs | D56: 4000000 | E56: =D56 -> 4000000 | F56: =E56 -> 4000000 | G56: =F56 -> 4000000 | H56: =G56 -> 4000000 | I56: =H56 -> 4000000 | J56: =I56 -> 4000000 | K56: =J56 -> 4000000 | L56: =K56 -> 4000000 | ... O56: =N56 -> 4000000 | P56: =SUM(D56:O56) -> 48000000
...

Sheet Computations-(MedSupplies)
A2: Computations-Outputs
D3: Jan | E3: Feb | F3: Mar | G3: Apr | H3: May | I3: Jun | J3: Jul | K3: Aug | L3: Sep | M3: Oct | N3: Nov | O3: Dec | P3: FY 1 | Q3: FY 2 | R3: FY 3 | S3: FY 4 | T3: FY 5
D4: ₦ | E4: ₦ | F4: ₦ | G4: ₦ | H4: ₦ | I4: ₦ | J4: ₦ | K4: ₦ | L4: ₦ | M4: ₦ | N4: ₦ | O4: ₦ | P4: NGN | Q4: NGN | R4: NGN | S4: NGN | T4: NGN
B5: Revenue
B6: ='Assumption-(MedSupplies)'!B13 -> Medsupplies | D6: ='Assumption-(MedSupplies)'!D13 -> 36000000 | E6: ='Assumption-(MedSupplies)'!E13 -> 36000000 | F6: ='Assumption-(MedSupplies)'!F13 -> 248000000 | G6: ='Assumption-(MedSupplies)'!G13 -> 36000000 | H6: ='Assumption-(MedSupplies)'!H13 -> 36000000 | I6: ='Assumption-(MedSupplies)'!I13 -> 248000000 | J6: ='Assumption-(MedSupplies)'!J13 -> 36000000 | K6: ='Assumption-(MedSupplies)'!K13 -> 36000000 | ... O6: ='Assumption-(MedSupplies)'!O13 -> 248000000 | P6: =SUM(D6:O6) -> 1280000000 | Q6: =P6*(1+'Assumption-(MedSupplies)'!E$66)*(1+'Assumption-(MedSupplies)'!E$69) -> 1766400000 | R6: =Q6*(1+'Assumption-(MedSupplies)'!F$66)*(1+'Assumption-(MedSupplies)'!F$69) -> 2.437632e+09 | S6: =R6*(1+'Assumption-(MedSupplies)'!G$66)*(1+'Assumption-(MedSupplies)'!G$69) -> 3.3639322e+09 | T6: =S6*(1+'Assumption-(MedSupplies)'!H$66)*(1+'Assumption-(MedSupplies)'!H$69) -> 4.6422264e+09
B8: Total Revenue | D8: =SUM(D6:D6) -> 36000000 | E8: =SUM(E6:E6) -> 36000000 | F8: =SUM(F6:F6) -> 248000000 | G8: =SUM(G6:G6) -> 36000000 | H8: =SUM(H6:H6) -> 36000000 | I8: =SUM(I6:I6) -> 248000000 | J8: =SUM(J6:J6) -> 36000000 | K8: =SUM(K6:K6) -> 36000000 | ... T8: =SUM(T6:T6) -> 4.6422264e+09
E9: =(E8-D8)/D8 -> 0 | F9: =(F8-E8)/E8 -> 5.8888889 | G9: =(G8-F8)/F8 -> -0.85483871 | H9: =(H8-G8)/G8 -> 0 | I9: =(I8-H8)/H8 -> 5.8888889 | J9: =(J8-I8)/I8 -> -0.85483871 | K9: =(K8-J8)/J8 -> 0 | L9: =(L8-K8)/K8 -> 5.8888889 | ... O9: =(O8-N8)/N8 -> 5.8888889 | Q9: =(Q8-P8)/P8 -> 0.38 | R9: =(R8-Q8)/Q8 -> 0.38 | S9: =(S8-R8)/R8 -> 0.38 | T9: =(T8-S8)/S8 -> 0.38
B10: Cost of Revenue
B11: Direct Cost - 3rd Party Services | C11: ='Assumption-(MedSupplies)'!C70 -> 0.5 | D11: =D$8*$C$11 -> 18000000 | E11: =E$8*$C$11 -> 18000000 | F11: =F$8*$C$11 -> 124000000 | G11: =G$8*$C$11 -> 18000000 | H11: =H$8*$C$11 -> 18000000 | I11: =I$8*$C$11 -> 124000000 | J11: =J$8*$C$11 -> 18000000 | K11: =K$8*$C$11 -> 18000000 | ... O11: =O$8*$C$11 -> 124000000 | P11: =SUM(D11:O11) -> 640000000 | Q11: =P$8*(1+'Assumption-(MedSupplies)'!E$70)*'Assumption-(MedSupplies)'!$C$70 -> 704000000 | R11: =Q$8*(1+'Assumption-(MedSupplies)'!F$70)*'Assumption-(MedSupplies)'!$C$70 -> 9.53856e+08 | S11: =R$8*(1+'Assumption-(MedSupplies)'!G$70)*'Assumption-(MedSupplies)'!$C$70 -> 1.3163213e+09 | T11: =S$8*(1+'Assumption-(MedSupplies)'!H$70)*'Assumption-(MedSupplies)'!$C$70 -> 1.782884e+09
B12: Direct Cost - Staff | D12: ='Assumption-(MedSupplies)'!V105 -> 3700000 | E12: =D12 -> 3700000 | F12: =E12 -> 3700000 | G12: =F12 -> 3700000 | H12: =G12 -> 3700000 | I12: =H12 -> 3700000 | J12: =I12 -> 3700000 | K12: =J12 -> 3700000 | L12: =K12 -> 3700000 | ... O12: =N12 -> 3700000 | P12: =SUM(D12:O12) -> 44400000 | Q12: =P12 -> 44400000 | R12: =Q12 -> 44400000 | S12: =R12 -> 44400000 | T12: =S12 -> 44400000
B13: Direct Cost - Sales Commission | C13: ='Assumption-(MedSupplies)'!C72 -> 0.01 | D13: =$C$13*D8 -> 360000 | E13: =$C$13*E8 -> 360000 | F13: =$C$13*F8 -> 2480000 | G13: =$C$13*G8 -> 360000 | H13: =$C$13*H8 -> 360000 | I13: =$C$13*I8 -> 2480000 | J13: =$C$13*J8 -> 360000 | K13: =$C$13*K8 -> 360000 | ... O13: =$C$13*O8 -> 2480000 | P13: =SUM(D13:O13) -> 12800000 | Q13: =Q8*$C$13 -> 17664000 | R13: =R8*$C$13 -> 24376320 | S13: =S8*$C$13 -> 33639322 | T13: =T8*$C$13 -> 46422264
B14: Direct Cost - Overheads & Others | C14: ='Assumption-(MedSupplies)'!C73 -> 0 | D14: =$C$14*D$8 -> 0 | E14: =$C$14*E$8 -> 0 | F14: =$C$14*F$8 -> 0 | G14: =$C$14*G$8 -> 0 | H14: =$C$14*H$8 -> 0 | I14: =$C$14*I$8 -> 0 | J14: =$C$14*J$8 -> 0 | K14: =$C$14*K$8 -> 0 | ... O14: =$C$14*O$8 -> 0 | P14: =SUM(D14:O14) -> 0 | Q14: =P$8*(1+'Assumption-(MedSupplies)'!$E73)*'Assumption-(MedSupplies)'!$C$73 -> 0 | R14: =Q$8*(1+'Assumption-(MedSupplies)'!$E73)*'Assumption-(MedSupplies)'!$C$73 -> 0 | S14: =R$8*(1+'Assumption-(MedSupplies)'!$E73)*'Assumption-(MedSupplies)'!$C$73 -> 0 | T14: =S$8*(1+'Assumption-(MedSupplies)'!$E73)*'Assumption-(MedSupplies)'!$C$73 -> 0
B16: Total Direct Cost | D16: =SUM(D11:D14) -> 22060000 | E16: =SUM(E11:E14) -> 22060000 | F16: =SUM(F11:F14) -> 130180000 | G16: =SUM(G11:G14) -> 22060000 | H16: =SUM(H11:H14) -> 22060000 | I16: =SUM(I11:I14) -> 130180000 | J16: =SUM(J11:J14) -> 22060000 | K16: =SUM(K11:K14) -> 22060000 | ... O16: =SUM(O11:O14) -> 130180000 | P16: =SUM(P11:P15) -> 697200000 | Q16: =SUM(Q11:Q14) -> 766064000 | R16: =SUM(R11:R14) -> 1.0226323e+09 | S16: =SUM(S11:S14) -> 1.3943606e+09 | T16: =SUM(T11:T14) -> 1.8737063e+09
P17: =P16/P8 -> 0.5446875
B18: Gross Profit | D18: =D8-D16 -> 13940000 | E18: =E8-E16 -> 13940000 | F18: =F8-F16 -> 117820000 | G18: =G8-G16 -> 13940000 | H18: =H8-H16 -> 13940000 | I18: =I8-I16 -> 117820000 | J18: =J8-J16 -> 13940000 | K18: =K8-K16 -> 13940000 | ... T18: =T8-T16 -> 2.7685201e+09
P19: =P18/P8 -> 0.4553125
B20: Operating expenses
B21: Indirect Staff Cost | D21: ='Assumption-(MedSupplies)'!V111 -> 0 | E21: =D21 -> 0 | F21: =E21 -> 0 | G21: =F21 -> 0 | H21: =G21 -> 0 | I21: =H21 -> 0 | J21: =I21 -> 0 | K21: =J21 -> 0 | L21: =K21 -> 0 | ... O21: =N21 -> 0 | P21: =SUM(D21:O21) -> 0 | Q21: =P21*(1+'Assumption-(MedSupplies)'!E$77) -> 0 | R21: =Q21*(1+'Assumption-(MedSupplies)'!F$77) -> 0 | S21: =R21*(1+'Assumption-(MedSupplies)'!G$77) -> 0 | T21: =S21*(1+'Assumption-(MedSupplies)'!H$77) -> 0
B22: Repair&Maintenance | D22: ='Assumption-(MedSupplies)'!D78 -> 547083.33 | E22: =D22 -> 547083.33 | F22: =E22 -> 547083.33 | G22: =F22 -> 547083.33 | H22: =G22 -> 547083.33 | I22: =H22 -> 547083.33 | J22: =I22 -> 547083.33 | K22: =J22 -> 547083.33 | L22: =K22 -> 547083.33 | ... O22: =N22 -> 547083.33 | P22: =SUM(D22:O22) -> 6565000 | Q22: =P22*(1+'Assumption-(MedSupplies)'!E$67) -> 7549750 | R22: =Q22*(1+'Assumption-(MedSupplies)'!F$67) -> 8682212.5 | S22: =R22*(1+'Assumption-(MedSupplies)'!G$67) -> 9984544.4 | T22: =S22*(1+'Assumption-(MedSupplies)'!H$67) -> 11482226
B23: Bank Charges | D23: ='Assumption-(MedSupplies)'!D79 -> 27354.167 | E23: =D23 -> 27354.167 | F23: =E23 -> 27354.167 | G23: =F23 -> 27354.167 | H23: =G23 -> 27354.167 | I23: =H23 -> 27354.167 | J23: =I23 -> 27354.167 | K23: =J23 -> 27354.167 | L23: =K23 -> 27354.167 | ... O23: =N23 -> 27354.167 | P23: =SUM(D23:O23) -> 328250 | Q23: =P23*(1+'Assumption-(MedSupplies)'!E$67) -> 377487.5 | R23: =Q23*(1+'Assumption-(MedSupplies)'!F$67) -> 434110.62 | S23: =R23*(1+'Assumption-(MedSupplies)'!G$67) -> 499227.22 | T23: =S23*(1+'Assumption-(MedSupplies)'!H$67) -> 574111.3
B24: Advert, Printing & Stationery | D24: ='Assumption-(MedSupplies)'!$D$80 -> 150000 | E24: =D24 -> 150000 | F24: =E24 -> 150000 | G24: =F24 -> 150000 | H24: =G24 -> 150000 | I24: =H24 -> 150000 | J24: =I24 -> 150000 | K24: =J24 -> 150000 | L24: =K24 -> 150000 | ... O24: =N24 -> 150000 | P24: =SUM(D24:O24) -> 1800000 | Q24: =P24*(1+'Assumption-(MedSupplies)'!E$67) -> 2070000 | R24: =Q24*(1+'Assumption-(MedSupplies)'!F$67) -> 2380500 | S24: =R24*(1+'Assumption-(MedSupplies)'!G$67) -> 2737575 | T24: =S24*(1+'Assumption-(MedSupplies)'!H$67) -> 3148211.2
B25: Rent | D25: ='Assumption-(MedSupplies)'!D81 -> 416667 | E25: =D25 -> 416667 | F25: =E25 -> 416667 | G25: =F25 -> 416667 | H25: =G25 -> 416667 | I25: =H25 -> 416667 | J25: =I25 -> 416667 | K25: =J25 -> 416667 | L25: =K25 -> 416667 | ... O25: =N25 -> 416667 | P25: =SUM(D25:O25) -> 5000004 | Q25: =P25*(1+'Assumption-(MedSupplies)'!E$67) -> 5750004.6 | R25: =Q25*(1+'Assumption-(MedSupplies)'!F$67) -> 6612505.3 | S25: =R25*(1+'Assumption-(MedSupplies)'!G$67) -> 7604381.1 | T25: =S25*(1+'Assumption-(MedSupplies)'!H$67) -> 8745038.2
B26: Internet | D26: ='Assumption-(MedSupplies)'!$D82 -> 50000 | E26: =D26 -> 50000 | F26: =E26 -> 50000 | G26: =F26 -> 50000 | H26: =G26 -> 50000 | I26: =H26 -> 50000 | J26: =I26 -> 50000 | K26: =J26 -> 50000 | L26: =K26 -> 50000 | ... O26: =N26 -> 50000 | P26: =SUM(D26:O26) -> 600000 | Q26: =P26*(1+'Assumption-(MedSupplies)'!E$67) -> 690000 | R26: =Q26*(1+'Assumption-(MedSupplies)'!F$67) -> 793500 | S26: =R26*(1+'Assumption-(MedSupplies)'!G$67) -> 912525 | T26: =S26*(1+'Assumption-(MedSupplies)'!H$67) -> 1049403.7
B27: Call Centre Software Subscription | D27: ='Assumption-(MedSupplies)'!$D83 -> 100000 | E27: =D27 -> 100000 | F27: =E27 -> 100000 | G27: =F27 -> 100000 | H27: =G27 -> 100000 | I27: =H27 -> 100000 | J27: =I27 -> 100000 | K27: =J27 -> 100000 | L27: =K27 -> 100000 | ... O27: =N27 -> 100000 | P27: =SUM(D27:O27) -> 1200000 | Q27: =P27*(1+'Assumption-(MedSupplies)'!E$67) -> 1380000 | R27: =Q27*(1+'Assumption-(MedSupplies)'!F$67) -> 1587000 | S27: =R27*(1+'Assumption-(MedSupplies)'!G$67) -> 1825050 | T27: =S27*(1+'Assumption-(MedSupplies)'!H$67) -> 2098807.5
B28: Cleaning | D28: ='Assumption-(MedSupplies)'!$D84 -> 0 | E28: =D28 -> 0 | F28: =E28 -> 0 | G28: =F28 -> 0 | H28: =G28 -> 0 | I28: =H28 -> 0 | J28: =I28 -> 0 | K28: =J28 -> 0 | L28: =K28 -> 0 | ... O28: =N28 -> 0 | P28: =SUM(D28:O28) -> 0 | Q28: =P28*(1+'Assumption-(MedSupplies)'!E$67) -> 0 | R28: =Q28*(1+'Assumption-(MedSupplies)'!F$67) -> 0 | S28: =R28*(1+'Assumption-(MedSupplies)'!G$67) -> 0 | T28: =S28*(1+'Assumption-(MedSupplies)'!H$67) -> 0
B29: Fuel - Pool Cars | D29: ='Assumption-(MedSupplies)'!$D85 -> 200000 | E29: =D29 -> 200000 | F29: =E29 -> 200000 | G29: =F29 -> 200000 | H29: =G29 -> 200000 | I29: =H29 -> 200000 | J29: =I29 -> 200000 | K29: =J29 -> 200000 | L29: =K29 -> 200000 | ... O29: =N29 -> 200000 | P29: =SUM(D29:O29) -> 2400000 | Q29: =P29*(1+'Assumption-(MedSupplies)'!E$67) -> 2760000 | R29: =Q29*(1+'Assumption-(MedSupplies)'!F$67) -> 3174000 | S29: =R29*(1+'Assumption-(MedSupplies)'!G$67) -> 3650100 | T29: =S29*(1+'Assumption-(MedSupplies)'!H$67) -> 4197615
B30: Electricity | D30: ='Assumption-(MedSupplies)'!$D86 -> 0 | E30: =D30 -> 0 | F30: =E30 -> 0 | G30: =F30 -> 0 | H30: =G30 -> 0 | I30: =H30 -> 0 | J30: =I30 -> 0 | K30: =J30 -> 0 | L30: =K30 -> 0 | ... O30: =N30 -> 0 | P30: =SUM(D30:O30) -> 0 | Q30: =P30*(1+'Assumption-(MedSupplies)'!E$67) -> 0 | R30: =Q30*(1+'Assumption-(MedSupplies)'!F$67) -> 0 | S30: =R30*(1+'Assumption-(MedSupplies)'!G$67) -> 0 | T30: =S30*(1+'Assumption-(MedSupplies)'!H$67) -> 0
B31: Car Hire | D31: ='Assumption-(MedSupplies)'!$D87 -> 600000 | E31: =D31 -> 600000 | F31: =E31 -> 600000 | G31: =F31 -> 600000 | H31: =G31 -> 600000 | I31: =H31 -> 600000 | J31: =I31 -> 600000 | K31: =J31 -> 600000 | L31: =K31 -> 600000 | ... O31: =N31 -> 600000 | P31: =SUM(D31:O31) -> 7200000 | Q31: =P31*(1+'Assumption-(MedSupplies)'!E$67) -> 8280000 | R31: =Q31*(1+'Assumption-(MedSupplies)'!F$67) -> 9522000 | S31: =R31*(1+'Assumption-(MedSupplies)'!G$67) -> 10950300 | T31: =S31*(1+'Assumption-(MedSupplies)'!H$67) -> 12592845
B32: Security | D32: ='Assumption-(MedSupplies)'!$D88 -> 0 | E32: =D32 -> 0 | F32: =E32 -> 0 | G32: =F32 -> 0 | H32: =G32 -> 0 | I32: =H32 -> 0 | J32: =I32 -> 0 | K32: =J32 -> 0 | L32: =K32 -> 0 | ... O32: =N32 -> 0 | P32: =SUM(D32:O32) -> 0 | Q32: =P32*(1+'Assumption-(MedSupplies)'!E$67) -> 0 | R32: =Q32*(1+'Assumption-(MedSupplies)'!F$67) -> 0 | S32: =R32*(1+'Assumption-(MedSupplies)'!G$67) -> 0 | T32: =S32*(1+'Assumption-(MedSupplies)'!H$67) -> 0
B33: Local Govt Levies & Charges | D33: ='Assumption-(MedSupplies)'!$D89 -> 250000 | E33: =D33 -> 250000 | F33: =E33 -> 250000 | G33: =F33 -> 250000 | H33: =G33 -> 250000 | I33: =H33 -> 250000 | J33: =I33 -> 250000 | K33: =J33 -> 250000 | L33: =K33 -> 250000 | ... O33: =N33 -> 250000 | P33: =SUM(D33:O33) -> 3000000 | Q33: =P33*(1+'Assumption-(MedSupplies)'!E$67) -> 3450000 | R33: =Q33*(1+'Assumption-(MedSupplies)'!F$67) -> 3967500 | S33: =R33*(1+'Assumption-(MedSupplies)'!G$67) -> 4562625 | T33: =S33*(1+'Assumption-(MedSupplies)'!H$67) -> 5247018.7
B34: Insurance Expenses | D34: ='Assumption-(MedSupplies)'!$D90 -> 100000 | E34: =D34 -> 100000 | F34: =E34 -> 100000 | G34: =F34 -> 100000 | H34: =G34 -> 100000 | I34: =H34 -> 100000 | J34: =I34 -> 100000 | K34: =J34 -> 100000 | L34: =K34 -> 100000 | ... O34: =N34 -> 100000 | P34: =SUM(D34:O34) -> 1200000 | Q34: =P34*(1+'Assumption-(MedSupplies)'!E$67) -> 1380000 | R34: =Q34*(1+'Assumption-(MedSupplies)'!F$67) -> 1587000 | S34: =R34*(1+'Assumption-(MedSupplies)'!G$67) -> 1825050 | T34: =S34*(1+'Assumption-(MedSupplies)'!H$67) -> 2098807.5
B35: Contribution | D35: ='Assumption-(MedSupplies)'!D92 -> 1500000 | E35: =D35 -> 1500000 | F35: =E35 -> 1500000 | G35: =F35 -> 1500000 | H35: =G35 -> 1500000 | I35: =H35 -> 1500000 | J35: =I35 -> 1500000 | K35: =J35 -> 1500000 | L35: =K35 -> 1500000 | ... O35: =N35 -> 1500000 | P35: =SUM(D35:O35) -> 18000000 | Q35: =P35*(1+'Assumption-(MedSupplies)'!E$67) -> 20700000 | R35: =Q35*(1+'Assumption-(MedSupplies)'!F$67) -> 23805000 | S35: =R35*(1+'Assumption-(MedSupplies)'!G$67) -> 27375750 | T35: =S35*(1+'Assumption-(MedSupplies)'!H$67) -> 31482112
B37: Total Opex | D37: =SUM(D21:D35) -> 3941104.5 | E37: =SUM(E21:E35) -> 3941104.5 | F37: =SUM(F21:F35) -> 3941104.5 | G37: =SUM(G21:G35) -> 3941104.5 | H37: =SUM(H21:H35) -> 3941104.5 | I37: =SUM(I21:I35) -> 3941104.5 | J37: =SUM(J21:J35) -> 3941104.5 | K37: =SUM(K21:K35) -> 3941104.5 | ... T37: =SUM(T21:T35) -> 82716197
P38: =P37/P8 -> 0.036947855 | Q38: =Q37/Q8 -> 0.030789879 | R38: =R37/R8 -> 0.025658232 | S38: =S37/S8 -> 0.02138186 | T38: =T37/T8 -> 0.017818217
B39: EBITDA | D39: =D18-D37 -> 9998895.5 | E39: =E18-E37 -> 9998895.5 | F39: =F18-F37 -> 1.138789e+08 | G39: =G18-G37 -> 9998895.5 | H39: =H18-H37 -> 9998895.5 | I39: =I18-I37 -> 1.138789e+08 | J39: =J18-J37 -> 9998895.5 | K39: =K18-K37 -> 9998895.5 | ... T39: =T18-T37 -> 2.6858039e+09
B41: Depreciation Expenses | D41: ='Assumption-(MedSupplies)'!D90 -> 100000 | E41: =D41 -> 100000 | F41: =E41 -> 100000 | G41: =F41 -> 100000 | H41: =G41 -> 100000 | I41: =H41 -> 100000 | J41: =I41 -> 100000 | K41: =J41 -> 100000 | L41: =K41 -> 100000 | ... O41: =N41 -> 100000 | P41: =SUM(D41:O41) -> 1200000 | Q41: =P41*(1+'Assumption-(MedSupplies)'!E$67) -> 1380000 | R41: =Q41*(1+'Assumption-(MedSupplies)'!F$67) -> 1587000 | S41: =R41*(1+'Assumption-(MedSupplies)'!G$67) -> 1825050 | T41: =S41*(1+'Assumption-(MedSupplies)'!H$67) -> 2098807.5
B43: Net Profit/(Loss) | D43: =D39-D41 -> 9898895.5 | E43: =E39-E41 -> 9898895.5 | F43: =F39-F41 -> 1.137789e+08 | G43: =G39-G41 -> 9898895.5 | H43: =H39-H41 -> 9898895.5 | I43: =I39-I41 -> 1.137789e+08 | J43: =J39-J41 -> 9898895.5 | K43: =K39-K41 -> 9898895.5 | ... T43: =T39-T41 -> 2.6837051e+09
P44: =P43/P8 -> 0.41742715 | Q44: =Q43/Q8 -> 0.53474228 | R44: =R43/R8 -> 0.55417198 | S44: =S43/S8 -> 0.56357242 | T44: =T43/T8 -> 0.57810732
B45: Accumulated EBITDA | D45: =D43 -> 9898895.5 | E45: =D45+E43 -> 19797791 | F45: =E45+F43 -> 1.3357669e+08 | G45: =F45+G43 -> 143475582 | H45: =G45+H43 -> 1.5337448e+08 | I45: =H45+I43 -> 267153373 | J45: =I45+J43 -> 2.7705227e+08 | K45: =J45+K43 -> 286951164 | L45: =K45+L43 -> 4.0073006e+08 | ... O45: =N45+O43 -> 534306746 | P45: =P43 -> 534306746 | Q45: =P45+Q39 -> 1.4802555e+09 | R45: =Q45+R39 -> 2.8327099e+09 | S45: =R45+S39 -> 4.7303543e+09 | T45: =S45+T39 -> 7.4161582e+09
B47: Total Investment
...

Sheet Computations-Outputs
A2: Computations-Outputs
D3: January | E3: February | F3: March | G3: April | H3: May | I3: June | J3: July | K3: August | L3: September | M3: October | N3: November | O3: December | P3: FY 1 | Q3: FY 2 | R3: FY 3 | S3: FY 4 | T3: FY 5
D4: NGN | E4: NGN | F4: NGN | G4: NGN | H4: NGN | I4: NGN | J4: NGN | K4: NGN | L4: NGN | M4: NGN | N4: NGN | O4: NGN | P4: NGN | Q4: NGN | R4: NGN | S4: NGN | T4: NGN
B5: Revenue
B6: ='Assumption-(MedSupplies)'!B5 -> Wellness Packages | D6: ='Assumption-(MedSupplies)'!D5 -> 0 | E6: ='Assumption-(MedSupplies)'!E5 -> 0 | F6: ='Assumption-(MedSupplies)'!F5 -> 0 | G6: ='Assumption-(MedSupplies)'!G5 -> 0 | H6: ='Assumption-(MedSupplies)'!H5 -> 0 | I6: ='Assumption-(MedSupplies)'!I5 -> 0 | J6: ='Assumption-(MedSupplies)'!J5 -> 0 | K6: ='Assumption-(MedSupplies)'!K5 -> 0 | ... O6: ='Assumption-(MedSupplies)'!O5 -> 0 | P6: =SUM(D6:O6) -> 0 | Q6: =P6*(1+'Assumption-(MedSupplies)'!E$66)*(1+'Assumption-(MedSupplies)'!E$69) -> 0 | R6: =Q6*(1+'Assumption-(MedSupplies)'!F$66)*(1+'Assumption-(MedSupplies)'!F$69) -> 0 | S6: =R6*(1+'Assumption-(MedSupplies)'!G$66)*(1+'Assumption-(MedSupplies)'!G$69) -> 0 | T6: =S6*(1+'Assumption-(MedSupplies)'!H$66)*(1+'Assumption-(MedSupplies)'!H$69) -> 0
B7: ='Assumption-(MedSupplies)'!B13 -> Medsupplies | D7: ='Assumption-(MedSupplies)'!D13 -> 36000000 | E7: ='Assumption-(MedSupplies)'!E13 -> 36000000 | F7: ='Assumption-(MedSupplies)'!F13 -> 248000000 | G7: ='Assumption-(MedSupplies)'!G13 -> 36000000 | H7: ='Assumption-(MedSupplies)'!H13 -> 36000000 | I7: ='Assumption-(MedSupplies)'!I13 -> 248000000 | J7: ='Assumption-(MedSupplies)'!J13 -> 36000000 | K7: ='Assumption-(MedSupplies)'!K13 -> 36000000 | ... O7: ='Assumption-(MedSupplies)'!O13 -> 248000000 | P7: =SUM(D7:O7) -> 1280000000 | Q7: =P7*(1+'Assumption-(MedSupplies)'!E$66)*(1+'Assumption-(MedSupplies)'!E$69) -> 1766400000 | R7: =Q7*(1+'Assumption-(MedSupplies)'!F$66)*(1+'Assumption-(MedSupplies)'!F$69) -> 2.437632e+09 | S7: =R7*(1+'Assumption-(MedSupplies)'!G$66)*(1+'Assumption-(MedSupplies)'!G$69) -> 3.3639322e+09 | T7: =S7*(1+'Assumption-(MedSupplies)'!H$66)*(1+'Assumption-(MedSupplies)'!H$69) -> 4.6422264e+09
B9: Total Revenue | D9: =SUM(D6:D7) -> 36000000 | E9: =SUM(E6:E7) -> 36000000 | F9: =SUM(F6:F7) -> 248000000 | G9: =SUM(G6:G7) -> 36000000 | H9: =SUM(H6:H7) -> 36000000 | I9: =SUM(I6:I7) -> 248000000 | J9: =SUM(J6:J7) -> 36000000 | K9: =SUM(K6:K7) -> 36000000 | ... T9: =SUM(T6:T7) -> 4.6422264e+09
B11: Cost of Revenue
B12: Direct cost reagent | D12: ='Assumption-(MedSupplies)'!$C70*D$9 -> 18000000 | E12: ='Assumption-(MedSupplies)'!$C70*E$9 -> 18000000 | F12: ='Assumption-(MedSupplies)'!$C70*F$9 -> 124000000 | G12: ='Assumption-(MedSupplies)'!$C70*G$9 -> 18000000 | H12: ='Assumption-(MedSupplies)'!$C70*H$9 -> 18000000 | I12: ='Assumption-(MedSupplies)'!$C70*I$9 -> 124000000 | J12: ='Assumption-(MedSupplies)'!$C70*J$9 -> 18000000 | K12: ='Assumption-(MedSupplies)'!$C70*K$9 -> 18000000 | ... O12: ='Assumption-(MedSupplies)'!$C70*O$9 -> 124000000 | P12: =SUM(D12:O12) -> 640000000 | Q12: =P$9*(1+'Assumption-(MedSupplies)'!E$70)*'Assumption-(MedSupplies)'!$C$70 -> 704000000 | R12: =Q$9*(1+'Assumption-(MedSupplies)'!F$70)*'Assumption-(MedSupplies)'!$C$70 -> 9.53856e+08 | S12: =R$9*(1+'Assumption-(MedSupplies)'!G$70)*'Assumption-(MedSupplies)'!$C$70 -> 1.3163213e+09 | T12: =S$9*(1+'Assumption-(MedSupplies)'!H$70)*'Assumption-(MedSupplies)'!$C$70 -> 1.782884e+09
B13: Other direct cost | D13: ='Assumption-(MedSupplies)'!$C73*D$9 -> 0 | E13: ='Assumption-(MedSupplies)'!$C73*E$9 -> 0 | F13: ='Assumption-(MedSupplies)'!$C73*F$9 -> 0 | G13: ='Assumption-(MedSupplies)'!$C73*G$9 -> 0 | H13: ='Assumption-(MedSupplies)'!$C73*H$9 -> 0 | I13: ='Assumption-(MedSupplies)'!$C73*I$9 -> 0 | J13: ='Assumption-(MedSupplies)'!$C73*J$9 -> 0 | K13: ='Assumption-(MedSupplies)'!$C73*K$9 -> 0 | ... O13: ='Assumption-(MedSupplies)'!$C73*O$9 -> 0 | P13: =SUM(D13:O13) -> 0 | Q13: =P$9*(1+'Assumption-(MedSupplies)'!$E73)*'Assumption-(MedSupplies)'!$C$73 -> 0 | R13: =Q$9*(1+'Assumption-(MedSupplies)'!$E73)*'Assumption-(MedSupplies)'!$C$73 -> 0 | S13: =R$9*(1+'Assumption-(MedSupplies)'!$E73)*'Assumption-(MedSupplies)'!$C$73 -> 0 | T13: =S$9*(1+'Assumption-(MedSupplies)'!$E73)*'Assumption-(MedSupplies)'!$C$73 -> 0
B15: Total Direct Cost | D15: =SUM(D12:D13) -> 18000000 | E15: =SUM(E12:E13) -> 18000000 | F15: =SUM(F12:F13) -> 124000000 | G15: =SUM(G12:G13) -> 18000000 | H15: =SUM(H12:H13) -> 18000000 | I15: =SUM(I12:I13) -> 124000000 | J15: =SUM(J12:J13) -> 18000000 | K15: =SUM(K12:K13) -> 18000000 | ... T15: =SUM(T12:T13) -> 1.782884e+09
B17: Gross Profit | D17: =D9-D15 -> 18000000 | E17: =E9-E15 -> 18000000 | F17: =F9-F15 -> 124000000 | G17: =G9-G15 -> 18000000 | H17: =H9-H15 -> 18000000 | I17: =I9-I15 -> 124000000 | J17: =J9-J15 -> 18000000 | K17: =K9-K15 -> 18000000 | ... T17: =T9-T15 -> 2.8593423e+09
B19: Operating expenses
B20: Staff cost | D20: ='Assumption-(MedSupplies)'!$D$77/12 -> 0 | E20: ='Assumption-(MedSupplies)'!$D$77/12 -> 0 | F20: ='Assumption-(MedSupplies)'!$D$77/12 -> 0 | G20: ='Assumption-(MedSupplies)'!$D$77/12 -> 0 | H20: ='Assumption-(MedSupplies)'!$D$77/12 -> 0 | I20: ='Assumption-(MedSupplies)'!$D$77/12 -> 0 | J20: ='Assumption-(MedSupplies)'!$D$77/12 -> 0 | K20: ='Assumption-(MedSupplies)'!$D$77/12 -> 0 | ... O20: ='Assumption-(MedSupplies)'!$D$77/12 -> 0 | P20: =SUM(D20:O20) -> 0 | Q20: =P20*(1+'Assumption-(MedSupplies)'!E$77) -> 0 | R20: =Q20*(1+'Assumption-(MedSupplies)'!F$77) -> 0 | S20: =R20*(1+'Assumption-(MedSupplies)'!G$77) -> 0 | T20: =S20*(1+'Assumption-(MedSupplies)'!H$77) -> 0
B21: Repair&Maintenance | D21: ='Computations-Outputs'!$D$9*'Assumption-(MedSupplies)'!$C$78 -> 360000 | E21: ='Computations-Outputs'!$D$9*'Assumption-(MedSupplies)'!$C$78 -> 360000 | F21: ='Computations-Outputs'!$D$9*'Assumption-(MedSupplies)'!$C$78 -> 360000 | G21: ='Computations-Outputs'!$D$9*'Assumption-(MedSupplies)'!$C$78 -> 360000 | H21: ='Computations-Outputs'!$D$9*'Assumption-(MedSupplies)'!$C$78 -> 360000 | I21: ='Computations-Outputs'!$D$9*'Assumption-(MedSupplies)'!$C$78 -> 360000 | J21: ='Computations-Outputs'!$D$9*'Assumption-(MedSupplies)'!$C$78 -> 360000 | K21: ='Computations-Outputs'!$D$9*'Assumption-(MedSupplies)'!$C$78 -> 360000 | ... O21: ='Computations-Outputs'!$D$9*'Assumption-(MedSupplies)'!$C$78 -> 360000 | P21: =SUM(D21:O21) -> 4320000 | Q21: =P21*(1+'Assumption-(MedSupplies)'!E$67) -> 4968000 | R21: =Q21*(1+'Assumption-(MedSupplies)'!F$67) -> 5713200 | S21: =R21*(1+'Assumption-(MedSupplies)'!G$67) -> 6570180 | T21: =S21*(1+'Assumption-(MedSupplies)'!H$67) -> 7555707
B22: Bank Charges | D22: ='Assumption-(MedSupplies)'!$C$79*'Computations-Outputs'!$D$9 -> 18000 | E22: ='Assumption-(MedSupplies)'!$C$79*'Computations-Outputs'!$D$9 -> 18000 | F22: ='Assumption-(MedSupplies)'!$C$79*'Computations-Outputs'!$D$9 -> 18000 | G22: ='Assumption-(MedSupplies)'!$C$79*'Computations-Outputs'!$D$9 -> 18000 | H22: ='Assumption-(MedSupplies)'!$C$79*'Computations-Outputs'!$D$9 -> 18000 | I22: ='Assumption-(MedSupplies)'!$C$79*'Computations-Outputs'!$D$9 -> 18000 | J22: ='Assumption-(MedSupplies)'!$C$79*'Computations-Outputs'!$D$9 -> 18000 | K22: ='Assumption-(MedSupplies)'!$C$79*'Computations-Outputs'!$D$9 -> 18000 | ... O22: ='Assumption-(MedSupplies)'!$C$79*'Computations-Outputs'!$D$9 -> 18000 | P22: =SUM(D22:O22) -> 216000 | Q22: =P22*(1+'Assumption-(MedSupplies)'!E$67) -> 248400 | R22: =Q22*(1+'Assumption-(MedSupplies)'!F$67) -> 285660 | S22: =R22*(1+'Assumption-(MedSupplies)'!G$67) -> 328509 | T22: =S22*(1+'Assumption-(MedSupplies)'!H$67) -> 377785.35
B23: Printing & Stationery | D23: ='Assumption-(MedSupplies)'!$D$80/12 -> 12500 | E23: ='Assumption-(MedSupplies)'!$D$80/12 -> 12500 | F23: ='Assumption-(MedSupplies)'!$D$80/12 -> 12500 | G23: ='Assumption-(MedSupplies)'!$D$80/12 -> 12500 | H23: ='Assumption-(MedSupplies)'!$D$80/12 -> 12500 | I23: ='Assumption-(MedSupplies)'!$D$80/12 -> 12500 | J23: ='Assumption-(MedSupplies)'!$D$80/12 -> 12500 | K23: ='Assumption-(MedSupplies)'!$D$80/12 -> 12500 | ... O23: ='Assumption-(MedSupplies)'!$D$80/12 -> 12500 | P23: =SUM(D23:O23) -> 150000 | Q23: =P23*(1+'Assumption-(MedSupplies)'!E$67) -> 172500 | R23: =Q23*(1+'Assumption-(MedSupplies)'!F$67) -> 198375 | S23: =R23*(1+'Assumption-(MedSupplies)'!G$67) -> 228131.25 | T23: =S23*(1+'Assumption-(MedSupplies)'!H$67) -> 262350.94
B24: Internet | D24: ='Assumption-(MedSupplies)'!$D82/12 -> 4166.6667 | E24: ='Assumption-(MedSupplies)'!$D82/12 -> 4166.6667 | F24: ='Assumption-(MedSupplies)'!$D82/12 -> 4166.6667 | G24: ='Assumption-(MedSupplies)'!$D82/12 -> 4166.6667 | H24: ='Assumption-(MedSupplies)'!$D82/12 -> 4166.6667 | I24: ='Assumption-(MedSupplies)'!$D82/12 -> 4166.6667 | J24: ='Assumption-(MedSupplies)'!$D82/12 -> 4166.6667 | K24: ='Assumption-(MedSupplies)'!$D82/12 -> 4166.6667 | ... O24: ='Assumption-(MedSupplies)'!$D82/12 -> 4166.6667 | P24: =SUM(D24:O24) -> 50000 | Q24: =P24*(1+'Assumption-(MedSupplies)'!E$67) -> 57500 | R24: =Q24*(1+'Assumption-(MedSupplies)'!F$67) -> 66125 | S24: =R24*(1+'Assumption-(MedSupplies)'!G$67) -> 76043.75 | T24: =S24*(1+'Assumption-(MedSupplies)'!H$67) -> 87450.312
B25: Cleaning | D25: ='Assumption-(MedSupplies)'!$D84/12 -> 0 | E25: ='Assumption-(MedSupplies)'!$D84/12 -> 0 | F25: ='Assumption-(MedSupplies)'!$D84/12 -> 0 | G25: ='Assumption-(MedSupplies)'!$D84/12 -> 0 | H25: ='Assumption-(MedSupplies)'!$D84/12 -> 0 | I25: ='Assumption-(MedSupplies)'!$D84/12 -> 0 | J25: ='Assumption-(MedSupplies)'!$D84/12 -> 0 | K25: ='Assumption-(MedSupplies)'!$D84/12 -> 0 | ... O25: ='Assumption-(MedSupplies)'!$D84/12 -> 0 | P25: =SUM(D25:O25) -> 0 | Q25: =P25*(1+'Assumption-(MedSupplies)'!E$67) -> 0 | R25: =Q25*(1+'Assumption-(MedSupplies)'!F$67) -> 0 | S25: =R25*(1+'Assumption-(MedSupplies)'!G$67) -> 0 | T25: =S25*(1+'Assumption-(MedSupplies)'!H$67) -> 0
B26: Diesel & Fuel | D26: ='Assumption-(MedSupplies)'!$D85/12 -> 16666.667 | E26: ='Assumption-(MedSupplies)'!$D85/12 -> 16666.667 | F26: ='Assumption-(MedSupplies)'!$D85/12 -> 16666.667 | G26: ='Assumption-(MedSupplies)'!$D85/12 -> 16666.667 | H26: ='Assumption-(MedSupplies)'!$D85/12 -> 16666.667 | I26: ='Assumption-(MedSupplies)'!$D85/12 -> 16666.667 | J26: ='Assumption-(MedSupplies)'!$D85/12 -> 16666.667 | K26: ='Assumption-(MedSupplies)'!$D85/12 -> 16666.667 | ... O26: ='Assumption-(MedSupplies)'!$D85/12 -> 16666.667 | P26: =SUM(D26:O26) -> 200000 | Q26: =P26*(1+'Assumption-(MedSupplies)'!E$67) -> 230000 | R26: =Q26*(1+'Assumption-(MedSupplies)'!F$67) -> 264500 | S26: =R26*(1+'Assumption-(MedSupplies)'!G$67) -> 304175 | T26: =S26*(1+'Assumption-(MedSupplies)'!H$67) -> 349801.25
B27: Electricity | D27: ='Assumption-(MedSupplies)'!$D86/12 -> 0 | E27: ='Assumption-(MedSupplies)'!$D86/12 -> 0 | F27: ='Assumption-(MedSupplies)'!$D86/12 -> 0 | G27: ='Assumption-(MedSupplies)'!$D86/12 -> 0 | H27: ='Assumption-(MedSupplies)'!$D86/12 -> 0 | I27: ='Assumption-(MedSupplies)'!$D86/12 -> 0 | J27: ='Assumption-(MedSupplies)'!$D86/12 -> 0 | K27: ='Assumption-(MedSupplies)'!$D86/12 -> 0 | ... O27: ='Assumption-(MedSupplies)'!$D86/12 -> 0 | P27: =SUM(D27:O27) -> 0 | Q27: =P27*(1+'Assumption-(MedSupplies)'!E$67) -> 0 | R27: =Q27*(1+'Assumption-(MedSupplies)'!F$67) -> 0 | S27: =R27*(1+'Assumption-(MedSupplies)'!G$67) -> 0 | T27: =S27*(1+'Assumption-(MedSupplies)'!H$67) -> 0
B28: Security | D28: ='Assumption-(MedSupplies)'!$D88/12 -> 0 | E28: ='Assumption-(MedSupplies)'!$D88/12 -> 0 | F28: ='Assumption-(MedSupplies)'!$D88/12 -> 0 | G28: ='Assumption-(MedSupplies)'!$D88/12 -> 0 | H28: ='Assumption-(MedSupplies)'!$D88/12 -> 0 | I28: ='Assumption-(MedSupplies)'!$D88/12 -> 0 | J28: ='Assumption-(MedSupplies)'!$D88/12 -> 0 | K28: ='Assumption-(MedSupplies)'!$D88/12 -> 0 | ... O28: ='Assumption-(MedSupplies)'!$D88/12 -> 0 | P28: =SUM(D28:O28) -> 0 | Q28: =P28*(1+'Assumption-(MedSupplies)'!E$67) -> 0 | R28: =Q28*(1+'Assumption-(MedSupplies)'!F$67) -> 0 | S28: =R28*(1+'Assumption-(MedSupplies)'!G$67) -> 0 | T28: =S28*(1+'Assumption-(MedSupplies)'!H$67) -> 0
B29: Water | D29: ='Assumption-(MedSupplies)'!$D89/12 -> 20833.333 | E29: ='Assumption-(MedSupplies)'!$D89/12 -> 20833.333 | F29: ='Assumption-(MedSupplies)'!$D89/12 -> 20833.333 | G29: ='Assumption-(MedSupplies)'!$D89/12 -> 20833.333 | H29: ='Assumption-(MedSupplies)'!$D89/12 -> 20833.333 | I29: ='Assumption-(MedSupplies)'!$D89/12 -> 20833.333 | J29: ='Assumption-(MedSupplies)'!$D89/12 -> 20833.333 | K29: ='Assumption-(MedSupplies)'!$D89/12 -> 20833.333 | ... O29: ='Assumption-(MedSupplies)'!$D89/12 -> 20833.333 | P29: =SUM(D29:O29) -> 250000 | Q29: =P29*(1+'Assumption-(MedSupplies)'!E$67) -> 287500 | R29: =Q29*(1+'Assumption-(MedSupplies)'!F$67) -> 330625 | S29: =R29*(1+'Assumption-(MedSupplies)'!G$67) -> 380218.75 | T29: =S29*(1+'Assumption-(MedSupplies)'!H$67) -> 437251.56
B31: Total Opex | D31: =SUM(D20:D29) -> 432166.67 | E31: =SUM(E20:E29) -> 432166.67 | F31: =SUM(F20:F29) -> 432166.67 | G31: =SUM(G20:G29) -> 432166.67 | H31: =SUM(H20:H29) -> 432166.67 | I31: =SUM(I20:I29) -> 432166.67 | J31: =SUM(J20:J29) -> 432166.67 | K31: =SUM(K20:K29) -> 432166.67 | ... T31: =SUM(T20:T29) -> 9070346.4
B33: EBITDA | D33: =D17-D31 -> 17567833 | E33: =E17-E31 -> 17567833 | F33: =F17-F31 -> 1.2356783e+08 | G33: =G17-G31 -> 17567833 | H33: =H17-H31 -> 17567833 | I33: =I17-I31 -> 1.2356783e+08 | J33: =J17-J31 -> 17567833 | K33: =K17-K31 -> 17567833 | ... T33: =T17-T31 -> 2.850272e+09
B35: Accumulated EBITDA | D35: =D33 -> 17567833 | E35: =D35+E33 -> 35135667 | F35: =E35+F33 -> 158703500 | G35: =F35+G33 -> 1.7627133e+08 | H35: =G35+H33 -> 1.9383917e+08 | I35: =H35+I33 -> 317407000 | J35: =I35+J33 -> 3.3497483e+08 | K35: =J35+K33 -> 3.5254267e+08 | L35: =K35+L33 -> 4.761105e+08 | ... O35: =N35+O33 -> 6.34814e+08 | P35: =P33 -> 634814000 | Q35: =P35+Q33 -> 1691250100 | R35: =Q35+R33 -> 3.1681676e+09 | S35: =R35+S33 -> 5.2078912e+09 | T35: =S35+T33 -> 8.0581632e+09
B37: Total Investment
B39: Pay back Balance | D39: =D35-D37 -> 17567833 | E39: =E35-E37 -> 35135667 | F39: =F35-F37 -> 158703500 | G39: =G35-G37 -> 1.7627133e+08 | H39: =H35-H37 -> 1.9383917e+08 | I39: =I35-I37 -> 317407000 | J39: =J35-J37 -> 3.3497483e+08 | K39: =K35-K37 -> 3.5254267e+08 | ... T39: =T35-T37 -> 8.0581632e+09
B41: Pay back Period | P41: =IF(P39>0,"1 Year"," ") -> 1 Year | Q41: =IF(Q39>0,"2 Year"," ") -> 2 Year | R41: =IF(R39>0,"3 Year"," ") -> 3 Year | S41: =IF(S39>0,"4 Year"," ") -> 4 Year | T41: =IF(T39>0,"5 Year"," ") -> 5 Year
