Workbook
Name afril: #REF!
Name BS: #REF!
Name costaa: #REF!
Name F: #REF!
Name fs: #REF!
Name GGGG: #REF!
Name groupincome: #REF!
Name MANS: #REF!
Name OLDMAN: #REF!
Name PAC: #REF!
Name PL: #REF!
Name REGISTRAR: #REF!
Name SCHD3: #REF!
Name SCHED1: #REF!
Name SCHED2: #REF!
Name SCHED3: #REF!
Name SCHED4: #REF!
Name SEMI: #REF!
Name SSES: #REF!
Name SUMMARY: #REF!
Name yyy: #REF!

Sheet Assumption-(OH)
B1: Assumptions-Inputs
D3: January | E3: February | F3: March | G3: April | H3: May | I3: June | J3: July | K3: August | L3: September | M3: October | N3: November | O3: December
B4: Travel Health Consultancy
B5: Fit to fly Exams | D5: =SUM(D6:D11) -> 0 | E5: =SUM(E6:E11) -> 0 | F5: =SUM(F6:F11) -> 0 | G5: =SUM(G6:G11) -> 613333.33 | H5: =SUM(H6:H11) -> 1319166.7 | I5: =SUM(I6:I11) -> 2025000 | J5: =SUM(J6:J11) -> 2730833.3 | K5: =SUM(K6:K11) -> 3436666.7 | ... O5: =SUM(O6:O11) -> 6260000 | Q5: =SUM(D5:O5) -> 30930000
B6: Vaccination Services | D6: =D28*D49 -> 0 | E6: =E49*E28 -> 0 | F6: =F49*F28 -> 0 | G6: =G49*G28 -> 100000 | H6: =H49*H28 -> 292500 | I6: =I49*I28 -> 485000 | J6: =J49*J28 -> 677500 | K6: =K49*K28 -> 870000 | L6: =L49*L28 -> 1062500 | ... O6: =O49*O28 -> 1640000 | Q6: =SUM(D6:O6) -> 7830000
B7: Travel Health Advisory/Consultancy Services | D7: =D50*D29 -> 0 | E7: =E50*E29 -> 0 | F7: =F50*F29 -> 0 | G7: =G50*G29 -> 513333.33 | H7: =H50*H29 -> 1026666.7 | I7: =I50*I29 -> 1540000 | J7: =J50*J29 -> 2053333.3 | K7: =K50*K29 -> 2566666.7 | ... O7: =O50*O29 -> 4620000 | Q7: =SUM(D7:O7) -> 23100000
B8: Travellers Self-help Products (App, Kits, etc)
B13: IMEs | D13: =SUM(D14:D23) -> 810000 | E13: =SUM(E14:E23) -> 1200000 | F13: =SUM(F14:F23) -> 2800000 | G13: =SUM(G14:G23) -> 4380000 | H13: =SUM(H14:H23) -> 5665000 | I13: =SUM(I14:I23) -> 7570750 | J13: =SUM(J14:J23) -> 10757138 | K13: =SUM(K14:K23) -> 14344813 | ... O13: =SUM(O14:O23) -> 30859645 | Q13: =SUM(D13:O13) -> 1.4437997e+08
B14: Australia- Regulated | D14: =D36*D57 -> 810000 | E14: =E36*E57 -> 1200000 | F14: =F36*F57 -> 2800000 | G14: =G36*G57 -> 3680000 | H14: =H36*H57 -> 4370000 | I14: =I36*I57 -> 5175000 | J14: =J36*J57 -> 6325000 | K14: =K36*K57 -> 7475000 | ... O14: =O36*O57 -> 12075000 | Q14: =SUM(D14:P14) -> 73235000
B15: Canada- Regulated | D15: =D37*D58 -> 0 | E15: =E37*E58 -> 0 | F15: =F37*F58 -> 0 | G15: =G37*G58 -> 0 | H15: =H37*H58 -> 0 | I15: =I37*I58 -> 0 | J15: =J37*J58 -> 0 | Q15: =SUM(D15:P15) -> 0
B16: UK- Regulated | D16: =D38*D59 -> 0 | E16: =E38*E59 -> 0 | F16: =F38*F59 -> 0 | G16: =G38*G59 -> 0 | H16: =H38*H59 -> 0 | I16: =I38*I59 -> 0 | J16: =J38*J59 -> 0 | Q16: =SUM(D16:P16) -> 0
B17: USA- Regulated | D17: =D39*D60 -> 0 | E17: =E39*E60 -> 0 | F17: =F39*F60 -> 0 | G17: =G39*G60 -> 0 | H17: =H39*H60 -> 0 | I17: =I39*I60 -> 0 | J17: =J39*J60 -> 0 | Q17: =SUM(D17:P17) -> 0
B18: New Zealand -Regulated | D18: =D40*D61 -> 0 | E18: =E40*E61 -> 0 | F18: =F40*F61 -> 0 | G18: =G40*G61 -> 0 | H18: =H40*H61 -> 0 | I18: =I40*I61 -> 0 | J18: =J40*J61 -> 0 | Q18: =SUM(D18:P18) -> 0
B19: Wafid (Gulf Countries)-Regulated | D19: =D41*D62 -> 0 | E19: =E41*E62 -> 0 | F19: =F41*F62 -> 0 | G19: =G41*G62 -> 0 | H19: =H41*H62 -> 0 | I19: =I41*I62 -> 0 | J19: =J41*J62 -> 0 | Q19: =SUM(D19:P19) -> 0
B20: European Countries- Open Access | D20: =D42*D63 -> 0 | E20: =E42*E63 -> 0 | F20: =F42*F63 -> 0 | G20: =G42*G63 -> 0 | H20: =H42*H63 -> 0 | I20: =I42*I63 -> 0 | J20: =J42*J63 -> 0 | Q20: =SUM(D20:P20) -> 0
B21: South Africa-Open Access | D21: =D43*D64 -> 0 | E21: =E43*E64 -> 0 | F21: =F43*F64 -> 0 | G21: =G43*G64 -> 0 | H21: =H43*H64 -> 0 | I21: =I43*I64 -> 0 | J21: =J43*J64 -> 0 | Q21: =SUM(D21:P21) -> 0
D22: =D44*D65 -> 0 | Q22: =SUM(D22:P22) -> 0
B23: Others -Open Access | D23: =D44*D65 -> 0 | E23: =E44*E65 -> 0 | F23: =F44*F65 -> 0 | G23: =G44*G65 -> 700000 | H23: =H44*H65 -> 1295000 | I23: =I44*I65 -> 2395750 | J23: =J44*J65 -> 4432137.5 | K23: =K44*K65 -> 6869813.1 | ... O23: =O44*O65 -> 18784645 | Q23: =SUM(D23:P23) -> 71144973
B26: Average no of Patient
B27: Travel Health Consultancy
B28: Fit to fly Exams | D28: 0 | E28: 0 | F28: 0 | G28: =(40/12)+F28 -> 3.3333333 | H28: =(77/12)+G28 -> 9.75 | I28: =(77/12)+H28 -> 16.166667 | J28: =(77/12)+I28 -> 22.583333 | K28: =(77/12)+J28 -> 29 | L28: =(77/12)+K28 -> 35.416667 | M28: =(77/12)+L28 -> 41.833333 | N28: =(77/12)+M28 -> 48.25 | O28: =(77/12)+N28 -> 54.666667 | Q28: =SUM(D28:O28) -> 261
B29: Vaccination Services | D29: 0 | E29: 0 | F29: 0 | G29: =(77/12)+F29 -> 6.4166667 | H29: =(77/12)+G29 -> 12.833333 | I29: =(77/12)+H29 -> 19.25 | J29: =(77/12)+I29 -> 25.666667 | K29: =(77/12)+J29 -> 32.083333 | L29: =(77/12)+K29 -> 38.5 | M29: =(77/12)+L29 -> 44.916667 | N29: =(77/12)+M29 -> 51.333333 | O29: =(77/12)+N29 -> 57.75 | Q29: =SUM(D29:O29) -> 288.75
B30: Travel Health Advisory/Consultancy Services | D30: 0 | E30: 0 | F30: 0 | G30: =(40/12)+F30 -> 3.3333333 | H30: =(77/12)+G30 -> 9.75 | I30: =(77/12)+H30 -> 16.166667 | J30: =(77/12)+I30 -> 22.583333 | K30: =(77/12)+J30 -> 29 | L30: =(77/12)+K30 -> 35.416667 | M30: =(77/12)+L30 -> 41.833333 | N30: =(77/12)+M30 -> 48.25 | O30: =(77/12)+N30 -> 54.666667 | Q30: =SUM(D30:O30) -> 261
B35: IMEs
B36: Australia- Regulated | D36: 9 | E36: 12 | F36: 28 | G36: 32 | H36: 38 | I36: 45 | J36: 55 | K36: 65 | L36: 75 | M36: 85 | N36: 95 | O36: 105 | Q36: =SUM(D36:O36) -> 644
B37: Canada- Regulated | Q37: =SUM(D37:P37) -> 0
B38: UK- Regulated | Q38: =SUM(D38:P38) -> 0
B39: USA- Regulated | Q39: =SUM(D39:P39) -> 0
B40: New Zealand -Regulated | Q40: =SUM(D40:P40) -> 0
B41: Wafid (Gulf Countries)-Regulated | Q41: =SUM(D41:P41) -> 0
B42: European Countries- Open Access | Q42: =SUM(D42:P42) -> 0
B43: South Africa-Open Access | Q43: =SUM(D43:P43) -> 0
B44: Others-Open Access | D44: 0 | E44: 0 | F44: 0 | G44: 10 | H44: =G44*1.85 -> 18.5 | I44: =H44*1.85 -> 34.225 | J44: =I44*1.85 -> 63.31625 | K44: =J44*1.55 -> 98.140188 | L44: =K44*1.4 -> 137.39626 | M44: =L44*1.25 -> 171.74533 | N44: =M44*1.25 -> 214.68166 | O44: =N44*1.25 -> 268.35208 | Q44: =SUM(D44:O44) -> 1016.3568 | S44: 0 | T44: 0 | U44: 0 | V44: 10 | W44: 15 | X44: 20 | Y44: 25 | Z44: 35 | AA44: 45 | AB44: 55 | AC44: 65 | AD44: 70
D45: =5000/12 -> 416.66667
Q46: =SUM(D46:P46) -> 0
B47: Average case - Price | Q47: =SUM(D47:P47) -> 0
B48: Travel Health Consultancy | D48: Average price spent per person | Q48: =SUM(D48:P48) -> 0
B49: Fit to fly Exams | D49: 30000 | E49: 30000 | F49: 30000 | G49: 30000 | H49: 30000 | I49: 30000 | J49: 30000 | K49: 30000 | L49: 30000 | M49: 30000 | N49: 30000 | O49: 30000 | Q49: =SUM(D49:O49) -> 360000
B50: Vaccination Services | D50: 80000 | E50: 80000 | F50: 80000 | G50: 80000 | H50: 80000 | I50: 80000 | J50: 80000 | K50: 80000 | L50: 80000 | M50: 80000 | N50: 80000 | O50: 80000 | Q50: =SUM(D50:O50) -> 960000
B51: Travel Health Advisory/Consultancy Services | D51: 50000 | E51: 50000 | F51: 50000 | G51: 50000 | H51: 50000 | I51: 50000 | J51: 50000 | K51: 50000 | L51: 50000 | M51: 50000 | N51: 50000 | O51: 50000 | Q51: =SUM(D51:O51) -> 600000
...

Sheet Computations-(OH)
A2: Computations-Outputs
D3: January | E3: February | F3: March | G3: April | H3: May | I3: June | J3: July | K3: August | L3: September | M3: October | N3: November | O3: December | P3: FY 1 | Q3: FY 2 | R3: FY 3 | S3: FY 4 | T3: FY 5
D4: NGN | E4: NGN | F4: NGN | G4: NGN | H4: NGN | I4: NGN | J4: NGN | K4: NGN | L4: NGN | M4: NGN | N4: NGN | O4: NGN | P4: NGN | Q4: NGN | R4: NGN | S4: NGN | T4: NGN
B5: Revenue
B6: ='Assumption-(OH)'!B4 -> Travel Health Consultancy | D6: ='Assumption-(OH)'!D5 -> 0 | E6: ='Assumption-(OH)'!E5 -> 0 | F6: ='Assumption-(OH)'!F5 -> 0 | G6: ='Assumption-(OH)'!G5 -> 613333.33 | H6: ='Assumption-(OH)'!H5 -> 1319166.7 | I6: ='Assumption-(OH)'!I5 -> 2025000 | J6: ='Assumption-(OH)'!J5 -> 2730833.3 | K6: ='Assumption-(OH)'!K5 -> 3436666.7 | ... O6: ='Assumption-(OH)'!O5 -> 6260000 | P6: =SUM(D6:O6) -> 30930000 | Q6: =P6*(1+'Assumption-(OH)'!E$71)*(1+'Assumption-(OH)'!E$74) -> 42683400 | R6: =Q6*(1+'Assumption-(OH)'!F$71)*(1+'Assumption-(OH)'!F$74) -> 58903092 | S6: =R6*(1+'Assumption-(OH)'!G$71)*(1+'Assumption-(OH)'!G$74) -> 81286267 | T6: =S6*(1+'Assumption-(OH)'!H$71)*(1+'Assumption-(OH)'!H$74) -> 1.1217505e+08
B7: ='Assumption-(OH)'!B13 -> IMEs | D7: ='Assumption-(OH)'!D13 -> 810000 | E7: ='Assumption-(OH)'!E13 -> 1200000 | F7: ='Assumption-(OH)'!F13 -> 2800000 | G7: ='Assumption-(OH)'!G13 -> 4380000 | H7: ='Assumption-(OH)'!H13 -> 5665000 | I7: ='Assumption-(OH)'!I13 -> 7570750 | J7: ='Assumption-(OH)'!J13 -> 10757138 | K7: ='Assumption-(OH)'!K13 -> 14344813 | ... O7: ='Assumption-(OH)'!O13 -> 30859645 | P7: =SUM(D7:O7) -> 1.4437997e+08 | Q7: =P7*(1+'Assumption-(OH)'!E$71)*(1+'Assumption-(OH)'!E$74) -> 1.9924436e+08 | R7: =Q7*(1+'Assumption-(OH)'!F$71)*(1+'Assumption-(OH)'!F$74) -> 2.7495722e+08 | S7: =R7*(1+'Assumption-(OH)'!G$71)*(1+'Assumption-(OH)'!G$74) -> 3.7944097e+08 | T7: =S7*(1+'Assumption-(OH)'!H$71)*(1+'Assumption-(OH)'!H$74) -> 5.2362853e+08
B9: Total Revenue | D9: =SUM(D6:D7) -> 810000 | E9: =SUM(E6:E7) -> 1200000 | F9: =SUM(F6:F7) -> 2800000 | G9: =SUM(G6:G7) -> 4993333.3 | H9: =SUM(H6:H7) -> 6984166.7 | I9: =SUM(I6:I7) -> 9595750 | J9: =SUM(J6:J7) -> 13487971 | K9: =SUM(K6:K7) -> 17781480 | ... T9: =SUM(T6:T7) -> 6.3580358e+08
B11: Cost of Revenue
B12: Direct Cost - Consumables & Reagents | C12: 0.35 | D12: =D$9*$C$12 -> 283500 | E12: =E$9*$C$12 -> 420000 | F12: =F$9*$C$12 -> 980000 | G12: =G$9*$C$12 -> 1747666.7 | H12: =H$9*$C$12 -> 2444458.3 | I12: =I$9*$C$12 -> 3358512.5 | J12: =J$9*$C$12 -> 4720789.8 | K12: =K$9*$C$12 -> 6223517.9 | ... O12: =O$9*$C$12 -> 12991876 | P12: =SUM(D12:O12) -> 61358491 | Q12: =P$9*(1+'Assumption-(OH)'!E$75)*'Assumption-(OH)'!$C$75 -> 34711375 | R12: =Q$9*(1+'Assumption-(OH)'!F$75)*'Assumption-(OH)'!$C$75 -> 47030757 | S12: =R$9*(1+'Assumption-(OH)'!G$75)*'Assumption-(OH)'!$C$75 -> 64902445 | T12: =S$9*(1+'Assumption-(OH)'!H$75)*'Assumption-(OH)'!$C$75 -> 87906756
B13: Direct Cost - Staff | D13: ='Assumption-(OH)'!D76/12 -> 1125643.5 | E13: =D13 -> 1125643.5 | F13: =E13 -> 1125643.5 | G13: =F13 -> 1125643.5 | H13: =G13 -> 1125643.5 | I13: =H13 -> 1125643.5 | J13: =I13 -> 1125643.5 | K13: =J13 -> 1125643.5 | L13: =K13 -> 1125643.5 | ... O13: =N13 -> 1125643.5 | P13: =SUM(D13:O13) -> 13507722 | Q13: =P$9*(1+'Assumption-(OH)'!E$75)*'Assumption-(OH)'!$C$75 -> 34711375 | R13: =Q$9*(1+'Assumption-(OH)'!F$75)*'Assumption-(OH)'!$C$75 -> 47030757 | S13: =R$9*(1+'Assumption-(OH)'!G$75)*'Assumption-(OH)'!$C$75 -> 64902445 | T13: =S$9*(1+'Assumption-(OH)'!H$75)*'Assumption-(OH)'!$C$75 -> 87906756
B14: Direct Cost - Sales Commission | C14: 0.015 | D14: ='Assumption-(OH)'!D77/12 -> 146091.64 | E14: =D14 -> 146091.64 | F14: =E14 -> 146091.64 | G14: =F14 -> 146091.64 | H14: =G14 -> 146091.64 | I14: =H14 -> 146091.64 | J14: =I14 -> 146091.64 | K14: =J14 -> 146091.64 | L14: =K14 -> 146091.64 | ... O14: =N14 -> 146091.64 | P14: =SUM(D14:O14) -> 1753099.7
B15: Direct Cost - Overheads & Others | C15: 0.05 | D15: =$C$15*D$9 -> 40500 | E15: =$C$15*E$9 -> 60000 | F15: =$C$15*F$9 -> 140000 | G15: =$C$15*G$9 -> 249666.67 | H15: =$C$15*H$9 -> 349208.33 | I15: =$C$15*I$9 -> 479787.5 | J15: =$C$15*J$9 -> 674398.54 | K15: =$C$15*K$9 -> 889073.99 | ... O15: =$C$15*O$9 -> 1855982.3 | P15: =SUM(D15:O15) -> 8765498.7 | Q15: =P$9*(1+'Assumption-(OH)'!$E78)*'Assumption-(OH)'!$C$78 -> 0 | R15: =Q$9*(1+'Assumption-(OH)'!$E78)*'Assumption-(OH)'!$C$78 -> 0 | S15: =R$9*(1+'Assumption-(OH)'!$E78)*'Assumption-(OH)'!$C$78 -> 0 | T15: =S$9*(1+'Assumption-(OH)'!$E78)*'Assumption-(OH)'!$C$78 -> 0
B17: Total Direct Cost | D17: =SUM(D12:D15) -> 1595735.2 | E17: =SUM(E12:E15) -> 1751735.2 | F17: =SUM(F12:F15) -> 2391735.2 | G17: =SUM(G12:G15) -> 3269068.5 | H17: =SUM(H12:H15) -> 4065401.8 | I17: =SUM(I12:I15) -> 5110035.2 | J17: =SUM(J12:J15) -> 6666923.5 | K17: =SUM(K12:K15) -> 8384327.1 | ... T17: =SUM(T12:T15) -> 1.7581351e+08
B19: Gross Profit | D19: =D9-D17 -> -785735.17 | E19: =E9-E17 -> -551735.17 | F19: =F9-F17 -> 408264.83 | G19: =G9-G17 -> 1724264.8 | H19: =H9-H17 -> 2918764.8 | I19: =I9-I17 -> 4485714.8 | J19: =J9-J17 -> 6821047.3 | K19: =K9-K17 -> 9397152.7 | ... T19: =T9-T17 -> 4.5999007e+08
B21: Operating expenses
B22: Indirect Staff Cost | D22: ='Assumption-(OH)'!$D$82/12 -> 0 | E22: =D22 -> 0 | F22: =E22 -> 0 | G22: =F22 -> 0 | H22: =G22 -> 0 | I22: =H22 -> 0 | J22: =I22 -> 0 | K22: =J22 -> 0 | L22: =K22 -> 0 | ... O22: =N22 -> 0 | P22: =SUM(D22:O22) -> 0 | Q22: =P22*(1+'Assumption-(OH)'!E$82) -> 0 | R22: =Q22*(1+'Assumption-(OH)'!F$82) -> 0 | S22: =R22*(1+'Assumption-(OH)'!G$82) -> 0 | T22: =S22*(1+'Assumption-(OH)'!H$82) -> 0
B23: Repair&Maintenance | D23: ='Assumption-(OH)'!D83/12 -> 78027.695 | E23: =D23 -> 78027.695 | F23: =E23 -> 78027.695 | G23: =F23 -> 78027.695 | H23: =G23 -> 78027.695 | I23: =H23 -> 78027.695 | J23: =I23 -> 78027.695 | K23: =J23 -> 78027.695 | L23: =K23 -> 78027.695 | ... O23: =N23 -> 78027.695 | P23: =SUM(D23:O23) -> 936332.34 | Q23: =P23*(1+'Assumption-(OH)'!E$72) -> 1076782.2 | R23: =Q23*(1+'Assumption-(OH)'!F$72) -> 1238299.5 | S23: =R23*(1+'Assumption-(OH)'!G$72) -> 1424044.5 | T23: =S23*(1+'Assumption-(OH)'!H$72) -> 1637651.1
B24: Bank Charges | D24: ='Assumption-(OH)'!D84/12 -> 1950.6924 | E24: =D24 -> 1950.6924 | F24: =E24 -> 1950.6924 | G24: =F24 -> 1950.6924 | H24: =G24 -> 1950.6924 | I24: =H24 -> 1950.6924 | J24: =I24 -> 1950.6924 | K24: =J24 -> 1950.6924 | L24: =K24 -> 1950.6924 | ... O24: =N24 -> 1950.6924 | P24: =SUM(D24:O24) -> 23408.309 | Q24: =P24*(1+'Assumption-(OH)'!E$72) -> 26919.555 | R24: =Q24*(1+'Assumption-(OH)'!F$72) -> 30957.488 | S24: =R24*(1+'Assumption-(OH)'!G$72) -> 35601.111 | T24: =S24*(1+'Assumption-(OH)'!H$72) -> 40941.278
B25: Advert, Printing & Stationery | D25: ='Assumption-(OH)'!$D$85/12 -> 500000 | E25: =D25 -> 500000 | F25: =E25 -> 500000 | G25: =F25 -> 500000 | H25: =G25 -> 500000 | I25: =H25 -> 500000 | J25: =I25 -> 500000 | K25: =J25 -> 500000 | L25: =K25 -> 500000 | ... O25: =N25 -> 500000 | P25: =SUM(D25:O25) -> 6000000 | Q25: =P25*(1+'Assumption-(OH)'!E$72) -> 6900000 | R25: =Q25*(1+'Assumption-(OH)'!F$72) -> 7935000 | S25: =R25*(1+'Assumption-(OH)'!G$72) -> 9125250 | T25: =S25*(1+'Assumption-(OH)'!H$72) -> 10494037
B26: Rent | D26: ='Assumption-(OH)'!D86/12 -> 4166.6667 | E26: =D26 -> 4166.6667 | F26: =E26 -> 4166.6667 | G26: =F26 -> 4166.6667 | H26: =G26 -> 4166.6667 | I26: =H26 -> 4166.6667 | J26: =I26 -> 4166.6667 | K26: =J26 -> 4166.6667 | L26: =K26 -> 4166.6667 | ... O26: =N26 -> 4166.6667 | P26: =SUM(D26:O26) -> 50000
B27: Internet | D27: ='Assumption-(OH)'!$D87/12 -> 33333.333 | E27: =D27 -> 33333.333 | F27: =E27 -> 33333.333 | G27: =F27 -> 33333.333 | H27: =G27 -> 33333.333 | I27: =H27 -> 33333.333 | J27: =I27 -> 33333.333 | K27: =J27 -> 33333.333 | L27: =K27 -> 33333.333 | ... O27: =N27 -> 33333.333 | P27: =SUM(D27:O27) -> 400000 | Q27: =P27*(1+'Assumption-(OH)'!E$72) -> 460000 | R27: =Q27*(1+'Assumption-(OH)'!F$72) -> 529000 | S27: =R27*(1+'Assumption-(OH)'!G$72) -> 608350 | T27: =S27*(1+'Assumption-(OH)'!H$72) -> 699602.5
B28: Cleaning | D28: ='Assumption-(OH)'!$D88/12 -> 0 | E28: =D28 -> 0 | F28: =E28 -> 0 | G28: =F28 -> 0 | H28: =G28 -> 0 | I28: =H28 -> 0 | J28: =I28 -> 0 | K28: =J28 -> 0 | L28: =K28 -> 0 | ... O28: =N28 -> 0 | P28: =SUM(D28:O28) -> 0 | Q28: =P28*(1+'Assumption-(OH)'!E$72) -> 0 | R28: =Q28*(1+'Assumption-(OH)'!F$72) -> 0 | S28: =R28*(1+'Assumption-(OH)'!G$72) -> 0 | T28: =S28*(1+'Assumption-(OH)'!H$72) -> 0
B29: Diesel & Fuel | D29: ='Assumption-(OH)'!$D89/12 -> 0 | E29: =D29 -> 0 | F29: =E29 -> 0 | G29: =F29 -> 0 | H29: =G29 -> 0 | I29: =H29 -> 0 | J29: =I29 -> 0 | K29: =J29 -> 0 | L29: =K29 -> 0 | ... O29: =N29 -> 0 | P29: =SUM(D29:O29) -> 0 | Q29: =P29*(1+'Assumption-(OH)'!E$72) -> 0 | R29: =Q29*(1+'Assumption-(OH)'!F$72) -> 0 | S29: =R29*(1+'Assumption-(OH)'!G$72) -> 0 | T29: =S29*(1+'Assumption-(OH)'!H$72) -> 0
B30: Electricity | D30: ='Assumption-(OH)'!$D90/12 -> 0 | E30: =D30 -> 0 | F30: =E30 -> 0 | G30: =F30 -> 0 | H30: =G30 -> 0 | I30: =H30 -> 0 | J30: =I30 -> 0 | K30: =J30 -> 0 | L30: =K30 -> 0 | ... O30: =N30 -> 0 | P30: =SUM(D30:O30) -> 0 | Q30: =P30*(1+'Assumption-(OH)'!E$72) -> 0 | R30: =Q30*(1+'Assumption-(OH)'!F$72) -> 0 | S30: =R30*(1+'Assumption-(OH)'!G$72) -> 0 | T30: =S30*(1+'Assumption-(OH)'!H$72) -> 0
B31: Security | D31: ='Assumption-(OH)'!$D91/12 -> 4166.6667 | E31: =D31 -> 4166.6667 | F31: =E31 -> 4166.6667 | G31: =F31 -> 4166.6667 | H31: =G31 -> 4166.6667 | I31: =H31 -> 4166.6667 | J31: =I31 -> 4166.6667 | K31: =J31 -> 4166.6667 | L31: =K31 -> 4166.6667 | ... O31: =N31 -> 4166.6667 | P31: =SUM(D31:O31) -> 50000 | Q31: =P31*(1+'Assumption-(OH)'!E$72) -> 57500 | R31: =Q31*(1+'Assumption-(OH)'!F$72) -> 66125 | S31: =R31*(1+'Assumption-(OH)'!G$72) -> 76043.75 | T31: =S31*(1+'Assumption-(OH)'!H$72) -> 87450.312
B32: Water | D32: ='Assumption-(OH)'!$D92/12 -> 8333.3333 | E32: =D32 -> 8333.3333 | F32: =E32 -> 8333.3333 | G32: =F32 -> 8333.3333 | H32: =G32 -> 8333.3333 | I32: =H32 -> 8333.3333 | J32: =I32 -> 8333.3333 | K32: =J32 -> 8333.3333 | L32: =K32 -> 8333.3333 | ... O32: =N32 -> 8333.3333 | P32: =SUM(D32:O32) -> 100000 | Q32: =P32*(1+'Assumption-(OH)'!E$72) -> 115000 | R32: =Q32*(1+'Assumption-(OH)'!F$72) -> 132250 | S32: =R32*(1+'Assumption-(OH)'!G$72) -> 152087.5 | T32: =S32*(1+'Assumption-(OH)'!H$72) -> 174900.62
B33: Insurance Expenses | D33: ='Assumption-(OH)'!$D94/12 -> 4166.6667 | E33: =D33 -> 4166.6667 | F33: =E33 -> 4166.6667 | G33: =F33 -> 4166.6667 | H33: =G33 -> 4166.6667 | I33: =H33 -> 4166.6667 | J33: =I33 -> 4166.6667 | K33: =J33 -> 4166.6667 | L33: =K33 -> 4166.6667 | ... O33: =N33 -> 4166.6667 | P33: =SUM(D33:O33) -> 50000
B35: Total Opex | D35: =SUM(D22:D33) -> 634145.05 | E35: =SUM(E22:E33) -> 634145.05 | F35: =SUM(F22:F33) -> 634145.05 | G35: =SUM(G22:G33) -> 634145.05 | H35: =SUM(H22:H33) -> 634145.05 | I35: =SUM(I22:I33) -> 634145.05 | J35: =SUM(J22:J33) -> 634145.05 | K35: =SUM(K22:K33) -> 634145.05 | ... P35: =SUM(P22:P33) -> 7609740.7 | Q35: =SUM(Q22:Q32) -> 8636201.8 | R35: =SUM(R22:R32) -> 9931632 | S35: =SUM(S22:S32) -> 11421377 | T35: =SUM(T22:T32) -> 13134583
B37: EBITDA | D37: =D19-D35 -> -1419880.2 | E37: =E19-E35 -> -1185880.2 | F37: =F19-F35 -> -225880.22 | G37: =G19-G35 -> 1090119.8 | H37: =H19-H35 -> 2284619.8 | I37: =I19-I35 -> 3851569.8 | J37: =J19-J35 -> 6186902.3 | K37: =K19-K35 -> 8763007.7 | ... T37: =T19-T35 -> 4.4685549e+08
B39: Depreciation Expenses | D39: ='Assumption-(OH)'!D93/12 -> 4166.6667 | E39: =D39 -> 4166.6667 | F39: =E39 -> 4166.6667 | G39: =F39 -> 4166.6667 | H39: =G39 -> 4166.6667 | I39: =H39 -> 4166.6667 | J39: =I39 -> 4166.6667 | K39: =J39 -> 4166.6667 | L39: =K39 -> 4166.6667 | ... O39: =N39 -> 4166.6667 | P39: =SUM(D39:O39) -> 50000
B41: Net Profit/(Loss) | D41: =D37-D39 -> -1424046.9 | E41: =E37-E39 -> -1190046.9 | F41: =F37-F39 -> -230046.89 | G41: =G37-G39 -> 1085953.1 | H41: =H37-H39 -> 2280453.1 | I41: =I37-I39 -> 3847403.1 | J41: =J37-J39 -> 6182735.6 | K41: =K37-K39 -> 8758841 | ... P41: =P37-P39 -> 82265421
B43: Accumulated EBITDA | D43: =D41 -> -1424046.9 | E43: =D43+E41 -> -2614093.8 | F43: =E43+F41 -> -2844140.7 | G43: =F43+G41 -> -1758187.6 | H43: =G43+H41 -> 522265.56 | I43: =H43+I41 -> 4369668.7 | J43: =I43+J41 -> 10552404 | K43: =J43+K41 -> 19311245 | L43: =K43+L41 -> 30832341 | ... O43: =N43+O41 -> 82265421 | P43: =P41 -> 82265421 | Q43: =P43+Q37 -> 2.4613423e+08 | R43: =Q43+R37 -> 4.760014e+08 | S43: =R43+S37 -> 7.9550237e+08 | T43: =S43+T37 -> 1.2423579e+09
B45: Total Investment
B47: Pay back Balance | D47: =D43-D45 -> -1424046.9 | E47: =E43-E45 -> -2614093.8 | F47: =F43-F45 -> -2844140.7 | G47: =G43-G45 -> -1758187.6 | H47: =H43-H45 -> 522265.56 | I47: =I43-I45 -> 4369668.7 | J47: =J43-J45 -> 10552404 | K47: =K43-K45 -> 19311245 | ... T47: =T43-T45 -> 1.2423579e+09
B49: Pay back Period | P49: =IF(P47>0,"1 Year"," ") -> 1 Year | Q49: =IF(Q47>0,"2 Year"," ") -> 2 Year | R49: =IF(R47>0,"3 Year"," ") -> 3 Year | S49: =IF(S47>0,"4 Year"," ") -> 4 Year | T49: =IF(T47>0,"5 Year"," ") -> 5 Year

Sheet Computations-Outputs
A2: Computations-Outputs
D3: January | E3: February | F3: March | G3: April | H3: May | I3: June | J3: July | K3: August | L3: September | M3: October | N3: November | O3: December | P3: FY 1 | Q3: FY 2 | R3: FY 3 | S3: FY 4 | T3: FY 5
D4: NGN | E4: NGN | F4: NGN | G4: NGN | H4: NGN | I4: NGN | J4: NGN | K4: NGN | L4: NGN | M4: NGN | N4: NGN | O4: NGN | P4: NGN | Q4: NGN | R4: NGN | S4: NGN | T4: NGN
B5: Revenue
B6: ='Assumption-(OH)'!#REF! -> #REF! | D6: ='Assumption-(OH)'!D5 -> 0 | E6: ='Assumption-(OH)'!E5 -> 0 | F6: ='Assumption-(OH)'!F5 -> 0 | G6: ='Assumption-(OH)'!G5 -> 613333.33 | H6: ='Assumption-(OH)'!H5 -> 1319166.7 | I6: ='Assumption-(OH)'!I5 -> 2025000 | J6: ='Assumption-(OH)'!J5 -> 2730833.3 | K6: ='Assumption-(OH)'!K5 -> 3436666.7 | ... O6: ='Assumption-(OH)'!O5 -> 6260000 | P6: =SUM(D6:O6) -> 30930000 | Q6: =P6*(1+'Assumption-(OH)'!E$71)*(1+'Assumption-(OH)'!E$74) -> 42683400 | R6: =Q6*(1+'Assumption-(OH)'!F$71)*(1+'Assumption-(OH)'!F$74) -> 58903092 | S6: =R6*(1+'Assumption-(OH)'!G$71)*(1+'Assumption-(OH)'!G$74) -> 81286267 | T6: =S6*(1+'Assumption-(OH)'!H$71)*(1+'Assumption-(OH)'!H$74) -> 1.1217505e+08
B7: ='Assumption-(OH)'!B13 -> IMEs | D7: ='Assumption-(OH)'!D13 -> 810000 | E7: ='Assumption-(OH)'!E13 -> 1200000 | F7: ='Assumption-(OH)'!F13 -> 2800000 | G7: ='Assumption-(OH)'!G13 -> 4380000 | H7: ='Assumption-(OH)'!H13 -> 5665000 | I7: ='Assumption-(OH)'!I13 -> 7570750 | J7: ='Assumption-(OH)'!J13 -> 10757138 | K7: ='Assumption-(OH)'!K13 -> 14344813 | ... O7: ='Assumption-(OH)'!O13 -> 30859645 | P7: =SUM(D7:O7) -> 1.4437997e+08 | Q7: =P7*(1+'Assumption-(OH)'!E$71)*(1+'Assumption-(OH)'!E$74) -> 1.9924436e+08 | R7: =Q7*(1+'Assumption-(OH)'!F$71)*(1+'Assumption-(OH)'!F$74) -> 2.7495722e+08 | S7: =R7*(1+'Assumption-(OH)'!G$71)*(1+'Assumption-(OH)'!G$74) -> 3.7944097e+08 | T7: =S7*(1+'Assumption-(OH)'!H$71)*(1+'Assumption-(OH)'!H$74) -> 5.2362853e+08
B9: Total Revenue | D9: =SUM(D6:D7) -> 810000 | E9: =SUM(E6:E7) -> 1200000 | F9: =SUM(F6:F7) -> 2800000 | G9: =SUM(G6:G7) -> 4993333.3 | H9: =SUM(H6:H7) -> 6984166.7 | I9: =SUM(I6:I7) -> 9595750 | J9: =SUM(J6:J7) -> 13487971 | K9: =SUM(K6:K7) -> 17781480 | ... T9: =SUM(T6:T7) -> 6.3580358e+08
B11: Cost of Revenue
B12: Direct cost reagent | D12: ='Assumption-(OH)'!$C75*D$9 -> 145800 | E12: ='Assumption-(OH)'!$C75*E$9 -> 216000 | F12: ='Assumption-(OH)'!$C75*F$9 -> 504000 | G12: ='Assumption-(OH)'!$C75*G$9 -> 898800 | H12: ='Assumption-(OH)'!$C75*H$9 -> 1257150 | I12: ='Assumption-(OH)'!$C75*I$9 -> 1727235 | J12: ='Assumption-(OH)'!$C75*J$9 -> 2427834.8 | K12: ='Assumption-(OH)'!$C75*K$9 -> 3200666.4 | ... O12: ='Assumption-(OH)'!$C75*O$9 -> 6681536.1 | P12: =SUM(D12:O12) -> 31555795 | Q12: =P$9*(1+'Assumption-(OH)'!E$75)*'Assumption-(OH)'!$C$75 -> 34711375 | R12: =Q$9*(1+'Assumption-(OH)'!F$75)*'Assumption-(OH)'!$C$75 -> 47030757 | S12: =R$9*(1+'Assumption-(OH)'!G$75)*'Assumption-(OH)'!$C$75 -> 64902445 | T12: =S$9*(1+'Assumption-(OH)'!H$75)*'Assumption-(OH)'!$C$75 -> 87906756
B13: Other direct cost | D13: ='Assumption-(OH)'!$C78*D$9 -> 0 | E13: ='Assumption-(OH)'!$C78*E$9 -> 0 | F13: ='Assumption-(OH)'!$C78*F$9 -> 0 | G13: ='Assumption-(OH)'!$C78*G$9 -> 0 | H13: ='Assumption-(OH)'!$C78*H$9 -> 0 | I13: ='Assumption-(OH)'!$C78*I$9 -> 0 | J13: ='Assumption-(OH)'!$C78*J$9 -> 0 | K13: ='Assumption-(OH)'!$C78*K$9 -> 0 | ... O13: ='Assumption-(OH)'!$C78*O$9 -> 0 | P13: =SUM(D13:O13) -> 0 | Q13: =P$9*(1+'Assumption-(OH)'!$E78)*'Assumption-(OH)'!$C$78 -> 0 | R13: =Q$9*(1+'Assumption-(OH)'!$E78)*'Assumption-(OH)'!$C$78 -> 0 | S13: =R$9*(1+'Assumption-(OH)'!$E78)*'Assumption-(OH)'!$C$78 -> 0 | T13: =S$9*(1+'Assumption-(OH)'!$E78)*'Assumption-(OH)'!$C$78 -> 0
B15: Total Direct Cost | D15: =SUM(D12:D13) -> 145800 | E15: =SUM(E12:E13) -> 216000 | F15: =SUM(F12:F13) -> 504000 | G15: =SUM(G12:G13) -> 898800 | H15: =SUM(H12:H13) -> 1257150 | I15: =SUM(I12:I13) -> 1727235 | J15: =SUM(J12:J13) -> 2427834.8 | K15: =SUM(K12:K13) -> 3200666.4 | ... T15: =SUM(T12:T13) -> 87906756
B17: Gross Profit | D17: =D9-D15 -> 664200 | E17: =E9-E15 -> 984000 | F17: =F9-F15 -> 2296000 | G17: =G9-G15 -> 4094533.3 | H17: =H9-H15 -> 5727016.7 | I17: =I9-I15 -> 7868515 | J17: =J9-J15 -> 11060136 | K17: =K9-K15 -> 14580813 | ... T17: =T9-T15 -> 5.4789682e+08
B19: Operating expenses
B20: Staff cost | D20: ='Assumption-(OH)'!$D$82/12 -> 0 | E20: ='Assumption-(OH)'!$D$82/12 -> 0 | F20: ='Assumption-(OH)'!$D$82/12 -> 0 | G20: ='Assumption-(OH)'!$D$82/12 -> 0 | H20: ='Assumption-(OH)'!$D$82/12 -> 0 | I20: ='Assumption-(OH)'!$D$82/12 -> 0 | J20: ='Assumption-(OH)'!$D$82/12 -> 0 | K20: ='Assumption-(OH)'!$D$82/12 -> 0 | ... O20: ='Assumption-(OH)'!$D$82/12 -> 0 | P20: =SUM(D20:O20) -> 0 | Q20: =P20*(1+'Assumption-(OH)'!E$82) -> 0 | R20: =Q20*(1+'Assumption-(OH)'!F$82) -> 0 | S20: =R20*(1+'Assumption-(OH)'!G$82) -> 0 | T20: =S20*(1+'Assumption-(OH)'!H$82) -> 0
B21: Repair&Maintenance | D21: ='Computations-Outputs'!$D$9*'Assumption-(OH)'!$C$83 -> 16200 | E21: ='Computations-Outputs'!$D$9*'Assumption-(OH)'!$C$83 -> 16200 | F21: ='Computations-Outputs'!$D$9*'Assumption-(OH)'!$C$83 -> 16200 | G21: ='Computations-Outputs'!$D$9*'Assumption-(OH)'!$C$83 -> 16200 | H21: ='Computations-Outputs'!$D$9*'Assumption-(OH)'!$C$83 -> 16200 | I21: ='Computations-Outputs'!$D$9*'Assumption-(OH)'!$C$83 -> 16200 | J21: ='Computations-Outputs'!$D$9*'Assumption-(OH)'!$C$83 -> 16200 | K21: ='Computations-Outputs'!$D$9*'Assumption-(OH)'!$C$83 -> 16200 | ... O21: ='Computations-Outputs'!$D$9*'Assumption-(OH)'!$C$83 -> 16200 | P21: =SUM(D21:O21) -> 194400 | Q21: =P21*(1+'Assumption-(OH)'!E$72) -> 223560 | R21: =Q21*(1+'Assumption-(OH)'!F$72) -> 257094 | S21: =R21*(1+'Assumption-(OH)'!G$72) -> 295658.1 | T21: =S21*(1+'Assumption-(OH)'!H$72) -> 340006.81
B22: Bank Charges | D22: ='Assumption-(OH)'!$C$84*'Computations-Outputs'!$D$9 -> 405 | E22: ='Assumption-(OH)'!$C$84*'Computations-Outputs'!$D$9 -> 405 | F22: ='Assumption-(OH)'!$C$84*'Computations-Outputs'!$D$9 -> 405 | G22: ='Assumption-(OH)'!$C$84*'Computations-Outputs'!$D$9 -> 405 | H22: ='Assumption-(OH)'!$C$84*'Computations-Outputs'!$D$9 -> 405 | I22: ='Assumption-(OH)'!$C$84*'Computations-Outputs'!$D$9 -> 405 | J22: ='Assumption-(OH)'!$C$84*'Computations-Outputs'!$D$9 -> 405 | K22: ='Assumption-(OH)'!$C$84*'Computations-Outputs'!$D$9 -> 405 | ... O22: ='Assumption-(OH)'!$C$84*'Computations-Outputs'!$D$9 -> 405 | P22: =SUM(D22:O22) -> 4860 | Q22: =P22*(1+'Assumption-(OH)'!E$72) -> 5589 | R22: =Q22*(1+'Assumption-(OH)'!F$72) -> 6427.35 | S22: =R22*(1+'Assumption-(OH)'!G$72) -> 7391.4525 | T22: =S22*(1+'Assumption-(OH)'!H$72) -> 8500.1704
B23: Printing & Stationery | D23: ='Assumption-(OH)'!$D$85/12 -> 500000 | E23: ='Assumption-(OH)'!$D$85/12 -> 500000 | F23: ='Assumption-(OH)'!$D$85/12 -> 500000 | G23: ='Assumption-(OH)'!$D$85/12 -> 500000 | H23: ='Assumption-(OH)'!$D$85/12 -> 500000 | I23: ='Assumption-(OH)'!$D$85/12 -> 500000 | J23: ='Assumption-(OH)'!$D$85/12 -> 500000 | K23: ='Assumption-(OH)'!$D$85/12 -> 500000 | ... O23: ='Assumption-(OH)'!$D$85/12 -> 500000 | P23: =SUM(D23:O23) -> 6000000 | Q23: =P23*(1+'Assumption-(OH)'!E$72) -> 6900000 | R23: =Q23*(1+'Assumption-(OH)'!F$72) -> 7935000 | S23: =R23*(1+'Assumption-(OH)'!G$72) -> 9125250 | T23: =S23*(1+'Assumption-(OH)'!H$72) -> 10494037
B24: Internet | D24: ='Assumption-(OH)'!$D87/12 -> 33333.333 | E24: ='Assumption-(OH)'!$D87/12 -> 33333.333 | F24: ='Assumption-(OH)'!$D87/12 -> 33333.333 | G24: ='Assumption-(OH)'!$D87/12 -> 33333.333 | H24: ='Assumption-(OH)'!$D87/12 -> 33333.333 | I24: ='Assumption-(OH)'!$D87/12 -> 33333.333 | J24: ='Assumption-(OH)'!$D87/12 -> 33333.333 | K24: ='Assumption-(OH)'!$D87/12 -> 33333.333 | ... O24: ='Assumption-(OH)'!$D87/12 -> 33333.333 | P24: =SUM(D24:O24) -> 400000 | Q24: =P24*(1+'Assumption-(OH)'!E$72) -> 460000 | R24: =Q24*(1+'Assumption-(OH)'!F$72) -> 529000 | S24: =R24*(1+'Assumption-(OH)'!G$72) -> 608350 | T24: =S24*(1+'Assumption-(OH)'!H$72) -> 699602.5
B25: Cleaning | D25: ='Assumption-(OH)'!$D88/12 -> 0 | E25: ='Assumption-(OH)'!$D88/12 -> 0 | F25: ='Assumption-(OH)'!$D88/12 -> 0 | G25: ='Assumption-(OH)'!$D88/12 -> 0 | H25: ='Assumption-(OH)'!$D88/12 -> 0 | I25: ='Assumption-(OH)'!$D88/12 -> 0 | J25: ='Assumption-(OH)'!$D88/12 -> 0 | K25: ='Assumption-(OH)'!$D88/12 -> 0 | ... O25: ='Assumption-(OH)'!$D88/12 -> 0 | P25: =SUM(D25:O25) -> 0 | Q25: =P25*(1+'Assumption-(OH)'!E$72) -> 0 | R25: =Q25*(1+'Assumption-(OH)'!F$72) -> 0 | S25: =R25*(1+'Assumption-(OH)'!G$72) -> 0 | T25: =S25*(1+'Assumption-(OH)'!H$72) -> 0
B26: Diesel & Fuel | D26: ='Assumption-(OH)'!$D89/12 -> 0 | E26: ='Assumption-(OH)'!$D89/12 -> 0 | F26: ='Assumption-(OH)'!$D89/12 -> 0 | G26: ='Assumption-(OH)'!$D89/12 -> 0 | H26: ='Assumption-(OH)'!$D89/12 -> 0 | I26: ='Assumption-(OH)'!$D89/12 -> 0 | J26: ='Assumption-(OH)'!$D89/12 -> 0 | K26: ='Assumption-(OH)'!$D89/12 -> 0 | ... O26: ='Assumption-(OH)'!$D89/12 -> 0 | P26: =SUM(D26:O26) -> 0 | Q26: =P26*(1+'Assumption-(OH)'!E$72) -> 0 | R26: =Q26*(1+'Assumption-(OH)'!F$72) -> 0 | S26: =R26*(1+'Assumption-(OH)'!G$72) -> 0 | T26: =S26*(1+'Assumption-(OH)'!H$72) -> 0
B27: Electricity | D27: ='Assumption-(OH)'!$D90/12 -> 0 | E27: ='Assumption-(OH)'!$D90/12 -> 0 | F27: ='Assumption-(OH)'!$D90/12 -> 0 | G27: ='Assumption-(OH)'!$D90/12 -> 0 | H27: ='Assumption-(OH)'!$D90/12 -> 0 | I27: ='Assumption-(OH)'!$D90/12 -> 0 | J27: ='Assumption-(OH)'!$D90/12 -> 0 | K27: ='Assumption-(OH)'!$D90/12 -> 0 | ... O27: ='Assumption-(OH)'!$D90/12 -> 0 | P27: =SUM(D27:O27) -> 0 | Q27: =P27*(1+'Assumption-(OH)'!E$72) -> 0 | R27: =Q27*(1+'Assumption-(OH)'!F$72) -> 0 | S27: =R27*(1+'Assumption-(OH)'!G$72) -> 0 | T27: =S27*(1+'Assumption-(OH)'!H$72) -> 0
B28: Security | D28: ='Assumption-(OH)'!$D91/12 -> 4166.6667 | E28: ='Assumption-(OH)'!$D91/12 -> 4166.6667 | F28: ='Assumption-(OH)'!$D91/12 -> 4166.6667 | G28: ='Assumption-(OH)'!$D91/12 -> 4166.6667 | H28: ='Assumption-(OH)'!$D91/12 -> 4166.6667 | I28: ='Assumption-(OH)'!$D91/12 -> 4166.6667 | J28: ='Assumption-(OH)'!$D91/12 -> 4166.6667 | K28: ='Assumption-(OH)'!$D91/12 -> 4166.6667 | ... O28: ='Assumption-(OH)'!$D91/12 -> 4166.6667 | P28: =SUM(D28:O28) -> 50000 | Q28: =P28*(1+'Assumption-(OH)'!E$72) -> 57500 | R28: =Q28*(1+'Assumption-(OH)'!F$72) -> 66125 | S28: =R28*(1+'Assumption-(OH)'!G$72) -> 76043.75 | T28: =S28*(1+'Assumption-(OH)'!H$72) -> 87450.312
B29: Water | D29: ='Assumption-(OH)'!$D92/12 -> 8333.3333 | E29: ='Assumption-(OH)'!$D92/12 -> 8333.3333 | F29: ='Assumption-(OH)'!$D92/12 -> 8333.3333 | G29: ='Assumption-(OH)'!$D92/12 -> 8333.3333 | H29: ='Assumption-(OH)'!$D92/12 -> 8333.3333 | I29: ='Assumption-(OH)'!$D92/12 -> 8333.3333 | J29: ='Assumption-(OH)'!$D92/12 -> 8333.3333 | K29: ='Assumption-(OH)'!$D92/12 -> 8333.3333 | ... O29: ='Assumption-(OH)'!$D92/12 -> 8333.3333 | P29: =SUM(D29:O29) -> 100000 | Q29: =P29*(1+'Assumption-(OH)'!E$72) -> 115000 | R29: =Q29*(1+'Assumption-(OH)'!F$72) -> 132250 | S29: =R29*(1+'Assumption-(OH)'!G$72) -> 152087.5 | T29: =S29*(1+'Assumption-(OH)'!H$72) -> 174900.62
B31: Total Opex | D31: =SUM(D20:D29) -> 562438.33 | E31: =SUM(E20:E29) -> 562438.33 | F31: =SUM(F20:F29) -> 562438.33 | G31: =SUM(G20:G29) -> 562438.33 | H31: =SUM(H20:H29) -> 562438.33 | I31: =SUM(I20:I29) -> 562438.33 | J31: =SUM(J20:J29) -> 562438.33 | K31: =SUM(K20:K29) -> 562438.33 | ... T31: =SUM(T20:T29) -> 11804498
B33: EBITDA | D33: =D17-D31 -> 101761.67 | E33: =E17-E31 -> 421561.67 | F33: =F17-F31 -> 1733561.7 | G33: =G17-G31 -> 3532095 | H33: =H17-H31 -> 5164578.3 | I33: =I17-I31 -> 7306076.7 | J33: =J17-J31 -> 10497698 | K33: =K17-K31 -> 14018375 | ... T33: =T17-T31 -> 5.3609233e+08
B35: Accumulated EBITDA | D35: =D33 -> 101761.67 | E35: =D35+E33 -> 523323.33 | F35: =E35+F33 -> 2256885 | G35: =F35+G33 -> 5788980 | H35: =G35+H33 -> 10953558 | I35: =H35+I33 -> 18259635 | J35: =I35+J33 -> 28757333 | K35: =J35+K33 -> 42775708 | L35: =K35+L33 -> 60569165 | ... O35: =N35+O33 -> 1.3700492e+08 | P35: =P33 -> 1.3700492e+08 | Q35: =P35+Q33 -> 3.3645966e+08 | R35: =Q35+R33 -> 6.1436332e+08 | S35: =R35+S33 -> 9.9992332e+08 | T35: =S35+T33 -> 1.5360157e+09
B37: Total Investment
B39: Pay back Balance | D39: =D35-D37 -> 101761.67 | E39: =E35-E37 -> 523323.33 | F39: =F35-F37 -> 2256885 | G39: =G35-G37 -> 5788980 | H39: =H35-H37 -> 10953558 | I39: =I35-I37 -> 18259635 | J39: =J35-J37 -> 28757333 | K39: =K35-K37 -> 42775708 | ... T39: =T35-T37 -> 1.5360157e+09
B41: Pay back Period | P41: =IF(P39>0,"1 Year"," ") -> 1 Year | Q41: =IF(Q39>0,"2 Year"," ") -> 2 Year | R41: =IF(R39>0,"3 Year"," ") -> 3 Year | S41: =IF(S39>0,"4 Year"," ") -> 4 Year | T41: =IF(T39>0,"5 Year"," ") -> 5 Year
