Workbook
Name afril: #REF!
Name BS: #REF!
Name costaa: #REF!
Name Department: #REF!
Name expense: '[1]Exp scxhedule'!$AU$10:$AU$43
Name Expenses: #REF!
Name F: #REF!
Name fs: #REF!
Name GGGG: #REF!
Name groupincome: #REF!
Name LOCATION: [1]Payables!$W$4:$W$6
Name Locattion: '[1]Exp scxhedule'!$AX$10:$AX$11
Name MANS: #REF!
Name OLDMAN: #REF!
Name PAC: #REF!
Name PL: #REF!
Name REGISTRAR: #REF!
Name SCHD3: #REF!
Name SCHED1: #REF!
Name SCHED2: #REF!
Name SCHED3: #REF!
Name SCHED4: #REF!
Name SEMI: #REF!
Name SSES: #REF!
Name STAT: '[1]Exp scxhedule'!$AY$10:$AY$13
Name SUMMARY: #REF!
Name yyy: #REF!

Sheet Assumption (Advisory)
B1: Assumptions-Inputs
D3: Jan | E3: Feb | F3: Mar | G3: Apr | H3: May | I3: Jun | J3: Jul | K3: Aug | L3: Sep | M3: Oct | N3: Nov | O3: Dec | P3: Total
B4: Live_Case
B5: Consultancy | D5: =SUM(D6:D11) -> 16416667 | E5: =SUM(E6:E11) -> 16416667 | F5: =SUM(F6:F11) -> 16416667 | G5: =SUM(G6:G11) -> 16416667 | H5: =SUM(H6:H11) -> 16416667 | I5: =SUM(I6:I11) -> 16416667 | J5: =SUM(J6:J11) -> 16416667 | K5: =SUM(K6:K11) -> 16416667 | ... O5: =SUM(O6:O11) -> 16416667 | P5: =SUM(P6:P9) -> 197000000
B6: Needs Assessment/ Site inspections/Audits | D6: =70000000/12 -> 5833333.3 | E6: =D6 -> 5833333.3 | F6: =E6 -> 5833333.3 | G6: =F6 -> 5833333.3 | H6: =G6 -> 5833333.3 | I6: =H6 -> 5833333.3 | J6: =I6 -> 5833333.3 | K6: =J6 -> 5833333.3 | L6: =K6 -> 5833333.3 | ... O6: =N6 -> 5833333.3 | P6: =SUM(D6:O6) -> 70000000
B7: Health promotion programs (eg EAP) | D7: =D22*D35 -> 6000000 | E7: =D7 -> 6000000 | F7: =E7 -> 6000000 | G7: =F7 -> 6000000 | H7: =G7 -> 6000000 | I7: =H7 -> 6000000 | J7: =I7 -> 6000000 | K7: =J7 -> 6000000 | L7: =K7 -> 6000000 | ... O7: =N7 -> 6000000 | P7: =SUM(D7:O7) -> 72000000
B8: Professional Services (MRO Services/OHP report & recommendation) | D8: =20000000/12 -> 1666666.7 | E8: =D8 -> 1666666.7 | F8: =E8 -> 1666666.7 | G8: =F8 -> 1666666.7 | H8: =G8 -> 1666666.7 | I8: =H8 -> 1666666.7 | J8: =I8 -> 1666666.7 | K8: =J8 -> 1666666.7 | L8: =K8 -> 1666666.7 | ... O8: =N8 -> 1666666.7 | P8: =SUM(D8:O8) -> 20000000
B9: OH Trainings | D9: =35000000/12 -> 2916666.7 | E9: =35000000/12 -> 2916666.7 | F9: =35000000/12 -> 2916666.7 | G9: =35000000/12 -> 2916666.7 | H9: =35000000/12 -> 2916666.7 | I9: =35000000/12 -> 2916666.7 | J9: =35000000/12 -> 2916666.7 | K9: =35000000/12 -> 2916666.7 | ... O9: =35000000/12 -> 2916666.7 | P9: =SUM(D9:O9) -> 35000000
B12: Occupational Hygiene | D12: =SUM(D13:D18) -> 0 | E12: =SUM(E13:E18) -> 135000000 | F12: =SUM(F13:F18) -> 0 | G12: =SUM(G13:G18) -> 0 | H12: =SUM(H13:H18) -> 135000000 | I12: =SUM(I13:I18) -> 0 | J12: =SUM(J13:J18) -> 0 | K12: =SUM(K13:K18) -> 135000000 | ... O12: =SUM(O13:O18) -> 0 | P12: =SUM(D12:O12) -> 540000000
B13: Microbiologic Audits (Water testing) | C13: 0.5 | E13: =$C13*50000000 -> 25000000 | H13: =$C13*50000000 -> 25000000 | K13: =$C13*50000000 -> 25000000 | N13: =$C13*50000000 -> 25000000 | P13: =SUM(D13:O13) -> 100000000
B14: Physical Hazards Measurements (Noise, Light, etc) | C14: 0.1 | E14: =$C14*50000000 -> 5000000 | H14: =$C14*50000000 -> 5000000 | K14: =$C14*50000000 -> 5000000 | N14: =$C14*50000000 -> 5000000 | P14: =SUM(D14:O14) -> 20000000
B15: Work place Hygiene Assessments (Ergonomic surveys) | C15: 0.1 | E15: =$C15*50000000 -> 5000000 | H15: =$C15*50000000 -> 5000000 | K15: =$C15*50000000 -> 5000000 | N15: =$C15*50000000 -> 5000000 | P15: =SUM(D15:O15) -> 20000000
B16: Calibration/Maintenance | C16: 0.3 | E16: =E30*E43 -> 100000000 | H16: =H30*H43 -> 100000000 | K16: =K30*K43 -> 100000000 | N16: =N30*N43 -> 100000000 | P16: =SUM(D16:O16) -> 400000000
P18: =P12+P5 -> 737000000
B19: Average no of Patient
B20: Consultancy
B21: Needs Assessment/ Site inspections/Audits | D21: 2 | E21: =D21 -> 2 | F21: =E21 -> 2 | G21: =F21 -> 2 | H21: =G21 -> 2 | I21: =H21 -> 2 | J21: =I21 -> 2 | K21: =J21 -> 2 | L21: =K21 -> 2 | ... O21: =N21 -> 2 | P21: =SUM(D21:O21) -> 24
B22: Health promotion programs (eg EAP) | D22: 30 | E22: =D22 -> 30 | F22: =E22 -> 30 | G22: =F22 -> 30 | H22: =G22 -> 30 | I22: =H22 -> 30 | J22: =I22 -> 30 | K22: =J22 -> 30 | L22: =K22 -> 30 | ... O22: =N22 -> 30 | P22: =SUM(D22:O22) -> 360
B23: Professional Services (MRO Services/OHP report & recommendation) | D23: 30 | E23: =D23 -> 30 | F23: =E23 -> 30 | G23: =F23 -> 30 | H23: =G23 -> 30 | I23: =H23 -> 30 | J23: =I23 -> 30 | K23: =J23 -> 30 | L23: =K23 -> 30 | ... O23: =N23 -> 30 | P23: =SUM(D23:O23) -> 360
B24: OH Trainings | D24: 10 | E24: =D24 -> 10 | F24: =E24 -> 10 | G24: =F24 -> 10 | H24: =G24 -> 10 | I24: =H24 -> 10 | J24: =I24 -> 10 | K24: =J24 -> 10 | L24: =K24 -> 10 | ... O24: =N24 -> 10 | P24: =SUM(D24:O24) -> 120
B26: Occupational Hygiene
B27: Microbiologic Audits (Water testing) | D27: 3 | E27: 3 | F27: 3 | G27: 3 | H27: 3 | I27: 3 | J27: 3 | K27: 3 | L27: 3 | M27: 3 | N27: 3 | O27: 3 | P27: =SUM(D27:O27) -> 36
B28: Physical Hazards Measurements (Noise, Light, etc) | D28: 3 | E28: =D28 -> 3 | F28: =E28 -> 3 | G28: =F28 -> 3 | H28: =G28 -> 3 | I28: =H28 -> 3 | J28: =I28 -> 3 | K28: =J28 -> 3 | L28: =K28 -> 3 | ... O28: =N28 -> 3 | P28: =SUM(D28:O28) -> 36
B29: Work place Hygiene Assessments (Ergonomic surveys) | D29: 5 | E29: =D29 -> 5 | F29: =E29 -> 5 | G29: =F29 -> 5 | H29: =G29 -> 5 | I29: =H29 -> 5 | J29: =I29 -> 5 | K29: =J29 -> 5 | L29: =K29 -> 5 | ... O29: =N29 -> 5 | P29: =SUM(D29:O29) -> 60
B30: Calibration/Maintenance | E30: 2 | H30: 2 | K30: 2 | N30: 2 | P30: =SUM(D30:O30) -> 8
B32: Average case - Price
B33: Consultancy | D33: Average price spent per person
B34: Needs Assessment/ Site inspections/Audits | D34: 2000000 | E34: 2000000 | F34: 2000000 | G34: 2000000 | H34: 2000000 | I34: 2000000 | J34: 2000000 | K34: 2000000 | L34: 2000000 | M34: 2000000 | N34: 2000000 | O34: 2000000
B35: Health promotion programs (eg EAP) | D35: 200000 | E35: =D35 -> 200000 | F35: =E35 -> 200000 | G35: =F35 -> 200000 | H35: =G35 -> 200000 | I35: =H35 -> 200000 | J35: =I35 -> 200000 | K35: =J35 -> 200000 | L35: =K35 -> 200000 | ... O35: =N35 -> 200000
B36: Professional Services (MRO Services/OHP report & recommendation) | D36: 50000 | E36: =D36 -> 50000 | F36: =E36 -> 50000 | G36: =F36 -> 50000 | H36: =G36 -> 50000 | I36: =H36 -> 50000 | J36: =I36 -> 50000 | K36: =J36 -> 50000 | L36: =K36 -> 50000 | ... O36: =N36 -> 50000
B37: OH Trainings | D37: 200000 | E37: =D37 -> 200000 | F37: =E37 -> 200000 | G37: =F37 -> 200000 | H37: =G37 -> 200000 | I37: =H37 -> 200000 | J37: =I37 -> 200000 | K37: =J37 -> 200000 | L37: =K37 -> 200000 | ... O37: =N37 -> 200000
B39: Occupational Hygiene
B40: Microbiologic Audits (Water testing) | D40: 1388888.8 | E40: =D40 -> 1388888.8 | F40: =E40 -> 1388888.8 | G40: =F40 -> 1388888.8 | H40: =G40 -> 1388888.8 | I40: =H40 -> 1388888.8 | J40: =I40 -> 1388888.8 | K40: =J40 -> 1388888.8 | L40: =K40 -> 1388888.8 | ... O40: =N40 -> 1388888.8
B41: Physical Hazards Measurements (Noise, Light, etc) | D41: 555555.55 | E41: =D41 -> 555555.55 | F41: =E41 -> 555555.55 | G41: =F41 -> 555555.55 | H41: =G41 -> 555555.55 | I41: =H41 -> 555555.55 | J41: =I41 -> 555555.55 | K41: =J41 -> 555555.55 | L41: =K41 -> 555555.55 | ... O41: =N41 -> 555555.55
B42: Work place Hygiene Assessments (Ergonomic surveys) | D42: 333333.33 | E42: =D42 -> 333333.33 | F42: =E42 -> 333333.33 | G42: =F42 -> 333333.33 | H42: =G42 -> 333333.33 | I42: =H42 -> 333333.33 | J42: =I42 -> 333333.33 | K42: =J42 -> 333333.33 | L42: =K42 -> 333333.33 | ... O42: =N42 -> 333333.33
B43: Calibration/Maintenance | E43: 50000000 | H43: 50000000 | K43: 50000000 | N43: 50000000
B46: Other Inputs
D47: FY 1 | E47: FY 2 | F47: FY 3 | G47: FY 4 | H47: FY 5
B48: Price Inflation | E48: 0.15 | F48: 0.15 | G48: 0.15 | H48: 0.15
B49: Cost Inflation | E49: 0.15 | F49: 0.15 | G49: 0.15 | H49: 0.15
...

Sheet Computations (Advisory)
A2: Computations-Outputs
D3: Jan | E3: Feb | F3: Mar | G3: Apr | H3: May | I3: Jun | J3: Jul | K3: Aug | L3: Sep | M3: Oct | N3: Nov | O3: Dec | P3: FY 1 | Q3: FY 2 | R3: FY 3 | S3: FY 4 | T3: FY 5
D4: ₦ | E4: ₦ | F4: ₦ | G4: ₦ | H4: ₦ | I4: ₦ | J4: ₦ | K4: ₦ | L4: ₦ | M4: ₦ | N4: ₦ | O4: ₦ | P4: ₦ | Q4: NGN | R4: NGN | S4: NGN | T4: NGN
B5: Revenue
B6: ='Assumption (Advisory)'!B5 -> Consultancy | D6: ='Assumption (Advisory)'!D5 -> 16416667 | E6: ='Assumption (Advisory)'!E5 -> 16416667 | F6: ='Assumption (Advisory)'!F5 -> 16416667 | G6: ='Assumption (Advisory)'!G5 -> 16416667 | H6: ='Assumption (Advisory)'!H5 -> 16416667 | I6: ='Assumption (Advisory)'!I5 -> 16416667 | J6: ='Assumption (Advisory)'!J5 -> 16416667 | K6: ='Assumption (Advisory)'!K5 -> 16416667 | ... O6: ='Assumption (Advisory)'!O5 -> 16416667 | P6: =SUM(D6:O6) -> 1.97e+08 | Q6: =P6*(1+'Assumption (Advisory)'!E$48)*(1+'Assumption (Advisory)'!E$51) -> 2.7186e+08 | R6: =Q6*(1+'Assumption (Advisory)'!F$48)*(1+'Assumption (Advisory)'!F$51) -> 3.751668e+08 | S6: =R6*(1+'Assumption (Advisory)'!G$48)*(1+'Assumption (Advisory)'!G$51) -> 5.1773018e+08 | T6: =S6*(1+'Assumption (Advisory)'!H$48)*(1+'Assumption (Advisory)'!H$51) -> 7.1446765e+08
B7: ='Assumption (Advisory)'!B12 -> Occupational Hygiene | D7: ='Assumption (Advisory)'!D12 -> 0 | E7: ='Assumption (Advisory)'!E12 -> 135000000 | F7: ='Assumption (Advisory)'!F12 -> 0 | G7: ='Assumption (Advisory)'!G12 -> 0 | H7: ='Assumption (Advisory)'!H12 -> 135000000 | I7: ='Assumption (Advisory)'!I12 -> 0 | J7: ='Assumption (Advisory)'!J12 -> 0 | K7: ='Assumption (Advisory)'!K12 -> 135000000 | ... O7: ='Assumption (Advisory)'!O12 -> 0 | P7: =SUM(D7:O7) -> 540000000 | Q7: =P7*(1+'Assumption (Advisory)'!E$48)*(1+'Assumption (Advisory)'!E$51) -> 745200000 | R7: =Q7*(1+'Assumption (Advisory)'!F$48)*(1+'Assumption (Advisory)'!F$51) -> 1.028376e+09 | S7: =R7*(1+'Assumption (Advisory)'!G$48)*(1+'Assumption (Advisory)'!G$51) -> 1.4191589e+09 | T7: =S7*(1+'Assumption (Advisory)'!H$48)*(1+'Assumption (Advisory)'!H$51) -> 1.9584393e+09
B9: Total Revenue | D9: =SUM(D6:D7) -> 16416667 | E9: =SUM(E6:E7) -> 1.5141667e+08 | F9: =SUM(F6:F7) -> 16416667 | G9: =SUM(G6:G7) -> 16416667 | H9: =SUM(H6:H7) -> 1.5141667e+08 | I9: =SUM(I6:I7) -> 16416667 | J9: =SUM(J6:J7) -> 16416667 | K9: =SUM(K6:K7) -> 1.5141667e+08 | ... T9: =SUM(T6:T7) -> 2.6729069e+09
B11: Cost of Revenue
B12: Direct Cost - 3rd Party Services | C12: 0.5 | D12: =$C$12*D$9 -> 8208333.3 | E12: =$C$12*E$9 -> 75708333 | F12: =$C$12*F$9 -> 8208333.3 | G12: =$C$12*G$9 -> 8208333.3 | H12: =$C$12*H$9 -> 75708333 | I12: =$C$12*I$9 -> 8208333.3 | J12: =$C$12*J$9 -> 8208333.3 | K12: =$C$12*K$9 -> 75708333 | ... O12: =$C$12*O$9 -> 8208333.3 | P12: =SUM(D12:O12) -> 3.685e+08 | Q12: =P$9*(1+'Assumption (Advisory)'!E$52)*'Assumption (Advisory)'!$C$52 -> 4.0535e+08 | R12: =Q$9*(1+'Assumption (Advisory)'!F$52)*'Assumption (Advisory)'!$C$52 -> 5.492124e+08 | S12: =R$9*(1+'Assumption (Advisory)'!G$52)*'Assumption (Advisory)'!$C$52 -> 7.5791311e+08 | T12: =S$9*(1+'Assumption (Advisory)'!H$52)*'Assumption (Advisory)'!$C$52 -> 1.0265512e+09
B13: Direct Cost - Staff | D13: ='Assumption (Advisory)'!T54 -> 3050000 | E13: =D13 -> 3050000 | F13: =E13 -> 3050000 | G13: =F13 -> 3050000 | H13: =G13 -> 3050000 | I13: =H13 -> 3050000 | J13: =I13 -> 3050000 | K13: =J13 -> 3050000 | L13: =K13 -> 3050000 | ... O13: =N13 -> 3050000 | P13: =SUM(D13:O13) -> 36600000 | Q13: =P13 -> 36600000 | R13: =Q13 -> 36600000 | S13: =R13 -> 36600000 | T13: =S13 -> 36600000
B14: Direct Cost - Sales Commission | C14: 0.01 | D14: =$C$14*D$9 -> 164166.67 | E14: =$C$14*E$9 -> 1514166.7 | F14: =$C$14*F$9 -> 164166.67 | G14: =$C$14*G$9 -> 164166.67 | H14: =$C$14*H$9 -> 1514166.7 | I14: =$C$14*I$9 -> 164166.67 | J14: =$C$14*J$9 -> 164166.67 | K14: =$C$14*K$9 -> 1514166.7 | ... O14: =$C$14*O$9 -> 164166.67 | P14: =SUM(D14:O14) -> 7370000 | Q14: =$C$14*Q9 -> 10170600 | R14: =$C$14*R9 -> 14035428 | S14: =$C$14*S9 -> 19368891 | T14: =$C$14*T9 -> 26729069
B15: Direct Cost - Overheads & Others | C15: 0 | D15: =$C$15*D$9 -> 0 | E15: =D15 -> 0 | F15: =E15 -> 0 | G15: =F15 -> 0 | H15: =G15 -> 0 | I15: =H15 -> 0 | J15: =I15 -> 0 | K15: =J15 -> 0 | L15: =K15 -> 0 | ... O15: =N15 -> 0 | P15: =SUM(D15:O15) -> 0
B17: Total Direct Cost | D17: =SUM(D12:D15) -> 11422500 | E17: =SUM(E12:E15) -> 80272500 | F17: =SUM(F12:F15) -> 11422500 | G17: =SUM(G12:G15) -> 11422500 | H17: =SUM(H12:H15) -> 80272500 | I17: =SUM(I12:I15) -> 11422500 | J17: =SUM(J12:J15) -> 11422500 | K17: =SUM(K12:K15) -> 80272500 | ... O17: =SUM(O12:O15) -> 11422500 | P17: =SUM(P12:P16) -> 4.1247e+08 | Q17: =SUM(Q12:Q15) -> 4.521206e+08 | R17: =SUM(R12:R15) -> 5.9984783e+08 | S17: =SUM(S12:S15) -> 8.13882e+08 | T17: =SUM(T12:T15) -> 1.0898803e+09
P18: =P17/P9 -> 0.55966079
B19: Gross Profit | D19: =D9-D17 -> 4994166.7 | E19: =E9-E17 -> 71144167 | F19: =F9-F17 -> 4994166.7 | G19: =G9-G17 -> 4994166.7 | H19: =H9-H17 -> 71144167 | I19: =I9-I17 -> 4994166.7 | J19: =J9-J17 -> 4994166.7 | K19: =K9-K17 -> 71144167 | ... T19: =T9-T17 -> 1.5830266e+09
P20: =P19/P9 -> 0.44033921
B21: Operating expenses
B22: Indirect Staff Cost | D22: =VLOOKUP($B22,'Assumption (Advisory)'!$B:$O,3,FALSE) -> 0 | E22: =D22 -> 0 | F22: =E22 -> 0 | G22: =F22 -> 0 | H22: =G22 -> 0 | I22: =H22 -> 0 | J22: =I22 -> 0 | K22: =J22 -> 0 | L22: =K22 -> 0 | ... O22: =N22 -> 0 | P22: =SUM(D22:O22) -> 0 | Q22: =P22*(1+'Assumption (Advisory)'!E$58) -> 0 | R22: =Q22*(1+'Assumption (Advisory)'!F$58) -> 0 | S22: =R22*(1+'Assumption (Advisory)'!G$58) -> 0 | T22: =S22*(1+'Assumption (Advisory)'!H$58) -> 0
B23: Repair & Maintenance | D23: =VLOOKUP($B23,'Assumption (Advisory)'!$B:$O,3,FALSE) -> 0 | E23: =D23 -> 0 | F23: =E23 -> 0 | G23: =F23 -> 0 | H23: =G23 -> 0 | I23: =H23 -> 0 | J23: =I23 -> 0 | K23: =J23 -> 0 | L23: =K23 -> 0 | ... O23: =N23 -> 0 | P23: =SUM(D23:O23) -> 0 | Q23: =P23*(1+'Assumption (Advisory)'!E$49) -> 0 | R23: =Q23*(1+'Assumption (Advisory)'!F$49) -> 0 | S23: =R23*(1+'Assumption (Advisory)'!G$49) -> 0 | T23: =S23*(1+'Assumption (Advisory)'!H$49) -> 0
B24: Bank Charges | D24: =VLOOKUP($B24,'Assumption (Advisory)'!$B:$O,3,FALSE) -> 12283.333 | E24: =D24 -> 12283.333 | F24: =E24 -> 12283.333 | G24: =F24 -> 12283.333 | H24: =G24 -> 12283.333 | I24: =H24 -> 12283.333 | J24: =I24 -> 12283.333 | K24: =J24 -> 12283.333 | L24: =K24 -> 12283.333 | ... O24: =N24 -> 12283.333 | P24: =SUM(D24:O24) -> 147400 | Q24: =P24*(1+'Assumption (Advisory)'!E$49) -> 169510 | R24: =Q24*(1+'Assumption (Advisory)'!F$49) -> 194936.5 | S24: =R24*(1+'Assumption (Advisory)'!G$49) -> 224176.97 | T24: =S24*(1+'Assumption (Advisory)'!H$49) -> 257803.52
B25: Advert, Printing & Stationery | D25: =VLOOKUP($B25,'Assumption (Advisory)'!$B:$O,3,FALSE) -> 100000 | E25: =D25 -> 100000 | F25: =E25 -> 100000 | G25: =F25 -> 100000 | H25: =G25 -> 100000 | I25: =H25 -> 100000 | J25: =I25 -> 100000 | K25: =J25 -> 100000 | L25: =K25 -> 100000 | ... O25: =N25 -> 100000 | P25: =SUM(D25:O25) -> 1200000 | Q25: =P25*(1+'Assumption (Advisory)'!E$49) -> 1380000 | R25: =Q25*(1+'Assumption (Advisory)'!F$49) -> 1587000 | S25: =R25*(1+'Assumption (Advisory)'!G$49) -> 1825050 | T25: =S25*(1+'Assumption (Advisory)'!H$49) -> 2098807.5
B26: Rent | D26: =VLOOKUP($B26,'Assumption (Advisory)'!$B:$O,3,FALSE) -> 0 | E26: =D26 -> 0 | F26: =E26 -> 0 | G26: =F26 -> 0 | H26: =G26 -> 0 | I26: =H26 -> 0 | J26: =I26 -> 0 | K26: =J26 -> 0 | L26: =K26 -> 0 | ... O26: =N26 -> 0 | P26: =SUM(D26:O26) -> 0 | Q26: =P26*(1+'Assumption (Advisory)'!E$49) -> 0 | R26: =Q26*(1+'Assumption (Advisory)'!F$49) -> 0 | S26: =R26*(1+'Assumption (Advisory)'!G$49) -> 0 | T26: =S26*(1+'Assumption (Advisory)'!H$49) -> 0
B27: Internet | D27: =VLOOKUP($B27,'Assumption (Advisory)'!$B:$O,3,FALSE) -> 50000 | E27: =D27 -> 50000 | F27: =E27 -> 50000 | G27: =F27 -> 50000 | H27: =G27 -> 50000 | I27: =H27 -> 50000 | J27: =I27 -> 50000 | K27: =J27 -> 50000 | L27: =K27 -> 50000 | ... O27: =N27 -> 50000 | P27: =SUM(D27:O27) -> 600000 | Q27: =P27*(1+'Assumption (Advisory)'!E$49) -> 690000 | R27: =Q27*(1+'Assumption (Advisory)'!F$49) -> 793500 | S27: =R27*(1+'Assumption (Advisory)'!G$49) -> 912525 | T27: =S27*(1+'Assumption (Advisory)'!H$49) -> 1049403.7
B28: Cleaning Services | D28: =VLOOKUP($B28,'Assumption (Advisory)'!$B:$O,3,FALSE) -> 0 | E28: =D28 -> 0 | F28: =E28 -> 0 | G28: =F28 -> 0 | H28: =G28 -> 0 | I28: =H28 -> 0 | J28: =I28 -> 0 | K28: =J28 -> 0 | L28: =K28 -> 0 | ... O28: =N28 -> 0 | P28: =SUM(D28:O28) -> 0 | Q28: =P28*(1+'Assumption (Advisory)'!E$49) -> 0 | R28: =Q28*(1+'Assumption (Advisory)'!F$49) -> 0 | S28: =R28*(1+'Assumption (Advisory)'!G$49) -> 0 | T28: =S28*(1+'Assumption (Advisory)'!H$49) -> 0
B29: Fuel - Car Pool | D29: =VLOOKUP($B29,'Assumption (Advisory)'!$B:$O,3,FALSE) -> 0 | E29: =D29 -> 0 | F29: =E29 -> 0 | G29: =F29 -> 0 | H29: =G29 -> 0 | I29: =H29 -> 0 | J29: =I29 -> 0 | K29: =J29 -> 0 | L29: =K29 -> 0 | ... O29: =N29 -> 0 | P29: =SUM(D29:O29) -> 0 | Q29: =P29*(1+'Assumption (Advisory)'!E$49) -> 0 | R29: =Q29*(1+'Assumption (Advisory)'!F$49) -> 0 | S29: =R29*(1+'Assumption (Advisory)'!G$49) -> 0 | T29: =S29*(1+'Assumption (Advisory)'!H$49) -> 0
B30: Electricity | D30: =VLOOKUP($B30,'Assumption (Advisory)'!$B:$O,3,FALSE) -> 0 | E30: =D30 -> 0 | F30: =E30 -> 0 | G30: =F30 -> 0 | H30: =G30 -> 0 | I30: =H30 -> 0 | J30: =I30 -> 0 | K30: =J30 -> 0 | L30: =K30 -> 0 | ... O30: =N30 -> 0 | P30: =SUM(D30:O30) -> 0 | Q30: =P30*(1+'Assumption (Advisory)'!E$49) -> 0 | R30: =Q30*(1+'Assumption (Advisory)'!F$49) -> 0 | S30: =R30*(1+'Assumption (Advisory)'!G$49) -> 0 | T30: =S30*(1+'Assumption (Advisory)'!H$49) -> 0
B31: Security | D31: =VLOOKUP($B31,'Assumption (Advisory)'!$B:$O,3,FALSE) -> 0 | E31: =D31 -> 0 | F31: =E31 -> 0 | G31: =F31 -> 0 | H31: =G31 -> 0 | I31: =H31 -> 0 | J31: =I31 -> 0 | K31: =J31 -> 0 | L31: =K31 -> 0 | ... O31: =N31 -> 0 | P31: =SUM(D31:O31) -> 0 | Q31: =P31*(1+'Assumption (Advisory)'!E$49) -> 0 | R31: =Q31*(1+'Assumption (Advisory)'!F$49) -> 0 | S31: =R31*(1+'Assumption (Advisory)'!G$49) -> 0 | T31: =S31*(1+'Assumption (Advisory)'!H$49) -> 0
B32: Local Govt Levies & Charges | D32: =VLOOKUP($B32,'Assumption (Advisory)'!$B:$O,3,FALSE) -> 300000 | E32: =D32 -> 300000 | F32: =E32 -> 300000 | G32: =F32 -> 300000 | H32: =G32 -> 300000 | I32: =H32 -> 300000 | J32: =I32 -> 300000 | K32: =J32 -> 300000 | L32: =K32 -> 300000 | ... O32: =N32 -> 300000 | P32: =SUM(D32:O32) -> 3600000 | Q32: =P32*(1+'Assumption (Advisory)'!E$49) -> 4140000 | R32: =Q32*(1+'Assumption (Advisory)'!F$49) -> 4761000 | S32: =R32*(1+'Assumption (Advisory)'!G$49) -> 5475150 | T32: =S32*(1+'Assumption (Advisory)'!H$49) -> 6296422.5
B33: Insurance Expenses | D33: =VLOOKUP($B33,'Assumption (Advisory)'!$B:$O,3,FALSE) -> 135000 | E33: =D33 -> 135000 | F33: =E33 -> 135000 | G33: =F33 -> 135000 | H33: =G33 -> 135000 | I33: =H33 -> 135000 | J33: =I33 -> 135000 | K33: =J33 -> 135000 | L33: =K33 -> 135000 | ... O33: =N33 -> 135000 | P33: =SUM(D33:O33) -> 1620000 | Q33: =P33*(1+'Assumption (Advisory)'!E$49) -> 1863000 | R33: =Q33*(1+'Assumption (Advisory)'!F$49) -> 2142450 | S33: =R33*(1+'Assumption (Advisory)'!G$49) -> 2463817.5 | T33: =S33*(1+'Assumption (Advisory)'!H$49) -> 2833390.1
B34: Contribution | D34: =VLOOKUP($B34,'Assumption (Advisory)'!$B:$O,3,FALSE) -> 700000 | E34: =D34 -> 700000 | F34: =E34 -> 700000 | G34: =F34 -> 700000 | H34: =G34 -> 700000 | I34: =H34 -> 700000 | J34: =I34 -> 700000 | K34: =J34 -> 700000 | L34: =K34 -> 700000 | ... O34: =N34 -> 700000 | P34: =SUM(D34:O34) -> 8400000 | Q34: =P34*(1+'Assumption (Advisory)'!E$49) -> 9660000 | R34: =Q34*(1+'Assumption (Advisory)'!F$49) -> 11109000 | S34: =R34*(1+'Assumption (Advisory)'!G$49) -> 12775350 | T34: =S34*(1+'Assumption (Advisory)'!H$49) -> 14691652
B36: Total Opex | D36: =SUM(D22:D34) -> 1297283.3 | E36: =SUM(E22:E34) -> 1297283.3 | F36: =SUM(F22:F34) -> 1297283.3 | G36: =SUM(G22:G34) -> 1297283.3 | H36: =SUM(H22:H34) -> 1297283.3 | I36: =SUM(I22:I34) -> 1297283.3 | J36: =SUM(J22:J34) -> 1297283.3 | K36: =SUM(K22:K34) -> 1297283.3 | ... P36: =SUM(P22:P34) -> 15567400 | Q36: =SUM(Q23:Q34) -> 17902510 | R36: =SUM(R23:R34) -> 20587886 | S36: =SUM(S23:S34) -> 23676069 | T36: =SUM(T23:T34) -> 27227480
B38: EBITDA | D38: =D19-D36 -> 3696883.3 | E38: =E19-E36 -> 69846883 | F38: =F19-F36 -> 3696883.3 | G38: =G19-G36 -> 3696883.3 | H38: =H19-H36 -> 69846883 | I38: =I19-I36 -> 3696883.3 | J38: =J19-J36 -> 3696883.3 | K38: =K19-K36 -> 69846883 | ... T38: =T19-T36 -> 1.5557992e+09
B40: Depreciation Expenses | D40: =VLOOKUP($B40,'Assumption (Advisory)'!$B:$O,3,FALSE) -> 31250 | E40: =D40 -> 31250 | F40: =E40 -> 31250 | G40: =F40 -> 31250 | H40: =G40 -> 31250 | I40: =H40 -> 31250 | J40: =I40 -> 31250 | K40: =J40 -> 31250 | L40: =K40 -> 31250 | ... O40: =N40 -> 31250 | P40: =SUM(D40:O40) -> 375000 | Q40: =P40*(1+'Assumption (Advisory)'!E$49) -> 431250 | R40: =Q40*(1+'Assumption (Advisory)'!F$49) -> 495937.5 | S40: =R40*(1+'Assumption (Advisory)'!G$49) -> 570328.12 | T40: =S40*(1+'Assumption (Advisory)'!H$49) -> 655877.34
B42: Net Profit/(Loss) | D42: =D38-D40 -> 3665633.3 | E42: =E38-E40 -> 69815633 | F42: =F38-F40 -> 3665633.3 | G42: =G38-G40 -> 3665633.3 | H42: =H38-H40 -> 69815633 | I42: =I38-I40 -> 3665633.3 | J42: =J38-J40 -> 3665633.3 | K42: =K38-K40 -> 69815633 | ... T42: =T38-T40 -> 1.5551433e+09
P43: =P42/P9 -> 0.41870773
B44: Accumulated EBITDA | D44: =D42 -> 3665633.3 | E44: =D44+E42 -> 73481267 | F44: =E44+F42 -> 77146900 | G44: =F44+G42 -> 80812533 | H44: =G44+H42 -> 1.5062817e+08 | I44: =H44+I42 -> 1.542938e+08 | J44: =I44+J42 -> 1.5795943e+08 | K44: =J44+K42 -> 2.2777507e+08 | L44: =K44+L42 -> 2.314407e+08 | ... O44: =N44+O42 -> 3.085876e+08 | P44: =P42 -> 308587600 | Q44: =P44+Q38 -> 8.5562449e+08 | R44: =Q44+R38 -> 1.6387316e+09 | S44: =R44+S38 -> 2.7380626e+09 | T44: =S44+T38 -> 4.2938617e+09
B46: Total Investment
B48: Pay back Balance | D48: =D44-D46 -> 3665633.3 | E48: =E44-E46 -> 73481267 | F48: =F44-F46 -> 77146900 | G48: =G44-G46 -> 80812533 | H48: =H44-H46 -> 1.5062817e+08 | I48: =I44-I46 -> 1.542938e+08 | J48: =J44-J46 -> 1.5795943e+08 | K48: =K44-K46 -> 2.2777507e+08 | ... T48: =T44-T46 -> 4.2938617e+09
B50: Pay back Period | P50: =IF(P48>0,"1 Year"," ") -> 1 Year | Q50: =IF(Q48>0,"2 Year"," ") -> 2 Year | R50: =IF(R48>0,"3 Year"," ") -> 3 Year | S50: =IF(S48>0,"4 Year"," ") -> 4 Year | T50: =IF(T48>0,"5 Year"," ") -> 5 Year

Sheet Assumption (MedClinic)
B1: MedClinic
B2: Live_Case | D2: Jan | E2: Feb | F2: Mar | G2: Apr | H2: May | I2: Jun | J2: Jul | K2: Aug | L2: Sep | M2: Oct | N2: Nov | O2: Dec | P2: Total
B3: Medstaffing | D3: =SUM(D4:D5) -> 2880000 | E3: =SUM(E4:E5) -> 2880000 | F3: =SUM(F4:F5) -> 2880000 | G3: =SUM(G4:G5) -> 2880000 | H3: =SUM(H4:H5) -> 2880000 | I3: =SUM(I4:I5) -> 2880000 | J3: =SUM(J4:J5) -> 2880000 | K3: =SUM(K4:K5) -> 2880000 | ... P3: =SUM(P4:P5) -> 34560000
B4: Onshore Medical Doctor | D4: =D27*D47 -> 1530000 | E4: =E27*E47 -> 1530000 | F4: =F27*F47 -> 1530000 | G4: =G27*G47 -> 1530000 | H4: =H27*H47 -> 1530000 | I4: =I27*I47 -> 1530000 | J4: =J27*J47 -> 1530000 | K4: =K27*K47 -> 1530000 | ... O4: =O27*O47 -> 1530000 | P4: =SUM(D4:O4) -> 18360000
B5: Onshore Nurses | D5: =D28*D48 -> 1350000 | E5: =E28*E48 -> 1350000 | F5: =F28*F48 -> 1350000 | G5: =G28*G48 -> 1350000 | H5: =H28*H48 -> 1350000 | I5: =I28*I48 -> 1350000 | J5: =J28*J48 -> 1350000 | K5: =K28*K48 -> 1350000 | ... O5: =O28*O48 -> 1350000 | P5: =SUM(D5:O5) -> 16200000
B6: Onshore Pharm Technician | D6: =D29*D49 -> 380000 | E6: =E29*E49 -> 380000 | F6: =F29*F49 -> 380000 | G6: =G29*G49 -> 380000 | H6: =H29*H49 -> 380000 | I6: =I29*I49 -> 380000 | J6: =J29*J49 -> 380000 | K6: =K29*K49 -> 380000 | ... O6: =O29*O49 -> 380000 | P6: =SUM(D6:O6) -> 4560000
B7: Onshore Pharmacist | D7: =D30*D50 -> 450000 | E7: =E30*E50 -> 450000 | F7: =F30*F50 -> 450000 | G7: =G30*G50 -> 450000 | H7: =H30*H50 -> 450000 | I7: =I30*I50 -> 450000 | J7: =J30*J50 -> 450000 | K7: =K30*K50 -> 450000 | ... O7: =O30*O50 -> 450000 | P7: =SUM(D7:O7) -> 5400000
B8: Offshore Medical Doctor | D8: =D31*D51 -> 0 | E8: =E31*E51 -> 1500000 | F8: =F31*F51 -> 0 | G8: =G31*G51 -> 1500000 | H8: =H31*H51 -> 0 | I8: =I31*I51 -> 1500000 | J8: =J31*J51 -> 0 | K8: =K31*K51 -> 1500000 | ... O8: =O31*O51 -> 1500000 | P8: =SUM(D8:O8) -> 9000000
B9: Offshore Nurses | D9: =D32*D52 -> 850000 | E9: =E32*E52 -> 850000 | F9: =F32*F52 -> 850000 | G9: =G32*G52 -> 850000 | H9: =H32*H52 -> 850000 | I9: =I32*I52 -> 850000 | J9: =J32*J52 -> 850000 | K9: =K32*K52 -> 850000 | ... O9: =O32*O52 -> 850000 | P9: =SUM(D9:O9) -> 10200000
B10: Offshore Pharm Technician | D10: =D33*D53 -> 450000 | E10: =E33*E53 -> 450000 | F10: =F33*F53 -> 450000 | G10: =G33*G53 -> 450000 | H10: =H33*H53 -> 450000 | I10: =I33*I53 -> 450000 | J10: =J33*J53 -> 450000 | K10: =K33*K53 -> 450000 | ... O10: =O33*O53 -> 450000 | P10: =SUM(D10:O10) -> 5400000
B11: Offshore Pharm acist | D11: =D34*D54 -> 0 | E11: =E34*E54 -> 850000 | F11: =F34*F54 -> 0 | G11: =G34*G54 -> 850000 | H11: =H34*H54 -> 0 | I11: =I34*I54 -> 850000 | J11: =J34*J54 -> 0 | K11: =K34*K54 -> 850000 | ... O11: =O34*O54 -> 850000 | P11: =SUM(D11:O11) -> 5100000
B14: Outsourced Corporate Clinics | D14: =SUM(D15:D21) -> 2.1180445e+08 | E14: =SUM(E15:E21) -> 2.1180445e+08 | F14: =SUM(F15:F21) -> 2.1180445e+08 | G14: =SUM(G15:G21) -> 2.1180445e+08 | H14: =SUM(H15:H21) -> 2.1180445e+08 | I14: =SUM(I15:I21) -> 2.1180445e+08 | J14: =SUM(J15:J21) -> 2.1180445e+08 | K14: =SUM(K15:K21) -> 2.1180445e+08 | ... P14: =SUM(P15:P21) -> 2.5416534e+09
B15: APM Terminals | D15: =D37*D57 -> 4825999.6 | E15: =D15 -> 4825999.6 | F15: =E15 -> 4825999.6 | G15: =F15 -> 4825999.6 | H15: =G15 -> 4825999.6 | I15: =H15 -> 4825999.6 | J15: =I15 -> 4825999.6 | K15: =J15 -> 4825999.6 | L15: =K15 -> 4825999.6 | ... O15: =N15 -> 4825999.6 | P15: =SUM(D15:O15) -> 57911995 | Q15: Clinic Outsourcing
B16: Guiness Plc | D16: =D38*D58 -> 2631766.6 | E16: =E38*E58 -> 2631766.6 | F16: =F38*F58 -> 2631766.6 | G16: =G38*G58 -> 2631766.6 | H16: =H38*H58 -> 2631766.6 | I16: =I38*I58 -> 2631766.6 | J16: =J38*J58 -> 2631766.6 | K16: =K38*K58 -> 2631766.6 | ... O16: =O38*O58 -> 2631766.6 | P16: =SUM(D16:O16) -> 31581200 | Q16: Clinic Outsourcing
B17: Pipe Coaters Tenaris | D17: =D39*D59 -> 609150 | E17: =E39*E59 -> 609150 | F17: =F39*F59 -> 609150 | G17: =G39*G59 -> 609150 | H17: =H39*H59 -> 609150 | I17: =I39*I59 -> 609150 | J17: =J39*J59 -> 609150 | K17: =K39*K59 -> 609150 | ... O17: =O39*O59 -> 609150 | P17: =SUM(D17:O17) -> 7309800 | Q17: Clinic Outsourcing
B18: BATN | D18: =(D40*D60) -> 4570867.2 | E18: =D18 -> 4570867.2 | F18: =E18 -> 4570867.2 | G18: =F18 -> 4570867.2 | H18: =G18 -> 4570867.2 | I18: =H18 -> 4570867.2 | J18: =I18 -> 4570867.2 | K18: =J18 -> 4570867.2 | L18: =K18 -> 4570867.2 | ... O18: =N18 -> 4570867.2 | P18: =SUM(D18:O18) -> 54850407 | Q18: Quarterly Clinic outsourcing
B19: Shell IA | D19: =(D41*D61) -> 0 | E19: =D19 -> 0 | F19: =E19 -> 0 | G19: =F19 -> 0 | H19: =G19 -> 0 | I19: =H19 -> 0 | J19: =I19 -> 0 | K19: =J19 -> 0 | L19: =K19 -> 0 | ... O19: =N19 -> 0 | P19: =SUM(D19:O19) -> 0
B20: Oando | D20: =(D42*D62) -> 1.9616667e+08 | E20: =D20 -> 1.9616667e+08 | F20: =E20 -> 1.9616667e+08 | G20: =F20 -> 1.9616667e+08 | H20: =G20 -> 1.9616667e+08 | I20: =H20 -> 1.9616667e+08 | J20: =I20 -> 1.9616667e+08 | K20: =J20 -> 1.9616667e+08 | L20: =K20 -> 1.9616667e+08 | ... O20: =N20 -> 1.9616667e+08 | P20: =SUM(D20:O20) -> 2.354e+09
B21: Others | D21: 3000000 | E21: =D21 -> 3000000 | F21: =E21 -> 3000000 | G21: =F21 -> 3000000 | H21: =G21 -> 3000000 | I21: =H21 -> 3000000 | J21: =I21 -> 3000000 | K21: =J21 -> 3000000 | L21: =K21 -> 3000000 | ... O21: =N21 -> 3000000 | P21: =SUM(D21:O21) -> 36000000
B23: Total Revenue | D23: =D3+D14 -> 2.1468445e+08 | E23: =E3+E14 -> 2.1468445e+08 | F23: =F3+F14 -> 2.1468445e+08 | G23: =G3+G14 -> 2.1468445e+08 | H23: =H3+H14 -> 2.1468445e+08 | I23: =I3+I14 -> 2.1468445e+08 | J23: =J3+J14 -> 2.1468445e+08 | K23: =K3+K14 -> 2.1468445e+08 | ... P23: =P3+P14 -> 2.5762134e+09
B25: Average no Staff
B26: Medstaffing | D26: =SUM(D27:D34) -> 9 | E26: =SUM(E27:E34) -> 11 | F26: =SUM(F27:F34) -> 9 | G26: =SUM(G27:G34) -> 11 | H26: =SUM(H27:H34) -> 9 | I26: =SUM(I27:I34) -> 11 | J26: =SUM(J27:J34) -> 9 | K26: =SUM(K27:K34) -> 11 | ... P26: =SUM(P27:P34) -> 120
B27: Onshore Medical Doctor | D27: 2 | E27: 2 | F27: 2 | G27: 2 | H27: 2 | I27: 2 | J27: 2 | K27: 2 | L27: 2 | M27: 2 | N27: 2 | O27: 2 | P27: =SUM(D27:O27) -> 24
B28: Onshore Nurses | D28: 3 | E28: 3 | F28: 3 | G28: 3 | H28: 3 | I28: 3 | J28: 3 | K28: 3 | L28: 3 | M28: 3 | N28: 3 | O28: 3 | P28: =SUM(D28:O28) -> 36
B29: Onshore Pharm Technician | D29: 1 | E29: 1 | F29: 1 | G29: =F29 -> 1 | H29: =G29 -> 1 | I29: =H29 -> 1 | J29: =I29 -> 1 | K29: =J29 -> 1 | L29: =K29 -> 1 | M29: =L29 -> 1 | N29: =M29 -> 1 | O29: =N29 -> 1 | P29: =SUM(D29:O29) -> 12
B30: Onshore Pharmacist | D30: 1 | E30: 1 | F30: 1 | G30: =F30 -> 1 | H30: =G30 -> 1 | I30: =H30 -> 1 | J30: =I30 -> 1 | K30: =J30 -> 1 | L30: =K30 -> 1 | M30: =L30 -> 1 | N30: =M30 -> 1 | O30: =N30 -> 1 | P30: =SUM(D30:O30) -> 12
B31: Offshore Medical Doctor | E31: 1 | G31: 1 | I31: 1 | K31: 1 | M31: 1 | O31: 1 | P31: =SUM(D31:O31) -> 6
B32: Offshore Nurses | D32: 1 | E32: 1 | F32: 1 | G32: 1 | H32: 1 | I32: 1 | J32: 1 | K32: 1 | L32: 1 | M32: 1 | N32: 1 | O32: 1 | P32: =SUM(D32:O32) -> 12
B33: Offshore Pharm Technician | D33: 1 | E33: 1 | F33: 1 | G33: =F33 -> 1 | H33: =G33 -> 1 | I33: =H33 -> 1 | J33: =I33 -> 1 | K33: =J33 -> 1 | L33: =K33 -> 1 | M33: =L33 -> 1 | N33: =M33 -> 1 | O33: =N33 -> 1 | P33: =SUM(D33:O33) -> 12
B34: Offshore Pharmacist | E34: 1 | G34: 1 | I34: 1 | K34: 1 | M34: 1 | O34: 1 | P34: =SUM(D34:O34) -> 6
B36: Outsourced Corporate Clinics | D36: =SUM(D37:D40) -> 4 | E36: =SUM(E37:E40) -> 4 | F36: =SUM(F37:F40) -> 4 | G36: =SUM(G37:G40) -> 4 | H36: =SUM(H37:H40) -> 4 | I36: =SUM(I37:I40) -> 4 | J36: =SUM(J37:J40) -> 4 | K36: =SUM(K37:K40) -> 4 | ... P36: =SUM(P37:P40) -> 48
B37: APM Terminals | D37: 1 | E37: =D37 -> 1 | F37: =E37 -> 1 | G37: =F37 -> 1 | H37: =G37 -> 1 | I37: =H37 -> 1 | J37: =I37 -> 1 | K37: =J37 -> 1 | L37: =K37 -> 1 | ... O37: =N37 -> 1 | P37: =SUM(D37:O37) -> 12 | Q37: Per negotiated contract
B38: Guiness Plc | D38: 1 | E38: =D38 -> 1 | F38: =E38 -> 1 | G38: =F38 -> 1 | H38: =G38 -> 1 | I38: =H38 -> 1 | J38: =I38 -> 1 | K38: =J38 -> 1 | L38: =K38 -> 1 | ... O38: =N38 -> 1 | P38: =SUM(D38:O38) -> 12 | Q38: Per negotiated contract
B39: Pipe Coaters | D39: 1 | E39: =D39 -> 1 | F39: =E39 -> 1 | G39: =F39 -> 1 | H39: =G39 -> 1 | I39: =H39 -> 1 | J39: =I39 -> 1 | K39: =J39 -> 1 | L39: =K39 -> 1 | ... O39: =N39 -> 1 | P39: =SUM(D39:O39) -> 12 | Q39: Per negotiated contract
B40: BATN | D40: 1 | E40: =D40 -> 1 | F40: =E40 -> 1 | G40: =F40 -> 1 | H40: =G40 -> 1 | I40: =H40 -> 1 | J40: =I40 -> 1 | K40: =J40 -> 1 | L40: =K40 -> 1 | ... O40: =N40 -> 1 | P40: =SUM(D40:O40) -> 12 | Q40: Per negotiated contract
B41: Shell IA | D41: =7000*0 -> 0 | E41: 7000 | F41: 7000 | G41: =F41 -> 7000 | H41: =G41 -> 7000 | I41: =H41 -> 7000 | J41: =I41 -> 7000 | K41: =J41 -> 7000 | L41: =K41 -> 7000 | M41: =L41 -> 7000 | N41: =M41 -> 7000 | O41: =N41 -> 7000 | P41: =SUM(D41:O41) -> 77000
B42: Oando | D42: 2200 | E42: 2200 | F42: 2200 | G42: 2200 | H42: 2200 | I42: 2200 | J42: 2200 | K42: 2200 | L42: 2200 | M42: 2200 | N42: 2200 | O42: 2200 | P42: =SUM(D42:O42) -> 26400
B43: Others | P43: =SUM(D43:O43) -> 0
B45: Average case - Price
B46: Medstaffing
...

Sheet Computations (MedClinic)
B2: Computations-Outputs
D3: Jan | E3: Feb | F3: Mar | G3: Apr | H3: May | I3: Jun | J3: Jul | K3: Aug | L3: Sep | M3: Oct | N3: Nov | O3: Dec | P3: FY 1 | Q3: FY 2 | R3: FY 3 | S3: FY 4 | T3: FY 5
D4: ₦ | E4: ₦ | F4: ₦ | G4: ₦ | H4: ₦ | I4: ₦ | J4: ₦ | K4: ₦ | L4: ₦ | M4: ₦ | N4: ₦ | O4: ₦ | P4: NGN | Q4: NGN | R4: NGN | S4: NGN | T4: NGN
B5: Revenue
B6: Medstaffing | D6: =VLOOKUP($B6,'Assumption (MedClinic)'!$B:$P,3,FALSE) -> 2880000 | E6: =VLOOKUP($B6,'Assumption (MedClinic)'!$B:$P,4,FALSE) -> 2880000 | F6: =VLOOKUP($B6,'Assumption (MedClinic)'!$B:$P,5,FALSE) -> 2880000 | G6: =VLOOKUP($B6,'Assumption (MedClinic)'!$B:$P,6,FALSE) -> 2880000 | H6: =VLOOKUP($B6,'Assumption (MedClinic)'!$B:$P,7,FALSE) -> 2880000 | I6: =VLOOKUP($B6,'Assumption (MedClinic)'!$B:$P,8,FALSE) -> 2880000 | J6: =VLOOKUP($B6,'Assumption (MedClinic)'!$B:$P,9,FALSE) -> 2880000 | K6: =VLOOKUP($B6,'Assumption (MedClinic)'!$B:$P,10,FALSE) -> 2880000 | L6: =VLOOKUP($B6,'Assumption (MedClinic)'!$B:$P,11,FALSE) -> 2880000 | M6: =VLOOKUP($B6,'Assumption (MedClinic)'!$B:$P,12,FALSE) -> 2880000 | N6: =VLOOKUP($B6,'Assumption (MedClinic)'!$B:$P,13,FALSE) -> 2880000 | O6: =VLOOKUP($B6,'Assumption (MedClinic)'!$B:$P,14,FALSE) -> 2880000 | P6: =SUM(D6:O6) -> 34560000 | Q6: =P6*(1+'[2]Assumption (Advisory)'!E$45)*(1+'[2]Assumption (Advisory)'!E$48) -> 47692800 | R6: =Q6*(1+'[2]Assumption (Advisory)'!F$45)*(1+'[2]Assumption (Advisory)'!F$48) -> 65816064 | S6: =R6*(1+'[2]Assumption (Advisory)'!G$45)*(1+'[2]Assumption (Advisory)'!G$48) -> 90826168 | T6: =S6*(1+'[2]Assumption (Advisory)'!H$45)*(1+'[2]Assumption (Advisory)'!H$48) -> 1.2534011e+08
B7: Outsourced Corporate Clinics | D7: =VLOOKUP($B7,'Assumption (MedClinic)'!$B:$P,3,FALSE) -> 2.1180445e+08 | E7: =VLOOKUP($B7,'Assumption (MedClinic)'!$B:$P,4,FALSE) -> 2.1180445e+08 | F7: =VLOOKUP($B7,'Assumption (MedClinic)'!$B:$P,5,FALSE) -> 2.1180445e+08 | G7: =VLOOKUP($B7,'Assumption (MedClinic)'!$B:$P,6,FALSE) -> 2.1180445e+08 | H7: =VLOOKUP($B7,'Assumption (MedClinic)'!$B:$P,7,FALSE) -> 2.1180445e+08 | I7: =VLOOKUP($B7,'Assumption (MedClinic)'!$B:$P,8,FALSE) -> 2.1180445e+08 | J7: =VLOOKUP($B7,'Assumption (MedClinic)'!$B:$P,9,FALSE) -> 2.1180445e+08 | K7: =VLOOKUP($B7,'Assumption (MedClinic)'!$B:$P,10,FALSE) -> 2.1180445e+08 | L7: =VLOOKUP($B7,'Assumption (MedClinic)'!$B:$P,11,FALSE) -> 2.1180445e+08 | M7: =VLOOKUP($B7,'Assumption (MedClinic)'!$B:$P,12,FALSE) -> 2.1180445e+08 | N7: =VLOOKUP($B7,'Assumption (MedClinic)'!$B:$P,13,FALSE) -> 2.1180445e+08 | O7: =VLOOKUP($B7,'Assumption (MedClinic)'!$B:$P,14,FALSE) -> 2.1180445e+08 | P7: =SUM(D7:O7) -> 2.5416534e+09 | Q7: =P7*(1+'[2]Assumption (Advisory)'!E$45)*(1+'[2]Assumption (Advisory)'!E$48) -> 3.5074817e+09 | R7: =Q7*(1+'[2]Assumption (Advisory)'!F$45)*(1+'[2]Assumption (Advisory)'!F$48) -> 4.8403247e+09 | S7: =R7*(1+'[2]Assumption (Advisory)'!G$45)*(1+'[2]Assumption (Advisory)'!G$48) -> 6.6796481e+09 | T7: =S7*(1+'[2]Assumption (Advisory)'!H$45)*(1+'[2]Assumption (Advisory)'!H$48) -> 9.2179144e+09
B9: Total Revenue | D9: =SUM(D6:D7) -> 2.1468445e+08 | E9: =SUM(E6:E7) -> 2.1468445e+08 | F9: =SUM(F6:F7) -> 2.1468445e+08 | G9: =SUM(G6:G7) -> 2.1468445e+08 | H9: =SUM(H6:H7) -> 2.1468445e+08 | I9: =SUM(I6:I7) -> 2.1468445e+08 | J9: =SUM(J6:J7) -> 2.1468445e+08 | K9: =SUM(K6:K7) -> 2.1468445e+08 | ... T9: =SUM(T6:T7) -> 9.3432545e+09
B11: Cost of Revenue
B12: Direct Cost - Consumables | D12: =VLOOKUP($B12,'Assumption (MedClinic)'!$B:$P,3,FALSE) -> 75139558 | E12: =D12 -> 75139558 | F12: =E12 -> 75139558 | G12: =F12 -> 75139558 | H12: =G12 -> 75139558 | I12: =H12 -> 75139558 | J12: =I12 -> 75139558 | K12: =J12 -> 75139558 | L12: =K12 -> 75139558 | ... O12: =N12 -> 75139558 | P12: =SUM(D12:O12) -> 9.0167469e+08
B13: Direct Cost - Staff | D13: =VLOOKUP($B13,'Assumption (MedClinic)'!$B:$P,3,FALSE)/12 -> 437445.83 | E13: =D13 -> 437445.83 | F13: =E13 -> 437445.83 | G13: =F13 -> 437445.83 | H13: =G13 -> 437445.83 | I13: =H13 -> 437445.83 | J13: =I13 -> 437445.83 | K13: =J13 -> 437445.83 | L13: =K13 -> 437445.83 | ... O13: =N13 -> 437445.83 | P13: =SUM(D13:O13) -> 5249350 | Q13: =P13*(1+'[2]Assumption (Advisory)'!E$45)*(1+'[2]Assumption (Advisory)'!E$48) -> 7244103 | R13: =Q13*(1+'[2]Assumption (Advisory)'!F$45)*(1+'[2]Assumption (Advisory)'!F$48) -> 9996862.1 | S13: =R13*(1+'[2]Assumption (Advisory)'!G$45)*(1+'[2]Assumption (Advisory)'!G$48) -> 13795670 | T13: =S13*(1+'[2]Assumption (Advisory)'!H$45)*(1+'[2]Assumption (Advisory)'!H$48) -> 19038024
B14: Direct Cost - Sales Commission | D14: =VLOOKUP($B14,'Assumption (MedClinic)'!$B:$P,3,FALSE)/12 -> 2146844.5 | E14: =D14 -> 2146844.5 | F14: =E14 -> 2146844.5 | G14: =F14 -> 2146844.5 | H14: =G14 -> 2146844.5 | I14: =H14 -> 2146844.5 | J14: =I14 -> 2146844.5 | K14: =J14 -> 2146844.5 | L14: =K14 -> 2146844.5 | ... O14: =N14 -> 2146844.5 | P14: =SUM(D14:O14) -> 25762134 | Q14: =P14*(1+'[2]Assumption (Advisory)'!E$45)*(1+'[2]Assumption (Advisory)'!E$48) -> 35551745 | R14: =Q14*(1+'[2]Assumption (Advisory)'!F$45)*(1+'[2]Assumption (Advisory)'!F$48) -> 49061408 | S14: =R14*(1+'[2]Assumption (Advisory)'!G$45)*(1+'[2]Assumption (Advisory)'!G$48) -> 67704743 | T14: =S14*(1+'[2]Assumption (Advisory)'!H$45)*(1+'[2]Assumption (Advisory)'!H$48) -> 93432545
B15: Direct Cost - Overheads & Others | D15: =VLOOKUP($B15,'Assumption (MedClinic)'!$B:$P,3,FALSE)/12 -> 0 | E15: =D15 -> 0 | F15: =E15 -> 0 | G15: =F15 -> 0 | H15: =G15 -> 0 | I15: =H15 -> 0 | J15: =I15 -> 0 | K15: =J15 -> 0 | L15: =K15 -> 0 | ... O15: =N15 -> 0 | P15: =SUM(D15:O15) -> 0 | R15: =Q15*(1+'[2]Assumption (Advisory)'!F$45)*(1+'[2]Assumption (Advisory)'!F$48) -> 0 | S15: =R15*(1+'[2]Assumption (Advisory)'!G$45)*(1+'[2]Assumption (Advisory)'!G$48) -> 0 | T15: =S15*(1+'[2]Assumption (Advisory)'!H$45)*(1+'[2]Assumption (Advisory)'!H$48) -> 0
B17: Total Direct Cost | D17: =SUM(D12:D15) -> 77723848 | E17: =SUM(E12:E15) -> 77723848 | F17: =SUM(F12:F15) -> 77723848 | G17: =SUM(G12:G15) -> 77723848 | H17: =SUM(H12:H15) -> 77723848 | I17: =SUM(I12:I15) -> 77723848 | J17: =SUM(J12:J15) -> 77723848 | K17: =SUM(K12:K15) -> 77723848 | ... T17: =SUM(T12:T15) -> 1.1247057e+08
B19: Gross Profit | D19: =D9-D17 -> 1.369606e+08 | E19: =E9-E17 -> 1.369606e+08 | F19: =F9-F17 -> 1.369606e+08 | G19: =G9-G17 -> 1.369606e+08 | H19: =H9-H17 -> 1.369606e+08 | I19: =I9-I17 -> 1.369606e+08 | J19: =J9-J17 -> 1.369606e+08 | K19: =K9-K17 -> 1.369606e+08 | ... T19: =T9-T17 -> 9.230784e+09
B21: Operating expenses
B22: Indirect Staff Cost | D22: =VLOOKUP($B22,'Assumption (MedClinic)'!$B:$P,3,FALSE) -> 0 | E22: =D22 -> 0 | F22: =E22 -> 0 | G22: =F22 -> 0 | H22: =G22 -> 0 | I22: =H22 -> 0 | J22: =I22 -> 0 | K22: =J22 -> 0 | L22: =K22 -> 0 | ... O22: =N22 -> 0 | P22: =SUM(D22:O22) -> 0 | Q22: =P22*(1+'[2]Assumption (Advisory)'!E$55) -> 0 | R22: =Q22*(1+'[2]Assumption (Advisory)'!F$55) -> 0 | S22: =R22*(1+'[2]Assumption (Advisory)'!G$55) -> 0 | T22: =S22*(1+'[2]Assumption (Advisory)'!H$55) -> 0
B23: Repair & Maintenance | D23: =VLOOKUP($B23,'Assumption (MedClinic)'!$B:$P,3,FALSE) -> 0 | E23: =D23 -> 0 | F23: =E23 -> 0 | G23: =F23 -> 0 | H23: =G23 -> 0 | I23: =H23 -> 0 | J23: =I23 -> 0 | K23: =J23 -> 0 | L23: =K23 -> 0 | ... O23: =N23 -> 0 | P23: =SUM(D23:O23) -> 0 | Q23: =P23*(1+'[2]Assumption (Advisory)'!E$46) -> 0 | R23: =Q23*(1+'[2]Assumption (Advisory)'!F$46) -> 0 | S23: =R23*(1+'[2]Assumption (Advisory)'!G$46) -> 0 | T23: =S23*(1+'[2]Assumption (Advisory)'!H$46) -> 0
B24: Bank Charges | D24: =VLOOKUP($B24,'Assumption (MedClinic)'!$B:$P,3,FALSE) -> 214684.45 | E24: =D24 -> 214684.45 | F24: =E24 -> 214684.45 | G24: =F24 -> 214684.45 | H24: =G24 -> 214684.45 | I24: =H24 -> 214684.45 | J24: =I24 -> 214684.45 | K24: =J24 -> 214684.45 | L24: =K24 -> 214684.45 | ... O24: =N24 -> 214684.45 | P24: =SUM(D24:O24) -> 2576213.4 | Q24: =P24*(1+'[2]Assumption (Advisory)'!E$46) -> 2962645.4 | R24: =Q24*(1+'[2]Assumption (Advisory)'!F$46) -> 3407042.2 | S24: =R24*(1+'[2]Assumption (Advisory)'!G$46) -> 3918098.6 | T24: =S24*(1+'[2]Assumption (Advisory)'!H$46) -> 4505813.3
B25: Advert, Printing & Stationery | D25: =VLOOKUP($B25,'Assumption (MedClinic)'!$B:$P,3,FALSE) -> 200000 | E25: =D25 -> 200000 | F25: =E25 -> 200000 | G25: =F25 -> 200000 | H25: =G25 -> 200000 | I25: =H25 -> 200000 | J25: =I25 -> 200000 | K25: =J25 -> 200000 | L25: =K25 -> 200000 | ... O25: =N25 -> 200000 | P25: =SUM(D25:O25) -> 2400000 | Q25: =P25*(1+'[2]Assumption (Advisory)'!E$46) -> 2760000 | R25: =Q25*(1+'[2]Assumption (Advisory)'!F$46) -> 3174000 | S25: =R25*(1+'[2]Assumption (Advisory)'!G$46) -> 3650100 | T25: =S25*(1+'[2]Assumption (Advisory)'!H$46) -> 4197615
B26: Rent | D26: =VLOOKUP($B26,'Assumption (MedClinic)'!$B:$P,3,FALSE) -> 0 | E26: =D26 -> 0 | F26: =E26 -> 0 | G26: =F26 -> 0 | H26: =G26 -> 0 | I26: =H26 -> 0 | J26: =I26 -> 0 | K26: =J26 -> 0 | L26: =K26 -> 0 | ... O26: =N26 -> 0 | P26: =SUM(D26:O26) -> 0 | Q26: =P26*(1+'[2]Assumption (Advisory)'!E$46) -> 0 | R26: =Q26*(1+'[2]Assumption (Advisory)'!F$46) -> 0 | S26: =R26*(1+'[2]Assumption (Advisory)'!G$46) -> 0 | T26: =S26*(1+'[2]Assumption (Advisory)'!H$46) -> 0
B27: Internet | D27: =VLOOKUP($B27,'Assumption (MedClinic)'!$B:$P,3,FALSE) -> 125000 | E27: =D27 -> 125000 | F27: =E27 -> 125000 | G27: =F27 -> 125000 | H27: =G27 -> 125000 | I27: =H27 -> 125000 | J27: =I27 -> 125000 | K27: =J27 -> 125000 | L27: =K27 -> 125000 | ... O27: =N27 -> 125000 | P27: =SUM(D27:O27) -> 1500000 | Q27: =P27*(1+'[2]Assumption (Advisory)'!E$46) -> 1725000 | R27: =Q27*(1+'[2]Assumption (Advisory)'!F$46) -> 1983750 | S27: =R27*(1+'[2]Assumption (Advisory)'!G$46) -> 2281312.5 | T27: =S27*(1+'[2]Assumption (Advisory)'!H$46) -> 2623509.4
B28: Cleaning Services | D28: =VLOOKUP($B28,'Assumption (MedClinic)'!$B:$P,3,FALSE) -> 0 | E28: =D28 -> 0 | F28: =E28 -> 0 | G28: =F28 -> 0 | H28: =G28 -> 0 | I28: =H28 -> 0 | J28: =I28 -> 0 | K28: =J28 -> 0 | L28: =K28 -> 0 | ... O28: =N28 -> 0 | P28: =SUM(D28:O28) -> 0 | Q28: =P28*(1+'[2]Assumption (Advisory)'!E$46) -> 0 | R28: =Q28*(1+'[2]Assumption (Advisory)'!F$46) -> 0 | S28: =R28*(1+'[2]Assumption (Advisory)'!G$46) -> 0 | T28: =S28*(1+'[2]Assumption (Advisory)'!H$46) -> 0
B29: Fuel - Car Pool | D29: =VLOOKUP($B29,'Assumption (MedClinic)'!$B:$P,3,FALSE) -> 0 | E29: =D29 -> 0 | F29: =E29 -> 0 | G29: =F29 -> 0 | H29: =G29 -> 0 | I29: =H29 -> 0 | J29: =I29 -> 0 | K29: =J29 -> 0 | L29: =K29 -> 0 | ... O29: =N29 -> 0 | P29: =SUM(D29:O29) -> 0 | Q29: =P29*(1+'[2]Assumption (Advisory)'!E$46) -> 0 | R29: =Q29*(1+'[2]Assumption (Advisory)'!F$46) -> 0 | S29: =R29*(1+'[2]Assumption (Advisory)'!G$46) -> 0 | T29: =S29*(1+'[2]Assumption (Advisory)'!H$46) -> 0
B30: Electricity | D30: =VLOOKUP($B30,'Assumption (MedClinic)'!$B:$P,3,FALSE) -> 0 | E30: =D30 -> 0 | F30: =E30 -> 0 | G30: =F30 -> 0 | H30: =G30 -> 0 | I30: =H30 -> 0 | J30: =I30 -> 0 | K30: =J30 -> 0 | L30: =K30 -> 0 | ... O30: =N30 -> 0 | P30: =SUM(D30:O30) -> 0 | Q30: =P30*(1+'[2]Assumption (Advisory)'!E$46) -> 0 | R30: =Q30*(1+'[2]Assumption (Advisory)'!F$46) -> 0 | S30: =R30*(1+'[2]Assumption (Advisory)'!G$46) -> 0 | T30: =S30*(1+'[2]Assumption (Advisory)'!H$46) -> 0
B31: Security | D31: =VLOOKUP($B31,'Assumption (MedClinic)'!$B:$P,3,FALSE) -> 0 | E31: =D31 -> 0 | F31: =E31 -> 0 | G31: =F31 -> 0 | H31: =G31 -> 0 | I31: =H31 -> 0 | J31: =I31 -> 0 | K31: =J31 -> 0 | L31: =K31 -> 0 | ... O31: =N31 -> 0 | P31: =SUM(D31:O31) -> 0 | Q31: =P31*(1+'[2]Assumption (Advisory)'!E$46) -> 0 | R31: =Q31*(1+'[2]Assumption (Advisory)'!F$46) -> 0 | S31: =R31*(1+'[2]Assumption (Advisory)'!G$46) -> 0 | T31: =S31*(1+'[2]Assumption (Advisory)'!H$46) -> 0
B32: Local Govt Levies & Charges | D32: =VLOOKUP($B32,'Assumption (MedClinic)'!$B:$P,3,FALSE) -> 200000 | E32: =D32 -> 200000 | F32: =E32 -> 200000 | G32: =F32 -> 200000 | H32: =G32 -> 200000 | I32: =H32 -> 200000 | J32: =I32 -> 200000 | K32: =J32 -> 200000 | L32: =K32 -> 200000 | ... O32: =N32 -> 200000 | P32: =SUM(D32:O32) -> 2400000 | Q32: =P32*(1+'[2]Assumption (Advisory)'!E$46) -> 2760000 | R32: =Q32*(1+'[2]Assumption (Advisory)'!F$46) -> 3174000 | S32: =R32*(1+'[2]Assumption (Advisory)'!G$46) -> 3650100 | T32: =S32*(1+'[2]Assumption (Advisory)'!H$46) -> 4197615
B33: Insurance Expenses | D33: =VLOOKUP($B33,'Assumption (MedClinic)'!$B:$P,3,FALSE) -> 120000 | E33: =D33 -> 120000 | F33: =E33 -> 120000 | G33: =F33 -> 120000 | H33: =G33 -> 120000 | I33: =H33 -> 120000 | J33: =I33 -> 120000 | K33: =J33 -> 120000 | L33: =K33 -> 120000 | ... O33: =N33 -> 120000 | P33: =SUM(D33:O33) -> 1440000 | Q33: =P33*(1+'[2]Assumption (Advisory)'!E$46) -> 1656000 | R33: =Q33*(1+'[2]Assumption (Advisory)'!F$46) -> 1904400 | S33: =R33*(1+'[2]Assumption (Advisory)'!G$46) -> 2190060 | T33: =S33*(1+'[2]Assumption (Advisory)'!H$46) -> 2518569
B34: Depreciation Expenses | D34: =VLOOKUP($B34,'Assumption (MedClinic)'!$B:$P,3,FALSE) -> 125000 | E34: =D34 -> 125000 | F34: =E34 -> 125000 | G34: =F34 -> 125000 | H34: =G34 -> 125000 | I34: =H34 -> 125000 | J34: =I34 -> 125000 | K34: =J34 -> 125000 | L34: =K34 -> 125000 | ... O34: =N34 -> 125000 | P34: =SUM(D34:O34) -> 1500000 | Q34: =P34*(1+'[2]Assumption (Advisory)'!E$46) -> 1725000 | R34: =Q34*(1+'[2]Assumption (Advisory)'!F$46) -> 1983750 | S34: =R34*(1+'[2]Assumption (Advisory)'!G$46) -> 2281312.5 | T34: =S34*(1+'[2]Assumption (Advisory)'!H$46) -> 2623509.4
... B37: Oando Admin & Staff Cost | D37: =VLOOKUP($B37,'Assumption (MedClinic)'!$B:$P,3,FALSE) -> 21750563 | E37: =D37 -> 21750563 | F37: =E37 -> 21750563 | G37: =F37 -> 21750563 | H37: =G37 -> 21750563 | I37: =H37 -> 21750563 | J37: =I37 -> 21750563 | K37: =J37 -> 21750563 | L37: =K37 -> 21750563 | ... O37: =N37 -> 21750563 | P37: =SUM(D37:O37) -> 2.6100675e+08 | Q37: =P37*(1+'[2]Assumption (Advisory)'!E$46) -> 3.0015777e+08 | R37: =Q37*(1+'[2]Assumption (Advisory)'!F$46) -> 3.4518143e+08 | S37: =R37*(1+'[2]Assumption (Advisory)'!G$46) -> 3.9695865e+08 | T37: =S37*(1+'[2]Assumption (Advisory)'!H$46) -> 4.5650245e+08
B39: Total Opex | D39: =SUM(D22:D37) -> 23435247 | E39: =SUM(E22:E37) -> 23435247 | F39: =SUM(F22:F37) -> 23435247 | G39: =SUM(G22:G37) -> 23435247 | H39: =SUM(H22:H37) -> 23435247 | I39: =SUM(I22:I37) -> 23435247 | J39: =SUM(J22:J37) -> 23435247 | K39: =SUM(K22:K37) -> 23435247 | ... T39: =SUM(T22:T37) -> 4.9186073e+08
B41: EBITDA | D41: =D19-D39 -> 1.1352535e+08 | E41: =E19-E39 -> 1.1352535e+08 | F41: =F19-F39 -> 1.1352535e+08 | G41: =G19-G39 -> 1.1352535e+08 | H41: =H19-H39 -> 1.1352535e+08 | I41: =I19-I39 -> 1.1352535e+08 | J41: =J19-J39 -> 1.1352535e+08 | K41: =K19-K39 -> 1.1352535e+08 | ... T41: =T19-T39 -> 8.7389232e+09
B43: Depreciation Expenses | D43: =VLOOKUP($B43,'Assumption (MedClinic)'!$B:$P,3,FALSE) -> 125000 | E43: =D43 -> 125000 | F43: =E43 -> 125000 | G43: =F43 -> 125000 | H43: =G43 -> 125000 | I43: =H43 -> 125000 | J43: =I43 -> 125000 | K43: =J43 -> 125000 | L43: =K43 -> 125000 | ... O43: =N43 -> 125000 | P43: =SUM(D43:O43) -> 1500000 | Q43: =P43*(1+'[2]Assumption (Advisory)'!E$46) -> 1725000 | R43: =Q43*(1+'[2]Assumption (Advisory)'!F$46) -> 1983750 | S43: =R43*(1+'[2]Assumption (Advisory)'!G$46) -> 2281312.5 | T43: =S43*(1+'[2]Assumption (Advisory)'!H$46) -> 2623509.4
B45: Net Profit/(Loss) | D45: =D41-D43 -> 1.1340035e+08 | E45: =E41-E43 -> 1.1340035e+08 | F45: =F41-F43 -> 1.1340035e+08 | G45: =G41-G43 -> 1.1340035e+08 | H45: =H41-H43 -> 1.1340035e+08 | I45: =I41-I43 -> 1.1340035e+08 | J45: =J41-J43 -> 1.1340035e+08 | K45: =K41-K43 -> 1.1340035e+08 | ... T45: =T41-T43 -> 8.7362997e+09
B47: Accumulated EBITDA | D47: =D45 -> 1.1340035e+08 | E47: =D47+E45 -> 2.2680071e+08 | F47: =E47+F45 -> 3.4020106e+08 | G47: =F47+G45 -> 4.5360142e+08 | H47: =G47+H45 -> 5.6700177e+08 | I47: =H47+I45 -> 6.8040213e+08 | J47: =I47+J45 -> 7.9380248e+08 | K47: =J47+K45 -> 9.0720284e+08 | L47: =K47+L45 -> 1.0206032e+09 | ... O47: =N47+O45 -> 1.3608043e+09 | P47: =P45 -> 1.3608043e+09 | Q47: =P47+Q41 -> 4.5497765e+09 | R47: =Q47+R41 -> 9.0249416e+09 | S47: =R47+S41 -> 1.5286211e+10 | T47: =S47+T41 -> 2.4025134e+10
B49: Total Investment
B51: Pay back Balance | D51: =D47-D49 -> 1.1340035e+08 | E51: =E47-E49 -> 2.2680071e+08 | F51: =F47-F49 -> 3.4020106e+08 | G51: =G47-G49 -> 4.5360142e+08 | H51: =H47-H49 -> 5.6700177e+08 | I51: =I47-I49 -> 6.8040213e+08 | J51: =J47-J49 -> 7.9380248e+08 | K51: =K47-K49 -> 9.0720284e+08 | ... T51: =T47-T49 -> 2.4025134e+10
B53: Pay back Period | P53: =IF(P51>0,"1 Year"," ") -> 1 Year | Q53: =IF(Q51>0,"2 Year"," ") -> 2 Year | R53: =IF(R51>0,"3 Year"," ") -> 3 Year | S53: =IF(S51>0,"4 Year"," ") -> 4 Year | T53: =IF(T51>0,"5 Year"," ") -> 5 Year
