Workbook
Name afril: #REF!
Name BS: #REF!
Name costaa: #REF!
Name F: #REF!
Name fs: #REF!
Name GGGG: #REF!
Name groupincome: #REF!
Name MANS: #REF!
Name OLDMAN: #REF!
Name PAC: #REF!
Name PL: #REF!
Name REGISTRAR: #REF!
Name SCHD3: #REF!
Name SCHED1: #REF!
Name SCHED2: #REF!
Name SCHED3: #REF!
Name SCHED4: #REF!
Name SEMI: #REF!
Name SSES: #REF!
Name SUMMARY: #REF!
Name yyy: #REF!

Sheet Assumption-Inputs
B1: Assumptions-Inputs
E3: January | F3: February | G3: March | H3: April | I3: May | J3: June | K3: July | L3: August | M3: September | N3: October | O3: November | P3: December | R3: Total
B4: Live_Case | C4: EUR | D4: Rate (₦)
B5: Clinic | E5: =SUM(E6:E8) -> 29277750 | F5: =SUM(F6:F8) -> 29277750 | G5: =SUM(G6:G8) -> 29277750 | H5: =SUM(H6:H8) -> 29277750 | I5: =SUM(I6:I8) -> 29277750 | J5: =SUM(J6:J8) -> 29277750 | K5: =SUM(K6:K8) -> 29277750 | L5: =SUM(L6:L8) -> 29277750 | ... P5: =SUM(P6:P8) -> 29277750 | R5: =SUM(R6:R8) -> 351333000
B6: PRIMARY CARE - Clinic Access Subscription - MEDVAC + Assistance Centre | E6: =E26*E46 -> 2493750 | F6: =F26*F46 -> 2493750 | G6: =G26*G46 -> 2493750 | H6: =H26*H46 -> 2493750 | I6: =I26*I46 -> 2493750 | J6: =J26*J46 -> 2493750 | K6: =K26*K46 -> 2493750 | L6: =L26*L46 -> 2493750 | ... P6: =P26*P46 -> 2493750 | R6: =SUM(E6:P6) -> 29925000
B7: PREMIUM - Clinic Access Subscription - MedLyfe (Wellness) + MEDVAC + Assistance Centre | E7: =E27*E47 -> 26600000 | F7: =F27*F47 -> 26600000 | G7: =G27*G47 -> 26600000 | H7: =H27*H47 -> 26600000 | I7: =I27*I47 -> 26600000 | J7: =J27*J47 -> 26600000 | K7: =K27*K47 -> 26600000 | L7: =L27*L47 -> 26600000 | ... P7: =P27*P47 -> 26600000 | R7: =SUM(E7:P7) -> 319200000
B8: Emergency Ground Ambulance /Evacuation Services | E8: =E28*E48 -> 184000 | F8: =E8 -> 184000 | G8: =F8 -> 184000 | H8: =G8 -> 184000 | I8: =H8 -> 184000 | J8: =I8 -> 184000 | K8: =J8 -> 184000 | L8: =K8 -> 184000 | M8: =L8 -> 184000 | ... P8: =O8 -> 184000 | R8: =SUM(E8:P8) -> 2208000
B10: Healthcare Consulting | E10: =SUM(E11:E13) -> 0 | F10: =SUM(F11:F13) -> 0 | G10: =SUM(G11:G13) -> 0 | H10: =SUM(H11:H13) -> 0 | I10: =SUM(I11:I13) -> 0 | J10: =SUM(J11:J13) -> 0 | K10: =SUM(K11:K13) -> 0 | L10: =SUM(L11:L13) -> 0 | ... P10: =SUM(P11:P13) -> 0 | R10: =SUM(R11:R13) -> 0
B11: Workplace Solutions | E11: =E31*E51 -> 0 | F11: =F31*F51 -> 0 | G11: =G31*G51 -> 0 | H11: =H31*H51 -> 0 | I11: =I31*I51 -> 0 | J11: =J31*J51 -> 0 | K11: =K31*K51 -> 0 | L11: =L31*L51 -> 0 | ... P11: =P31*P51 -> 0 | R11: =SUM(E11:P11) -> 0
B12: Medical Staffing (rate per Dr) | E12: =E32*E52 -> 0 | F12: =F32*F52 -> 0 | G12: =G32*G52 -> 0 | H12: =H32*H52 -> 0 | I12: =I32*I52 -> 0 | J12: =J32*J52 -> 0 | K12: =K32*K52 -> 0 | L12: =L32*L52 -> 0 | ... P12: =P32*P52 -> 0 | R12: =SUM(E12:P12) -> 0
B13: Onsite Healthcare Review & Consulting | E13: =E33*E53 -> 0 | F13: =F33*F53 -> 0 | G13: =G33*G53 -> 0 | H13: =H33*H53 -> 0 | I13: =I33*I53 -> 0 | J13: =J33*J53 -> 0 | K13: =K33*K53 -> 0 | L13: =L33*L53 -> 0 | ... P13: =P33*P53 -> 0 | R13: =SUM(E13:P13) -> 0
B15: Public Health Solutions & Preventative Care Programs | E15: =SUM(E16) -> 0 | F15: =SUM(F16) -> 0 | G15: =SUM(G16) -> 0 | H15: =SUM(H16) -> 0 | I15: =SUM(I16) -> 0 | J15: =SUM(J16) -> 0 | K15: =SUM(K16) -> 0 | L15: =SUM(L16) -> 0 | ... P15: =SUM(P16) -> 0 | R15: =SUM(R16) -> 0
B16: Health Education & Preventive Care Programs | E16: =E36*E56 -> 0 | F16: =E16 -> 0 | G16: =F16 -> 0 | H16: =G16 -> 0 | I16: =H16 -> 0 | J16: =I16 -> 0 | K16: =J16 -> 0 | L16: =K16 -> 0 | M16: =L16 -> 0 | ... P16: =O16 -> 0 | R16: =SUM(E16:P16) -> 0
B18: Global Assistance Service | E18: =SUM(E19:E21) -> 69366667 | F18: =SUM(F19:F21) -> 69366667 | G18: =SUM(G19:G21) -> 69366667 | H18: =SUM(H19:H21) -> 69366667 | I18: =SUM(I19:I21) -> 69366667 | J18: =SUM(J19:J21) -> 69366667 | K18: =SUM(K19:K21) -> 69366667 | L18: =SUM(L19:L21) -> 69366667 | ... P18: =SUM(P19:P21) -> 69366667 | R18: =SUM(R19:R21) -> 832400000
B19: Annual Subscription for 24/7 Assistance Services (Telemedicine/ Virtual Consultations, Diagnosis and Treatment Plans) | E19: =E39*E59 -> 17100000 | F19: =E19 -> 17100000 | G19: =F19 -> 17100000 | H19: =G19 -> 17100000 | I19: =H19 -> 17100000 | J19: =I19 -> 17100000 | K19: =J19 -> 17100000 | L19: =K19 -> 17100000 | M19: =L19 -> 17100000 | ... P19: =O19 -> 17100000 | R19: =SUM(E19:P19) -> 205200000
B20: Medevac Ambulance (Air Ambulance | E20: =E40*E60 -> 50666667 | F20: =F40*F60 -> 50666667 | G20: =G40*G60 -> 50666667 | H20: =H40*H60 -> 50666667 | I20: =I40*I60 -> 50666667 | J20: =J40*J60 -> 50666667 | K20: =K40*K60 -> 50666667 | L20: =L40*L60 -> 50666667 | ... P20: =P40*P60 -> 50666667 | R20: =SUM(E20:P20) -> 608000000
B21: MER Plans | E21: =E41*E61 -> 1600000 | F21: =F41*F61 -> 1600000 | G21: =G41*G61 -> 1600000 | H21: =H41*H61 -> 1600000 | I21: =I41*I61 -> 1600000 | J21: =J41*J61 -> 1600000 | K21: =K41*K61 -> 1600000 | L21: =L41*L61 -> 1600000 | ... P21: =P41*P61 -> 1600000 | R21: =SUM(E21:P21) -> 19200000
B24: Average no of Patient
B25: Clinic
B26: PRIMARY CARE - Clinic Access Subscription - MEDVAC + Assistance Centre | E26: 15 | F26: 15 | G26: 15 | H26: 15 | I26: 15 | J26: 15 | K26: 15 | L26: 15 | M26: 15 | N26: 15 | O26: 15 | P26: 15 | R26: =SUM(E26:P26) -> 180
B27: PREMIUM - Clinic Access Subscription - MedLyfe (Wellness) + MEDVAC + Assistance Centre | E27: 4 | F27: 4 | G27: 4 | H27: 4 | I27: 4 | J27: 4 | K27: 4 | L27: 4 | M27: 4 | N27: 4 | O27: 4 | P27: 4 | R27: =SUM(E27:P27) -> 48
B28: Emergency Ground Ambulance /Evacuation Services | E28: 1 | F28: 2 | G28: 1 | H28: 2 | I28: 1 | J28: 2 | K28: 1 | L28: 2 | M28: 1 | N28: 2 | O28: 1 | P28: 2 | R28: =SUM(E28:P28) -> 18
B30: Healthcare Consulting:
B31: Workplace Solutions
B32: Medical Staffing (rate per Dr)
B33: Onsite Healthcare Review & Consulting
B35: Public Health Solutions & Preventative Care Programs
B36: Health Education & Preventive Care Programs
B38: Global Assistance Service:
B39: Annual Subscription for 24/7 Assistance Services (Telemedicine/ Virtual Consultations, Diagnosis and Treatment Plans) | E39: 15 | F39: 15 | G39: 15 | H39: 15 | I39: 15 | J39: 15 | K39: 15 | L39: 15 | M39: 15 | N39: 15 | O39: 15 | P39: 15 | R39: =SUM(E39:P39) -> 180
B40: Medevac Services (Air Ambulance) | E40: 4 | F40: =E40 -> 4 | G40: =F40 -> 4 | H40: =G40 -> 4 | I40: =H40 -> 4 | J40: =I40 -> 4 | K40: =J40 -> 4 | L40: =K40 -> 4 | M40: =L40 -> 4 | ... P40: =O40 -> 4 | R40: =SUM(E40:P40) -> 48
B41: MER Plans | E41: 1 | F41: 1 | G41: 1 | H41: 1 | I41: 1 | J41: 1 | K41: 1 | L41: 1 | M41: 1 | N41: 1 | O41: 1 | P41: 1 | R41: =SUM(E41:P41) -> 12
B44: Average case - Price | C44: EUR | D44: Rate (₦)
B45: Clinic | E45: Average price spent per person
B46: PRIMARY CARE - Clinic Access Subscription - MEDVAC + Assistance Centre | C46: 1050 | D46: 1900 | E46: =(D46*C46)/12 -> 166250 | F46: =E46 -> 166250 | G46: =F46 -> 166250 | H46: =G46 -> 166250 | I46: =H46 -> 166250 | J46: =I46 -> 166250 | K46: =J46 -> 166250 | L46: =K46 -> 166250 | M46: =L46 -> 166250 | ... P46: =O46 -> 166250 | R46: =SUM(E46:Q46) -> 1995000
B47: PREMIUM - Clinic Access Subscription - MedLyfe (Wellness) + MEDVAC + Assistance Centre | C47: 3500 | D47: 1900 | E47: =C47*D47 -> 6650000 | F47: 6650000 | G47: 6650000 | H47: 6650000 | I47: 6650000 | J47: 6650000 | K47: 6650000 | L47: 6650000 | M47: 6650000 | N47: 6650000 | O47: 6650000 | P47: 6650000 | R47: =SUM(E47:Q47) -> 79800000
B48: Emergency Ground Ambulance /Evacuation Services per case | C48: 115 | D48: 1600 | E48: =D48*C48 -> 184000 | F48: =E48 -> 184000 | G48: =F48 -> 184000 | H48: =G48 -> 184000 | I48: =H48 -> 184000 | J48: =I48 -> 184000 | K48: =J48 -> 184000 | L48: =K48 -> 184000 | M48: =L48 -> 184000 | ... P48: =O48 -> 184000 | R48: =SUM(E48:Q48) -> 2208000
R49: =SUM(E49:Q49) -> 0
B50: Healthcare Consulting: | R50: =SUM(E50:Q50) -> 0
B51: Workplace Solutions | R51: =SUM(E51:Q51) -> 0
...

Sheet Computations-Outputs
A2: Computations-Outputs
D3: Jan | E3: Feb | F3: Mar | G3: Apr | H3: May | I3: Jun | J3: Jul | K3: Aug | L3: Sep | M3: Oct | N3: Nov | O3: Dec | P3: FY 1 | Q3: FY 2 | R3: FY 3 | S3: FY 4 | T3: FY 5
D4: ₦ | E4: ₦ | F4: ₦ | G4: ₦ | H4: ₦ | I4: ₦ | J4: ₦ | K4: ₦ | L4: ₦ | M4: ₦ | N4: ₦ | O4: ₦ | P4: NGN | Q4: NGN | R4: NGN | S4: NGN | T4: NGN
B5: Revenue
B6: Clinic | D6: ='Assumption-Inputs'!E5 -> 29277750 | E6: ='Assumption-Inputs'!F5 -> 29277750 | F6: ='Assumption-Inputs'!G5 -> 29277750 | G6: ='Assumption-Inputs'!H5 -> 29277750 | H6: ='Assumption-Inputs'!I5 -> 29277750 | I6: ='Assumption-Inputs'!J5 -> 29277750 | J6: ='Assumption-Inputs'!K5 -> 29277750 | K6: ='Assumption-Inputs'!L5 -> 29277750 | ... O6: ='Assumption-Inputs'!P5 -> 29277750 | P6: =SUM(D6:O6) -> 351333000 | Q6: =P6*(1+'Assumption-Inputs'!F$67)*(1+'Assumption-Inputs'!F$70) -> 4.8483954e+08 | R6: =Q6*(1+'Assumption-Inputs'!G$67)*(1+'Assumption-Inputs'!G$70) -> 6.6907857e+08 | S6: =R6*(1+'Assumption-Inputs'!H$67)*(1+'Assumption-Inputs'!H$70) -> 9.2332842e+08 | T6: =S6*(1+'Assumption-Inputs'!I$67)*(1+'Assumption-Inputs'!I$70) -> 1.2741932e+09
B7: Healthcare Consulting | D7: ='Assumption-Inputs'!H10 -> 0 | E7: ='Assumption-Inputs'!F10 -> 0 | F7: ='Assumption-Inputs'!G10 -> 0 | G7: ='Assumption-Inputs'!H10 -> 0 | H7: ='Assumption-Inputs'!I10 -> 0 | I7: ='Assumption-Inputs'!J10 -> 0 | J7: ='Assumption-Inputs'!K10 -> 0 | K7: ='Assumption-Inputs'!L10 -> 0 | L7: ='Assumption-Inputs'!M10 -> 0 | ... O7: ='Assumption-Inputs'!P10 -> 0 | P7: =SUM(D7:O7) -> 0 | Q7: =P7*(1+'Assumption-Inputs'!F$67)*(1+'Assumption-Inputs'!F$70) -> 0 | R7: =Q7*(1+'Assumption-Inputs'!G$67)*(1+'Assumption-Inputs'!G$70) -> 0 | S7: =R7*(1+'Assumption-Inputs'!H$67)*(1+'Assumption-Inputs'!H$70) -> 0 | T7: =S7*(1+'Assumption-Inputs'!I$67)*(1+'Assumption-Inputs'!I$70) -> 0
B8: Public Health Solutions & Preventative Care Programs | D8: ='Assumption-Inputs'!E15 -> 0 | E8: ='Assumption-Inputs'!F15 -> 0 | F8: ='Assumption-Inputs'!G15 -> 0 | G8: ='Assumption-Inputs'!H15 -> 0 | H8: ='Assumption-Inputs'!I15 -> 0 | I8: ='Assumption-Inputs'!J15 -> 0 | J8: ='Assumption-Inputs'!K15 -> 0 | K8: ='Assumption-Inputs'!L15 -> 0 | ... O8: ='Assumption-Inputs'!P15 -> 0 | P8: =SUM(D8:O8) -> 0 | Q8: =P8*(1+'Assumption-Inputs'!F$67)*(1+'Assumption-Inputs'!F$70) -> 0 | R8: =Q8*(1+'Assumption-Inputs'!G$67)*(1+'Assumption-Inputs'!G$70) -> 0 | S8: =R8*(1+'Assumption-Inputs'!H$67)*(1+'Assumption-Inputs'!H$70) -> 0 | T8: =S8*(1+'Assumption-Inputs'!I$67)*(1+'Assumption-Inputs'!I$70) -> 0
B9: Global Assistance Service | D9: ='Assumption-Inputs'!E18 -> 69366667 | E9: ='Assumption-Inputs'!F18 -> 69366667 | F9: ='Assumption-Inputs'!G18 -> 69366667 | G9: ='Assumption-Inputs'!H18 -> 69366667 | H9: ='Assumption-Inputs'!I18 -> 69366667 | I9: ='Assumption-Inputs'!J18 -> 69366667 | J9: ='Assumption-Inputs'!K18 -> 69366667 | K9: ='Assumption-Inputs'!L18 -> 69366667 | ... O9: ='Assumption-Inputs'!P18 -> 69366667 | P9: =SUM(D9:O9) -> 8.324e+08 | Q9: =P9*(1+'Assumption-Inputs'!F$67)*(1+'Assumption-Inputs'!F$70) -> 1.148712e+09 | R9: =Q9*(1+'Assumption-Inputs'!G$67)*(1+'Assumption-Inputs'!G$70) -> 1.5852226e+09 | S9: =R9*(1+'Assumption-Inputs'!H$67)*(1+'Assumption-Inputs'!H$70) -> 2.1876071e+09 | T9: =S9*(1+'Assumption-Inputs'!I$67)*(1+'Assumption-Inputs'!I$70) -> 3.0188978e+09
B11: Total Revenue | D11: =SUM(D6:D9) -> 98644417 | E11: =SUM(E6:E9) -> 98644417 | F11: =SUM(F6:F9) -> 98644417 | G11: =SUM(G6:G9) -> 98644417 | H11: =SUM(H6:H9) -> 98644417 | I11: =SUM(I6:I9) -> 98644417 | J11: =SUM(J6:J9) -> 98644417 | K11: =SUM(K6:K9) -> 98644417 | ... T11: =SUM(T6:T9) -> 4.2930911e+09
B13: Cost of Revenue
B14: Direct Cost - Sales | C14: 0.4 | D14: =$C$14*D$11 -> 39457767 | E14: =D14 -> 39457767 | F14: =E14 -> 39457767 | G14: =F14 -> 39457767 | H14: =G14 -> 39457767 | I14: =H14 -> 39457767 | J14: =I14 -> 39457767 | K14: =J14 -> 39457767 | L14: =K14 -> 39457767 | ... O14: =N14 -> 39457767 | P14: =SUM(D14:O14) -> 4.734932e+08 | Q14: =P$11*(1+'Assumption-Inputs'!F$71)*'Assumption-Inputs'!$D$71 -> 5.2084252e+08 | R14: =Q$11*(1+'Assumption-Inputs'!G$71)*'Assumption-Inputs'!$D$71 -> 7.0569427e+08 | S14: =R$11*(1+'Assumption-Inputs'!H$71)*'Assumption-Inputs'!$D$71 -> 9.7385809e+08 | T14: =S$11*(1+'Assumption-Inputs'!I$71)*'Assumption-Inputs'!$D$71 -> 1.3190367e+09
B15: Direct Cost - Staff | C15: 0.07 | D15: =$C$15*D$11 -> 6905109.2 | E15: =D15 -> 6905109.2 | F15: =E15 -> 6905109.2 | G15: =F15 -> 6905109.2 | H15: =G15 -> 6905109.2 | I15: =H15 -> 6905109.2 | J15: =I15 -> 6905109.2 | K15: =J15 -> 6905109.2 | L15: =K15 -> 6905109.2 | ... O15: =N15 -> 6905109.2 | P15: =SUM(D15:O15) -> 82861310 | Q15: =P15 -> 82861310 | R15: =Q15 -> 82861310 | S15: =R15 -> 82861310 | T15: =S15 -> 82861310
B16: Direct Cost - Sales Commission | C16: 0.02 | D16: =$C$16*D$11 -> 1972888.3 | E16: =D16 -> 1972888.3 | F16: =E16 -> 1972888.3 | G16: =F16 -> 1972888.3 | H16: =G16 -> 1972888.3 | I16: =H16 -> 1972888.3 | J16: =I16 -> 1972888.3 | K16: =J16 -> 1972888.3 | L16: =K16 -> 1972888.3 | ... O16: =N16 -> 1972888.3 | P16: =SUM(D16:O16) -> 23674660 | Q16: =$C$16*Q11 -> 32671031 | R16: =$C$16*R11 -> 45086023 | S16: =$C$16*S11 -> 62218711 | T16: =$C$16*T11 -> 85861821
B17: Direct Cost - Overheads & Others | C17: 0.03 | D17: =$C$17*D$11 -> 2959332.5 | E17: =D17 -> 2959332.5 | F17: =E17 -> 2959332.5 | G17: =F17 -> 2959332.5 | H17: =G17 -> 2959332.5 | I17: =H17 -> 2959332.5 | J17: =I17 -> 2959332.5 | K17: =J17 -> 2959332.5 | L17: =K17 -> 2959332.5 | ... O17: =N17 -> 2959332.5 | P17: =SUM(D17:O17) -> 35511990
B19: Total Direct Cost | D19: =SUM(D14:D17) -> 51295097 | E19: =SUM(E14:E17) -> 51295097 | F19: =SUM(F14:F17) -> 51295097 | G19: =SUM(G14:G17) -> 51295097 | H19: =SUM(H14:H17) -> 51295097 | I19: =SUM(I14:I17) -> 51295097 | J19: =SUM(J14:J17) -> 51295097 | K19: =SUM(K14:K17) -> 51295097 | ... T19: =SUM(T14:T17) -> 1.4877598e+09
B21: Gross Profit | D21: =D11-D19 -> 47349320 | E21: =E11-E19 -> 47349320 | F21: =F11-F19 -> 47349320 | G21: =G11-G19 -> 47349320 | H21: =H11-H19 -> 47349320 | I21: =I11-I19 -> 47349320 | J21: =J11-J19 -> 47349320 | K21: =K11-K19 -> 47349320 | ... T21: =T11-T19 -> 2.8053313e+09
B23: Operating expenses
B24: Indirect Staff Cost | D24: =VLOOKUP($B24,'Assumption-Inputs'!$B:$P,4,FALSE) -> 0 | E24: =D24 -> 0 | F24: =E24 -> 0 | G24: =F24 -> 0 | H24: =G24 -> 0 | I24: =H24 -> 0 | J24: =I24 -> 0 | K24: =J24 -> 0 | L24: =K24 -> 0 | ... O24: =N24 -> 0 | P24: =SUM(D24:O24) -> 0 | Q24: =P24*(1+'Assumption-Inputs'!F$77) -> 0 | R24: =Q24*(1+'Assumption-Inputs'!G$77) -> 0 | S24: =R24*(1+'Assumption-Inputs'!H$77) -> 0 | T24: =S24*(1+'Assumption-Inputs'!I$77) -> 0
B25: Repair&Maintenance | D25: =VLOOKUP($B25,'Assumption-Inputs'!$B:$P,4,FALSE) -> 0 | E25: =D25 -> 0 | F25: =E25 -> 0 | G25: =F25 -> 0 | H25: =G25 -> 0 | I25: =H25 -> 0 | J25: =I25 -> 0 | K25: =J25 -> 0 | L25: =K25 -> 0 | ... O25: =N25 -> 0 | P25: =SUM(D25:O25) -> 0 | Q25: =P25*(1+'Assumption-Inputs'!F$68) -> 0 | R25: =Q25*(1+'Assumption-Inputs'!G$68) -> 0 | S25: =R25*(1+'Assumption-Inputs'!H$68) -> 0 | T25: =S25*(1+'Assumption-Inputs'!I$68) -> 0
B26: Bank Charges | D26: =VLOOKUP($B26,'Assumption-Inputs'!$B:$P,4,FALSE) -> 98644.417 | E26: =D26 -> 98644.417 | F26: =E26 -> 98644.417 | G26: =F26 -> 98644.417 | H26: =G26 -> 98644.417 | I26: =H26 -> 98644.417 | J26: =I26 -> 98644.417 | K26: =J26 -> 98644.417 | L26: =K26 -> 98644.417 | ... O26: =N26 -> 98644.417 | P26: =SUM(D26:O26) -> 1183733 | Q26: =P26*(1+'Assumption-Inputs'!F$68) -> 1361292.9 | R26: =Q26*(1+'Assumption-Inputs'!G$68) -> 1565486.9 | S26: =R26*(1+'Assumption-Inputs'!H$68) -> 1800309.9 | T26: =S26*(1+'Assumption-Inputs'!I$68) -> 2070356.4
B27: Advert, Printing & Stationery | D27: =VLOOKUP($B27,'Assumption-Inputs'!$B:$P,4,FALSE) -> 625000 | E27: =D27 -> 625000 | F27: =E27 -> 625000 | G27: =F27 -> 625000 | H27: =G27 -> 625000 | I27: =H27 -> 625000 | J27: =I27 -> 625000 | K27: =J27 -> 625000 | L27: =K27 -> 625000 | ... O27: =N27 -> 625000 | P27: =SUM(D27:O27) -> 7500000 | Q27: =P27*(1+'Assumption-Inputs'!F$68) -> 8625000 | R27: =Q27*(1+'Assumption-Inputs'!G$68) -> 9918750 | S27: =R27*(1+'Assumption-Inputs'!H$68) -> 11406562 | T27: =S27*(1+'Assumption-Inputs'!I$68) -> 13117547
B28: Rent | D28: =VLOOKUP($B28,'Assumption-Inputs'!$B:$P,4,FALSE) -> 0 | E28: =D28 -> 0 | F28: =E28 -> 0 | G28: =F28 -> 0 | H28: =G28 -> 0 | I28: =H28 -> 0 | J28: =I28 -> 0 | K28: =J28 -> 0 | L28: =K28 -> 0 | ... O28: =N28 -> 0 | P28: =SUM(D28:O28) -> 0 | Q28: =P28*(1+'Assumption-Inputs'!F$68) -> 0 | R28: =Q28*(1+'Assumption-Inputs'!G$68) -> 0 | S28: =R28*(1+'Assumption-Inputs'!H$68) -> 0 | T28: =S28*(1+'Assumption-Inputs'!I$68) -> 0
B29: Internet | D29: =VLOOKUP($B29,'Assumption-Inputs'!$B:$P,4,FALSE) -> 200000 | E29: =D29 -> 200000 | F29: =E29 -> 200000 | G29: =F29 -> 200000 | H29: =G29 -> 200000 | I29: =H29 -> 200000 | J29: =I29 -> 200000 | K29: =J29 -> 200000 | L29: =K29 -> 200000 | ... O29: =N29 -> 200000 | P29: =SUM(D29:O29) -> 2400000 | Q29: =P29*(1+'Assumption-Inputs'!F$68) -> 2760000 | R29: =Q29*(1+'Assumption-Inputs'!G$68) -> 3174000 | S29: =R29*(1+'Assumption-Inputs'!H$68) -> 3650100 | T29: =S29*(1+'Assumption-Inputs'!I$68) -> 4197615
B30: Cleaning Services | D30: =VLOOKUP($B30,'Assumption-Inputs'!$B:$P,4,FALSE) -> 0 | E30: =D30 -> 0 | F30: =E30 -> 0 | G30: =F30 -> 0 | H30: =G30 -> 0 | I30: =H30 -> 0 | J30: =I30 -> 0 | K30: =J30 -> 0 | L30: =K30 -> 0 | ... O30: =N30 -> 0 | P30: =SUM(D30:O30) -> 0 | Q30: =P30*(1+'Assumption-Inputs'!F$68) -> 0 | R30: =Q30*(1+'Assumption-Inputs'!G$68) -> 0 | S30: =R30*(1+'Assumption-Inputs'!H$68) -> 0 | T30: =S30*(1+'Assumption-Inputs'!I$68) -> 0
B31: Fuel for Gen | D31: =VLOOKUP($B31,'Assumption-Inputs'!$B:$P,4,FALSE) -> 0 | E31: =D31 -> 0 | F31: =E31 -> 0 | G31: =F31 -> 0 | H31: =G31 -> 0 | I31: =H31 -> 0 | J31: =I31 -> 0 | K31: =J31 -> 0 | L31: =K31 -> 0 | ... O31: =N31 -> 0 | P31: =SUM(D31:O31) -> 0 | Q31: =P31*(1+'Assumption-Inputs'!F$68) -> 0 | R31: =Q31*(1+'Assumption-Inputs'!G$68) -> 0 | S31: =R31*(1+'Assumption-Inputs'!H$68) -> 0 | T31: =S31*(1+'Assumption-Inputs'!I$68) -> 0
B32: Electricity | D32: =VLOOKUP($B32,'Assumption-Inputs'!$B:$P,4,FALSE) -> 0 | E32: =D32 -> 0 | F32: =E32 -> 0 | G32: =F32 -> 0 | H32: =G32 -> 0 | I32: =H32 -> 0 | J32: =I32 -> 0 | K32: =J32 -> 0 | L32: =K32 -> 0 | ... O32: =N32 -> 0 | P32: =SUM(D32:O32) -> 0 | Q32: =P32*(1+'Assumption-Inputs'!F$68) -> 0 | R32: =Q32*(1+'Assumption-Inputs'!G$68) -> 0 | S32: =R32*(1+'Assumption-Inputs'!H$68) -> 0 | T32: =S32*(1+'Assumption-Inputs'!I$68) -> 0
B33: CAPEX | D33: =VLOOKUP($B33,'Assumption-Inputs'!$B:$P,4,FALSE) -> 1833333 | E33: =D33 -> 1833333 | F33: =E33 -> 1833333 | G33: =F33 -> 1833333 | H33: =G33 -> 1833333 | I33: =H33 -> 1833333 | J33: =I33 -> 1833333 | K33: =J33 -> 1833333 | L33: =K33 -> 1833333 | ... O33: =N33 -> 1833333 | P33: =SUM(D33:O33) -> 21999996 | Q33: =P33*(1+'Assumption-Inputs'!F$68) -> 25299995 | R33: =Q33*(1+'Assumption-Inputs'!G$68) -> 29094995 | S33: =R33*(1+'Assumption-Inputs'!H$68) -> 33459244 | T33: =S33*(1+'Assumption-Inputs'!I$68) -> 38478131
B34: Local Govt Levies & Charges | D34: =VLOOKUP($B34,'Assumption-Inputs'!$B:$P,4,FALSE) -> 125000 | E34: =D34 -> 125000 | F34: =E34 -> 125000 | G34: =F34 -> 125000 | H34: =G34 -> 125000 | I34: =H34 -> 125000 | J34: =I34 -> 125000 | K34: =J34 -> 125000 | L34: =K34 -> 125000 | ... O34: =N34 -> 125000 | P34: =SUM(D34:O34) -> 1500000 | Q34: =P34*(1+'Assumption-Inputs'!F$68) -> 1725000 | R34: =Q34*(1+'Assumption-Inputs'!G$68) -> 1983750 | S34: =R34*(1+'Assumption-Inputs'!H$68) -> 2281312.5 | T34: =S34*(1+'Assumption-Inputs'!I$68) -> 2623509.4
B35: Insurance Expenses | D35: =VLOOKUP($B35,'Assumption-Inputs'!$B:$P,4,FALSE) -> 100000 | E35: =D35 -> 100000 | F35: =E35 -> 100000 | G35: =F35 -> 100000 | H35: =G35 -> 100000 | I35: =H35 -> 100000 | J35: =I35 -> 100000 | K35: =J35 -> 100000 | L35: =K35 -> 100000 | ... O35: =N35 -> 100000 | P35: =SUM(D35:O35) -> 1200000 | Q35: =P35*(1+'Assumption-Inputs'!F$68) -> 1380000 | R35: =Q35*(1+'Assumption-Inputs'!G$68) -> 1587000 | S35: =R35*(1+'Assumption-Inputs'!H$68) -> 1825050 | T35: =S35*(1+'Assumption-Inputs'!I$68) -> 2098807.5
B36: Contribution | D36: =VLOOKUP($B36,'Assumption-Inputs'!$B:$P,4,FALSE) -> 500000 | E36: =D36 -> 500000 | F36: =E36 -> 500000 | G36: =F36 -> 500000 | H36: =G36 -> 500000 | I36: =H36 -> 500000 | J36: =I36 -> 500000 | K36: =J36 -> 500000 | L36: =K36 -> 500000 | ... O36: =N36 -> 500000 | P36: =SUM(D36:O36) -> 6000000 | Q36: =P36*(1+'Assumption-Inputs'!F$68) -> 6900000 | R36: =Q36*(1+'Assumption-Inputs'!G$68) -> 7935000 | S36: =R36*(1+'Assumption-Inputs'!H$68) -> 9125250 | T36: =S36*(1+'Assumption-Inputs'!I$68) -> 10494037
B38: Total Opex | D38: =SUM(D24:D36) -> 3481977.4 | E38: =SUM(E24:E36) -> 3481977.4 | F38: =SUM(F24:F36) -> 3481977.4 | G38: =SUM(G24:G36) -> 3481977.4 | H38: =SUM(H24:H36) -> 3481977.4 | I38: =SUM(I24:I36) -> 3481977.4 | J38: =SUM(J24:J36) -> 3481977.4 | K38: =SUM(K24:K36) -> 3481977.4 | ... Q38: =SUM(Q24:Q36) -> 48051288 | R38: =SUM(R25:R36) -> 55258982 | S38: =SUM(S25:S36) -> 63547829 | T38: =SUM(T25:T36) -> 73080003
B40: EBITDA | D40: =D21-D38 -> 43867343 | E40: =E21-E38 -> 43867343 | F40: =F21-F38 -> 43867343 | G40: =G21-G38 -> 43867343 | H40: =H21-H38 -> 43867343 | I40: =I21-I38 -> 43867343 | J40: =J21-J38 -> 43867343 | K40: =K21-K38 -> 43867343 | ... T40: =T21-T38 -> 2.7322513e+09
B42: Depreciation Expenses | D42: =VLOOKUP($B42,'Assumption-Inputs'!$B:$P,4,FALSE) -> 50000 | E42: =D42 -> 50000 | F42: =E42 -> 50000 | G42: =F42 -> 50000 | H42: =G42 -> 50000 | I42: =H42 -> 50000 | J42: =I42 -> 50000 | K42: =J42 -> 50000 | L42: =K42 -> 50000 | ... O42: =N42 -> 50000 | P42: =SUM(D42:O42) -> 600000 | Q42: =P42*(1+'Assumption-Inputs'!F$68) -> 690000 | R42: =Q42*(1+'Assumption-Inputs'!G$68) -> 793500 | S42: =R42*(1+'Assumption-Inputs'!H$68) -> 912525 | T42: =S42*(1+'Assumption-Inputs'!I$68) -> 1049403.7
B44: Net Profit/(Loss) | D44: =D40-D42 -> 43817343 | E44: =E40-E42 -> 43817343 | F44: =F40-F42 -> 43817343 | G44: =G40-G42 -> 43817343 | H44: =H40-H42 -> 43817343 | I44: =I40-I42 -> 43817343 | J44: =J40-J42 -> 43817343 | K44: =K40-K42 -> 43817343 | ... T44: =T40-T42 -> 2.7312019e+09
B46: Accumulated EBITDA | D46: =D44 -> 43817343 | E46: =D46+E44 -> 87634685 | F46: =E46+F44 -> 1.3145203e+08 | G46: =F46+G44 -> 1.7526937e+08 | H46: =G46+H44 -> 2.1908671e+08 | I46: =H46+I44 -> 2.6290406e+08 | J46: =I46+J44 -> 3.067214e+08 | K46: =J46+K44 -> 3.5053874e+08 | L46: =K46+L44 -> 3.9435608e+08 | ... O46: =N46+O44 -> 5.2580811e+08 | P46: =P44 -> 5.2580811e+08 | Q46: =P46+Q40 -> 1.4749335e+09 | R46: =Q46+R40 -> 2.840334e+09 | S46: =R46+S40 -> 4.7687837e+09 | T46: =S46+T40 -> 7.5010349e+09
B48: Total Investment
B50: Pay back Balance | D50: =D46-D48 -> 43817343 | E50: =E46-E48 -> 87634685 | F50: =F46-F48 -> 1.3145203e+08 | G50: =G46-G48 -> 1.7526937e+08 | H50: =H46-H48 -> 2.1908671e+08 | I50: =I46-I48 -> 2.6290406e+08 | J50: =J46-J48 -> 3.067214e+08 | K50: =K46-K48 -> 3.5053874e+08 | ... T50: =T46-T48 -> 7.5010349e+09
B52: Pay back Period | P52: =IF(P50>0,"1 Year"," ") -> 1 Year | Q52: =IF(Q50>0,"2 Year"," ") -> 2 Year | R52: =IF(R50>0,"3 Year"," ") -> 3 Year | S52: =IF(S50>0,"4 Year"," ") -> 4 Year | T52: =IF(T50>0,"5 Year"," ") -> 5 Year
