Workbook
Name afril: #REF!
Name BS: #REF!
Name costaa: #REF!
Name Department: #REF!
Name expense: '[1]Exp scxhedule'!$AU$10:$AU$43
Name Expenses: #REF!
Name F: #REF!
Name fs: #REF!
Name GGGG: #REF!
Name groupincome: #REF!
Name LOCATION: [1]Payables!$W$4:$W$6
Name Locattion: '[1]Exp scxhedule'!$AX$10:$AX$11
Name MANS: #REF!
Name OLDMAN: #REF!
Name PAC: #REF!
Name PL: #REF!
Name REGISTRAR: #REF!
Name SCHD3: #REF!
Name SCHED1: #REF!
Name SCHED2: #REF!
Name SCHED3: #REF!
Name SCHED4: #REF!
Name SEMI: #REF!
Name SSES: #REF!
Name STAT: '[1]Exp scxhedule'!$AY$10:$AY$13
Name SUMMARY: #REF!
Name yyy: #REF!

Sheet Assumption (Corp Clinic)
B1: MedClinic
B2: Live_Case | D2: Jan | E2: Feb | F2: Mar | G2: Apr | H2: May | I2: Jun | J2: Jul | K2: Aug | L2: Sep | M2: Oct | N2: Nov | O2: Dec | P2: Total
B3: Medstaffing | D3: =SUM(D4:D19) -> 5010000 | E3: =SUM(E4:E19) -> 7360000 | F3: =SUM(F4:F19) -> 5010000 | G3: =SUM(G4:G19) -> 7360000 | H3: =SUM(H4:H19) -> 5010000 | I3: =SUM(I4:I19) -> 7360000 | J3: =SUM(J4:J19) -> 5010000 | K3: =SUM(K4:K19) -> 7360000 | ... P3: =SUM(P4:P19) -> 74220000
B4: Onshore Medical Doctor | D4: =D35*D63 -> 1530000 | E4: =E35*E63 -> 1530000 | F4: =F35*F63 -> 1530000 | G4: =G35*G63 -> 1530000 | H4: =H35*H63 -> 1530000 | I4: =I35*I63 -> 1530000 | J4: =J35*J63 -> 1530000 | K4: =K35*K63 -> 1530000 | ... O4: =O35*O63 -> 1530000 | P4: =SUM(D4:O4) -> 18360000
B5: Onshore Nurses | D5: =D36*D64 -> 1350000 | E5: =E36*E64 -> 1350000 | F5: =F36*F64 -> 1350000 | G5: =G36*G64 -> 1350000 | H5: =H36*H64 -> 1350000 | I5: =I36*I64 -> 1350000 | J5: =J36*J64 -> 1350000 | K5: =K36*K64 -> 1350000 | ... O5: =O36*O64 -> 1350000 | P5: =SUM(D5:O5) -> 16200000
B6: Onshore Pharm Technician | D6: =D37*D65 -> 380000 | E6: =E37*E65 -> 380000 | F6: =F37*F65 -> 380000 | G6: =G37*G65 -> 380000 | H6: =H37*H65 -> 380000 | I6: =I37*I65 -> 380000 | J6: =J37*J65 -> 380000 | K6: =K37*K65 -> 380000 | ... O6: =O37*O65 -> 380000 | P6: =SUM(D6:O6) -> 4560000
B7: Onshore Pharmacist | D7: =D38*D66 -> 450000 | E7: =E38*E66 -> 450000 | F7: =F38*F66 -> 450000 | G7: =G38*G66 -> 450000 | H7: =H38*H66 -> 450000 | I7: =I38*I66 -> 450000 | J7: =J38*J66 -> 450000 | K7: =K38*K66 -> 450000 | ... O7: =O38*O66 -> 450000 | P7: =SUM(D7:O7) -> 5400000
B8: Onshore Medical Doctor-Team Berlin | D8: =D39*D67 -> 0 | E8: =E39*E67 -> 0 | F8: =F39*F67 -> 0 | G8: =G39*G67 -> 0 | H8: =H39*H67 -> 0 | I8: =I39*I67 -> 0 | J8: =J39*J67 -> 0 | K8: =K39*K67 -> 0 | ... O8: =O39*O67 -> 0 | P8: =SUM(D8:O8) -> 0
B9: Onshore Nurses-Team Berlin | D9: =D40*D68 -> 0 | E9: =E40*E68 -> 0 | F9: =F40*F68 -> 0 | G9: =G40*G68 -> 0 | H9: =H40*H68 -> 0 | I9: =I40*I68 -> 0 | J9: =J40*J68 -> 0 | K9: =K40*K68 -> 0 | ... O9: =O40*O68 -> 0 | P9: =SUM(D9:O9) -> 0
B10: Onshore Pharm Technician-Team Berlin | D10: =D41*D69 -> 0 | E10: =E41*E69 -> 0 | F10: =F41*F69 -> 0 | G10: =G41*G69 -> 0 | H10: =H41*H69 -> 0 | I10: =I41*I69 -> 0 | J10: =J41*J69 -> 0 | K10: =K41*K69 -> 0 | ... O10: =O41*O69 -> 0 | P10: =SUM(D10:O10) -> 0
B11: Onshore Pharmacist-Team Berlin | D11: =D42*D70 -> 0 | E11: =E42*E70 -> 0 | F11: =F42*F70 -> 0 | G11: =G42*G70 -> 0 | H11: =H42*H70 -> 0 | I11: =I42*I70 -> 0 | J11: =J42*J70 -> 0 | K11: =K42*K70 -> 0 | ... O11: =O42*O70 -> 0 | P11: =SUM(D11:O11) -> 0
B12: Offshore Medical Doctor | D12: =D43*D71 -> 0 | E12: =E43*E71 -> 1500000 | F12: =F43*F71 -> 0 | G12: =G43*G71 -> 1500000 | H12: =H43*H71 -> 0 | I12: =I43*I71 -> 1500000 | J12: =J43*J71 -> 0 | K12: =K43*K71 -> 1500000 | ... O12: =O43*O71 -> 1500000 | P12: =SUM(D12:O12) -> 9000000
B13: Offshore Nurses | D13: =D44*D72 -> 850000 | E13: =E44*E72 -> 850000 | F13: =F44*F72 -> 850000 | G13: =G44*G72 -> 850000 | H13: =H44*H72 -> 850000 | I13: =I44*I72 -> 850000 | J13: =J44*J72 -> 850000 | K13: =K44*K72 -> 850000 | ... O13: =O44*O72 -> 850000 | P13: =SUM(D13:O13) -> 10200000
B14: Offshore Pharm Technician | D14: =D45*D73 -> 450000 | E14: =E45*E73 -> 450000 | F14: =F45*F73 -> 450000 | G14: =G45*G73 -> 450000 | H14: =H45*H73 -> 450000 | I14: =I45*I73 -> 450000 | J14: =J45*J73 -> 450000 | K14: =K45*K73 -> 450000 | ... O14: =O45*O73 -> 450000 | P14: =SUM(D14:O14) -> 5400000
B15: Offshore Pharmacist | D15: =D46*D74 -> 0 | E15: =E46*E74 -> 850000 | F15: =F46*F74 -> 0 | G15: =G46*G74 -> 850000 | H15: =H46*H74 -> 0 | I15: =I46*I74 -> 850000 | J15: =J46*J74 -> 0 | K15: =K46*K74 -> 850000 | ... O15: =O46*O74 -> 850000 | P15: =SUM(D15:O15) -> 5100000
... B19: Offshore Pharmacist-Team Berlin | D19: =D50*D78 -> 0 | E19: =E50*E78 -> 0 | F19: =F50*F78 -> 0 | G19: =G50*G78 -> 0 | H19: =H50*H78 -> 0 | I19: =I50*I78 -> 0 | J19: =J50*J78 -> 0 | K19: =K50*K78 -> 0 | ... O19: =O50*O78 -> 0 | P19: =SUM(D19:O19) -> 0
B22: Outsourced Corporate Clinics | D22: =SUM(D23:D29) -> 15637783 | E22: =SUM(E23:E29) -> 15637783 | F22: =SUM(F23:F29) -> 15637783 | G22: =SUM(G23:G29) -> 15637783 | H22: =SUM(H23:H29) -> 15637783 | I22: =SUM(I23:I29) -> 15637783 | J22: =SUM(J23:J29) -> 15637783 | K22: =SUM(K23:K29) -> 15637783 | ... P22: =SUM(P23:P29) -> 1.876534e+08
B23: APM Terminals | D23: =D53*D81 -> 4825999.6 | E23: =D23 -> 4825999.6 | F23: =E23 -> 4825999.6 | G23: =F23 -> 4825999.6 | H23: =G23 -> 4825999.6 | I23: =H23 -> 4825999.6 | J23: =I23 -> 4825999.6 | K23: =J23 -> 4825999.6 | L23: =K23 -> 4825999.6 | ... O23: =N23 -> 4825999.6 | P23: =SUM(D23:O23) -> 57911995 | Q23: Clinic Outsourcing
B24: Guiness Plc | D24: =D54*D82 -> 2631766.6 | E24: =E54*E82 -> 2631766.6 | F24: =F54*F82 -> 2631766.6 | G24: =G54*G82 -> 2631766.6 | H24: =H54*H82 -> 2631766.6 | I24: =I54*I82 -> 2631766.6 | J24: =J54*J82 -> 2631766.6 | K24: =K54*K82 -> 2631766.6 | ... O24: =O54*O82 -> 2631766.6 | P24: =SUM(D24:O24) -> 31581200 | Q24: Clinic Outsourcing
B25: Pipe Coaters Tenaris | D25: =D55*D83 -> 609150 | E25: =E55*E83 -> 609150 | F25: =F55*F83 -> 609150 | G25: =G55*G83 -> 609150 | H25: =H55*H83 -> 609150 | I25: =I55*I83 -> 609150 | J25: =J55*J83 -> 609150 | K25: =K55*K83 -> 609150 | ... O25: =O55*O83 -> 609150 | P25: =SUM(D25:O25) -> 7309800 | Q25: Clinic Outsourcing
B26: BATN | D26: =(D56*D84) -> 4570867.2 | E26: =D26 -> 4570867.2 | F26: =E26 -> 4570867.2 | G26: =F26 -> 4570867.2 | H26: =G26 -> 4570867.2 | I26: =H26 -> 4570867.2 | J26: =I26 -> 4570867.2 | K26: =J26 -> 4570867.2 | L26: =K26 -> 4570867.2 | ... O26: =N26 -> 4570867.2 | P26: =SUM(D26:O26) -> 54850407 | Q26: Quarterly Clinic outsourcing
B27: Shell IA | D27: =(D57*D85) -> 0 | E27: =D27 -> 0 | F27: =E27 -> 0 | G27: =F27 -> 0 | H27: =G27 -> 0 | I27: =H27 -> 0 | J27: =I27 -> 0 | K27: =J27 -> 0 | L27: =K27 -> 0 | ... O27: =N27 -> 0 | P27: =SUM(D27:O27) -> 0
B28: Oando | D28: =(D58*D86) -> 0 | E28: =D28 -> 0 | F28: =E28 -> 0 | G28: =F28 -> 0 | H28: =G28 -> 0 | I28: =H28 -> 0 | J28: =I28 -> 0 | K28: =J28 -> 0 | L28: =K28 -> 0 | ... O28: =N28 -> 0 | P28: =SUM(D28:O28) -> 0
B29: Others- Team Berlin | D29: 3000000 | E29: =D29 -> 3000000 | F29: =E29 -> 3000000 | G29: =F29 -> 3000000 | H29: =G29 -> 3000000 | I29: =H29 -> 3000000 | J29: =I29 -> 3000000 | K29: =J29 -> 3000000 | L29: =K29 -> 3000000 | ... O29: =N29 -> 3000000 | P29: =SUM(D29:O29) -> 36000000
B31: Total Revenue | D31: =D3+D22 -> 20647783 | E31: =E3+E22 -> 22997783 | F31: =F3+F22 -> 20647783 | G31: =G3+G22 -> 22997783 | H31: =H3+H22 -> 20647783 | I31: =I3+I22 -> 22997783 | J31: =J3+J22 -> 20647783 | K31: =K3+K22 -> 22997783 | ... P31: =P3+P22 -> 2.618734e+08
B33: Average no Staff
B34: Medstaffing | D34: =SUM(D35:D46) -> 9 | E34: =SUM(E35:E46) -> 11 | F34: =SUM(F35:F46) -> 9 | G34: =SUM(G35:G46) -> 11 | H34: =SUM(H35:H46) -> 9 | I34: =SUM(I35:I46) -> 11 | J34: =SUM(J35:J46) -> 9 | K34: =SUM(K35:K46) -> 11 | ... P34: =SUM(P35:P46) -> 120
B35: Onshore Medical Doctor | D35: 2 | E35: 2 | F35: 2 | G35: 2 | H35: 2 | I35: 2 | J35: 2 | K35: 2 | L35: 2 | M35: 2 | N35: 2 | O35: 2 | P35: =SUM(D35:O35) -> 24
B36: Onshore Nurses | D36: 3 | E36: 3 | F36: 3 | G36: 3 | H36: 3 | I36: 3 | J36: 3 | K36: 3 | L36: 3 | M36: 3 | N36: 3 | O36: 3 | P36: =SUM(D36:O36) -> 36
B37: Onshore Pharm Technician | D37: 1 | E37: 1 | F37: 1 | G37: =F37 -> 1 | H37: =G37 -> 1 | I37: =H37 -> 1 | J37: =I37 -> 1 | K37: =J37 -> 1 | L37: =K37 -> 1 | M37: =L37 -> 1 | N37: =M37 -> 1 | O37: =N37 -> 1 | P37: =SUM(D37:O37) -> 12
B38: Onshore Pharmacist | D38: 1 | E38: 1 | F38: 1 | G38: =F38 -> 1 | H38: =G38 -> 1 | I38: =H38 -> 1 | J38: =I38 -> 1 | K38: =J38 -> 1 | L38: =K38 -> 1 | M38: =L38 -> 1 | N38: =M38 -> 1 | O38: =N38 -> 1 | P38: =SUM(D38:O38) -> 12
B39: Onshore Medical Doctor-Team Berlin | D39: 0 | E39: 0 | F39: 0 | G39: 0 | H39: 0 | I39: 0 | J39: 0 | K39: 0 | L39: 0 | M39: 0 | N39: 0 | O39: 0 | P39: =SUM(D39:O39) -> 0
B40: Onshore Nurses-Team Berlin | D40: 0 | E40: 0 | F40: 0 | G40: 0 | H40: 0 | I40: 0 | J40: 0 | K40: 0 | L40: 0 | M40: 0 | N40: 0 | O40: 0 | P40: =SUM(D40:O40) -> 0
B41: Onshore Pharm Technician-Team Berlin | D41: 0 | E41: 0 | F41: 0 | G41: 0 | H41: 0 | I41: 0 | J41: 0 | K41: 0 | L41: 0 | M41: 0 | N41: 0 | O41: 0 | P41: =SUM(D41:O41) -> 0
B42: Onshore Pharmacist-Team Berlin | D42: 0 | E42: 0 | F42: 0 | G42: 0 | H42: 0 | I42: 0 | J42: 0 | K42: 0 | L42: 0 | M42: 0 | N42: 0 | O42: 0 | P42: =SUM(D42:O42) -> 0
B43: Offshore Medical Doctor | D43: 0 | E43: 1 | F43: 0 | G43: 1 | H43: 0 | I43: 1 | J43: 0 | K43: 1 | L43: 0 | M43: 1 | N43: 0 | O43: 1 | P43: =SUM(D43:O43) -> 6
B44: Offshore Nurses | D44: 1 | E44: 1 | F44: 1 | G44: 1 | H44: 1 | I44: 1 | J44: 1 | K44: 1 | L44: 1 | M44: 1 | N44: 1 | O44: 1 | P44: =SUM(D44:O44) -> 12
B45: Offshore Pharm Technician | D45: 1 | E45: 1 | F45: 1 | G45: =F45 -> 1 | H45: =G45 -> 1 | I45: =H45 -> 1 | J45: =I45 -> 1 | K45: =J45 -> 1 | L45: =K45 -> 1 | M45: =L45 -> 1 | N45: =M45 -> 1 | O45: =N45 -> 1 | P45: =SUM(D45:O45) -> 12
B46: Offshore Pharmacist | D46: 0 | E46: 1 | F46: 0 | G46: 1 | H46: 0 | I46: 1 | J46: 0 | K46: 1 | L46: 0 | M46: 1 | N46: 0 | O46: 1 | P46: =SUM(D46:O46) -> 6
B47: Offshore Medical Doctor-Team Berlin | D47: 0 | E47: 0 | F47: 0 | G47: 0 | H47: 0 | I47: 0 | J47: 0 | K47: 0 | L47: 0 | M47: 0 | N47: 0 | O47: 0 | P47: =SUM(D47:O47) -> 0
...

Sheet Computations (Corp Clinic)
B2: Computations-Outputs
D3: Jan | E3: Feb | F3: Mar | G3: Apr | H3: May | I3: Jun | J3: Jul | K3: Aug | L3: Sep | M3: Oct | N3: Nov | O3: Dec | P3: FY 1 | Q3: FY 2 | R3: FY 3 | S3: FY 4 | T3: FY 5
D4: ₦ | E4: ₦ | F4: ₦ | G4: ₦ | H4: ₦ | I4: ₦ | J4: ₦ | K4: ₦ | L4: ₦ | M4: ₦ | N4: ₦ | O4: ₦ | P4: NGN | Q4: NGN | R4: NGN | S4: NGN | T4: NGN
B5: Revenue
B6: Medstaffing | D6: =VLOOKUP($B6,'Assumption (Corp Clinic)'!$B:$P,3,FALSE) -> 5010000 | E6: =VLOOKUP($B6,'Assumption (Corp Clinic)'!$B:$P,4,FALSE) -> 7360000 | F6: =VLOOKUP($B6,'Assumption (Corp Clinic)'!$B:$P,5,FALSE) -> 5010000 | G6: =VLOOKUP($B6,'Assumption (Corp Clinic)'!$B:$P,6,FALSE) -> 7360000 | H6: =VLOOKUP($B6,'Assumption (Corp Clinic)'!$B:$P,7,FALSE) -> 5010000 | I6: =VLOOKUP($B6,'Assumption (Corp Clinic)'!$B:$P,8,FALSE) -> 7360000 | J6: =VLOOKUP($B6,'Assumption (Corp Clinic)'!$B:$P,9,FALSE) -> 5010000 | K6: =VLOOKUP($B6,'Assumption (Corp Clinic)'!$B:$P,10,FALSE) -> 7360000 | L6: =VLOOKUP($B6,'Assumption (Corp Clinic)'!$B:$P,11,FALSE) -> 5010000 | M6: =VLOOKUP($B6,'Assumption (Corp Clinic)'!$B:$P,12,FALSE) -> 7360000 | N6: =VLOOKUP($B6,'Assumption (Corp Clinic)'!$B:$P,13,FALSE) -> 5010000 | O6: =VLOOKUP($B6,'Assumption (Corp Clinic)'!$B:$P,14,FALSE) -> 7360000 | P6: =SUM(D6:O6) -> 74220000 | Q6: =P6*(1+'[2]Assumption (Advisory)'!E$45)*(1+'[2]Assumption (Advisory)'!E$48) -> 102423600 | R6: =Q6*(1+'[2]Assumption (Advisory)'!F$45)*(1+'[2]Assumption (Advisory)'!F$48) -> 1.4134457e+08 | S6: =R6*(1+'[2]Assumption (Advisory)'!G$45)*(1+'[2]Assumption (Advisory)'!G$48) -> 1.950555e+08 | T6: =S6*(1+'[2]Assumption (Advisory)'!H$45)*(1+'[2]Assumption (Advisory)'!H$48) -> 2.691766e+08
B7: Outsourced Corporate Clinics | D7: =VLOOKUP($B7,'Assumption (Corp Clinic)'!$B:$P,3,FALSE) -> 15637783 | E7: =VLOOKUP($B7,'Assumption (Corp Clinic)'!$B:$P,4,FALSE) -> 15637783 | F7: =VLOOKUP($B7,'Assumption (Corp Clinic)'!$B:$P,5,FALSE) -> 15637783 | G7: =VLOOKUP($B7,'Assumption (Corp Clinic)'!$B:$P,6,FALSE) -> 15637783 | H7: =VLOOKUP($B7,'Assumption (Corp Clinic)'!$B:$P,7,FALSE) -> 15637783 | I7: =VLOOKUP($B7,'Assumption (Corp Clinic)'!$B:$P,8,FALSE) -> 15637783 | J7: =VLOOKUP($B7,'Assumption (Corp Clinic)'!$B:$P,9,FALSE) -> 15637783 | K7: =VLOOKUP($B7,'Assumption (Corp Clinic)'!$B:$P,10,FALSE) -> 15637783 | L7: =VLOOKUP($B7,'Assumption (Corp Clinic)'!$B:$P,11,FALSE) -> 15637783 | M7: =VLOOKUP($B7,'Assumption (Corp Clinic)'!$B:$P,12,FALSE) -> 15637783 | N7: =VLOOKUP($B7,'Assumption (Corp Clinic)'!$B:$P,13,FALSE) -> 15637783 | O7: =VLOOKUP($B7,'Assumption (Corp Clinic)'!$B:$P,14,FALSE) -> 15637783 | P7: =SUM(D7:O7) -> 1.876534e+08 | Q7: =P7*(1+'[2]Assumption (Advisory)'!E$45)*(1+'[2]Assumption (Advisory)'!E$48) -> 2.5896169e+08 | R7: =Q7*(1+'[2]Assumption (Advisory)'!F$45)*(1+'[2]Assumption (Advisory)'!F$48) -> 3.5736714e+08 | S7: =R7*(1+'[2]Assumption (Advisory)'!G$45)*(1+'[2]Assumption (Advisory)'!G$48) -> 4.9316665e+08 | T7: =S7*(1+'[2]Assumption (Advisory)'!H$45)*(1+'[2]Assumption (Advisory)'!H$48) -> 6.8056998e+08
B9: Total Revenue | D9: =SUM(D6:D7) -> 20647783 | E9: =SUM(E6:E7) -> 22997783 | F9: =SUM(F6:F7) -> 20647783 | G9: =SUM(G6:G7) -> 22997783 | H9: =SUM(H6:H7) -> 20647783 | I9: =SUM(I6:I7) -> 22997783 | J9: =SUM(J6:J7) -> 20647783 | K9: =SUM(K6:K7) -> 22997783 | ... T9: =SUM(T6:T7) -> 9.4974657e+08
B11: Cost of Revenue
B12: Direct Cost - Consumables | D12: =VLOOKUP($B12,'Assumption (Corp Clinic)'!$B:$P,3,FALSE) -> 7637974.2 | E12: =D12 -> 7637974.2 | F12: =E12 -> 7637974.2 | G12: =F12 -> 7637974.2 | H12: =G12 -> 7637974.2 | I12: =H12 -> 7637974.2 | J12: =I12 -> 7637974.2 | K12: =J12 -> 7637974.2 | L12: =K12 -> 7637974.2 | ... O12: =N12 -> 7637974.2 | P12: =SUM(D12:O12) -> 91655691
B13: Direct Cost - Staff | D13: =VLOOKUP($B13,'Assumption (Corp Clinic)'!$B:$P,3,FALSE)/12 -> 437445.83 | E13: =D13 -> 437445.83 | F13: =E13 -> 437445.83 | G13: =F13 -> 437445.83 | H13: =G13 -> 437445.83 | I13: =H13 -> 437445.83 | J13: =I13 -> 437445.83 | K13: =J13 -> 437445.83 | L13: =K13 -> 437445.83 | ... O13: =N13 -> 437445.83 | P13: =SUM(D13:O13) -> 5249350 | Q13: =P13*(1+'[2]Assumption (Advisory)'!E$45)*(1+'[2]Assumption (Advisory)'!E$48) -> 7244103 | R13: =Q13*(1+'[2]Assumption (Advisory)'!F$45)*(1+'[2]Assumption (Advisory)'!F$48) -> 9996862.1 | S13: =R13*(1+'[2]Assumption (Advisory)'!G$45)*(1+'[2]Assumption (Advisory)'!G$48) -> 13795670 | T13: =S13*(1+'[2]Assumption (Advisory)'!H$45)*(1+'[2]Assumption (Advisory)'!H$48) -> 19038024
B14: Direct Cost - Sales Commission | D14: =VLOOKUP($B14,'Assumption (Corp Clinic)'!$B:$P,3,FALSE)/12 -> 218227.83 | E14: =D14 -> 218227.83 | F14: =E14 -> 218227.83 | G14: =F14 -> 218227.83 | H14: =G14 -> 218227.83 | I14: =H14 -> 218227.83 | J14: =I14 -> 218227.83 | K14: =J14 -> 218227.83 | L14: =K14 -> 218227.83 | ... O14: =N14 -> 218227.83 | P14: =SUM(D14:O14) -> 2618734 | Q14: =P14*(1+'[2]Assumption (Advisory)'!E$45)*(1+'[2]Assumption (Advisory)'!E$48) -> 3613852.9 | R14: =Q14*(1+'[2]Assumption (Advisory)'!F$45)*(1+'[2]Assumption (Advisory)'!F$48) -> 4987117.1 | S14: =R14*(1+'[2]Assumption (Advisory)'!G$45)*(1+'[2]Assumption (Advisory)'!G$48) -> 6882221.6 | T14: =S14*(1+'[2]Assumption (Advisory)'!H$45)*(1+'[2]Assumption (Advisory)'!H$48) -> 9497465.7
B15: Direct Cost - Overheads & Others | D15: =VLOOKUP($B15,'Assumption (Corp Clinic)'!$B:$P,3,FALSE)/12 -> 0 | E15: =D15 -> 0 | F15: =E15 -> 0 | G15: =F15 -> 0 | H15: =G15 -> 0 | I15: =H15 -> 0 | J15: =I15 -> 0 | K15: =J15 -> 0 | L15: =K15 -> 0 | ... O15: =N15 -> 0 | P15: =SUM(D15:O15) -> 0 | R15: =Q15*(1+'[2]Assumption (Advisory)'!F$45)*(1+'[2]Assumption (Advisory)'!F$48) -> 0 | S15: =R15*(1+'[2]Assumption (Advisory)'!G$45)*(1+'[2]Assumption (Advisory)'!G$48) -> 0 | T15: =S15*(1+'[2]Assumption (Advisory)'!H$45)*(1+'[2]Assumption (Advisory)'!H$48) -> 0
B17: Total Direct Cost | D17: =SUM(D12:D15) -> 8293647.9 | E17: =SUM(E12:E15) -> 8293647.9 | F17: =SUM(F12:F15) -> 8293647.9 | G17: =SUM(G12:G15) -> 8293647.9 | H17: =SUM(H12:H15) -> 8293647.9 | I17: =SUM(I12:I15) -> 8293647.9 | J17: =SUM(J12:J15) -> 8293647.9 | K17: =SUM(K12:K15) -> 8293647.9 | ... T17: =SUM(T12:T15) -> 28535490
B19: Gross Profit | D19: =D9-D17 -> 12354136 | E19: =E9-E17 -> 14704136 | F19: =F9-F17 -> 12354136 | G19: =G9-G17 -> 14704136 | H19: =H9-H17 -> 12354136 | I19: =I9-I17 -> 14704136 | J19: =J9-J17 -> 12354136 | K19: =K9-K17 -> 14704136 | ... T19: =T9-T17 -> 9.2121108e+08
B21: Operating expenses
B22: Indirect Staff Cost | D22: =VLOOKUP($B22,'Assumption (Corp Clinic)'!$B:$P,3,FALSE) -> 0 | E22: =D22 -> 0 | F22: =E22 -> 0 | G22: =F22 -> 0 | H22: =G22 -> 0 | I22: =H22 -> 0 | J22: =I22 -> 0 | K22: =J22 -> 0 | L22: =K22 -> 0 | ... O22: =N22 -> 0 | P22: =SUM(D22:O22) -> 0 | Q22: =P22*(1+'[2]Assumption (Advisory)'!E$55) -> 0 | R22: =Q22*(1+'[2]Assumption (Advisory)'!F$55) -> 0 | S22: =R22*(1+'[2]Assumption (Advisory)'!G$55) -> 0 | T22: =S22*(1+'[2]Assumption (Advisory)'!H$55) -> 0
B23: Repair & Maintenance | D23: =VLOOKUP($B23,'Assumption (Corp Clinic)'!$B:$P,3,FALSE) -> 0 | E23: =D23 -> 0 | F23: =E23 -> 0 | G23: =F23 -> 0 | H23: =G23 -> 0 | I23: =H23 -> 0 | J23: =I23 -> 0 | K23: =J23 -> 0 | L23: =K23 -> 0 | ... O23: =N23 -> 0 | P23: =SUM(D23:O23) -> 0 | Q23: =P23*(1+'[2]Assumption (Advisory)'!E$46) -> 0 | R23: =Q23*(1+'[2]Assumption (Advisory)'!F$46) -> 0 | S23: =R23*(1+'[2]Assumption (Advisory)'!G$46) -> 0 | T23: =S23*(1+'[2]Assumption (Advisory)'!H$46) -> 0
B24: Bank Charges | D24: =VLOOKUP($B24,'Assumption (Corp Clinic)'!$B:$P,3,FALSE) -> 21822.783 | E24: =D24 -> 21822.783 | F24: =E24 -> 21822.783 | G24: =F24 -> 21822.783 | H24: =G24 -> 21822.783 | I24: =H24 -> 21822.783 | J24: =I24 -> 21822.783 | K24: =J24 -> 21822.783 | L24: =K24 -> 21822.783 | ... O24: =N24 -> 21822.783 | P24: =SUM(D24:O24) -> 261873.4 | Q24: =P24*(1+'[2]Assumption (Advisory)'!E$46) -> 301154.41 | R24: =Q24*(1+'[2]Assumption (Advisory)'!F$46) -> 346327.57 | S24: =R24*(1+'[2]Assumption (Advisory)'!G$46) -> 398276.71 | T24: =S24*(1+'[2]Assumption (Advisory)'!H$46) -> 458018.22
B25: Advert, Printing & Stationery | D25: =VLOOKUP($B25,'Assumption (Corp Clinic)'!$B:$P,3,FALSE) -> 200000 | E25: =D25 -> 200000 | F25: =E25 -> 200000 | G25: =F25 -> 200000 | H25: =G25 -> 200000 | I25: =H25 -> 200000 | J25: =I25 -> 200000 | K25: =J25 -> 200000 | L25: =K25 -> 200000 | ... O25: =N25 -> 200000 | P25: =SUM(D25:O25) -> 2400000 | Q25: =P25*(1+'[2]Assumption (Advisory)'!E$46) -> 2760000 | R25: =Q25*(1+'[2]Assumption (Advisory)'!F$46) -> 3174000 | S25: =R25*(1+'[2]Assumption (Advisory)'!G$46) -> 3650100 | T25: =S25*(1+'[2]Assumption (Advisory)'!H$46) -> 4197615
B26: Rent | D26: =VLOOKUP($B26,'Assumption (Corp Clinic)'!$B:$P,3,FALSE) -> 0 | E26: =D26 -> 0 | F26: =E26 -> 0 | G26: =F26 -> 0 | H26: =G26 -> 0 | I26: =H26 -> 0 | J26: =I26 -> 0 | K26: =J26 -> 0 | L26: =K26 -> 0 | ... O26: =N26 -> 0 | P26: =SUM(D26:O26) -> 0 | Q26: =P26*(1+'[2]Assumption (Advisory)'!E$46) -> 0 | R26: =Q26*(1+'[2]Assumption (Advisory)'!F$46) -> 0 | S26: =R26*(1+'[2]Assumption (Advisory)'!G$46) -> 0 | T26: =S26*(1+'[2]Assumption (Advisory)'!H$46) -> 0
B27: Internet | D27: =VLOOKUP($B27,'Assumption (Corp Clinic)'!$B:$P,3,FALSE) -> 125000 | E27: =D27 -> 125000 | F27: =E27 -> 125000 | G27: =F27 -> 125000 | H27: =G27 -> 125000 | I27: =H27 -> 125000 | J27: =I27 -> 125000 | K27: =J27 -> 125000 | L27: =K27 -> 125000 | ... O27: =N27 -> 125000 | P27: =SUM(D27:O27) -> 1500000 | Q27: =P27*(1+'[2]Assumption (Advisory)'!E$46) -> 1725000 | R27: =Q27*(1+'[2]Assumption (Advisory)'!F$46) -> 1983750 | S27: =R27*(1+'[2]Assumption (Advisory)'!G$46) -> 2281312.5 | T27: =S27*(1+'[2]Assumption (Advisory)'!H$46) -> 2623509.4
B28: Cleaning Services | D28: =VLOOKUP($B28,'Assumption (Corp Clinic)'!$B:$P,3,FALSE) -> 0 | E28: =D28 -> 0 | F28: =E28 -> 0 | G28: =F28 -> 0 | H28: =G28 -> 0 | I28: =H28 -> 0 | J28: =I28 -> 0 | K28: =J28 -> 0 | L28: =K28 -> 0 | ... O28: =N28 -> 0 | P28: =SUM(D28:O28) -> 0 | Q28: =P28*(1+'[2]Assumption (Advisory)'!E$46) -> 0 | R28: =Q28*(1+'[2]Assumption (Advisory)'!F$46) -> 0 | S28: =R28*(1+'[2]Assumption (Advisory)'!G$46) -> 0 | T28: =S28*(1+'[2]Assumption (Advisory)'!H$46) -> 0
B29: Fuel - Car Pool | D29: =VLOOKUP($B29,'Assumption (Corp Clinic)'!$B:$P,3,FALSE) -> 0 | E29: =D29 -> 0 | F29: =E29 -> 0 | G29: =F29 -> 0 | H29: =G29 -> 0 | I29: =H29 -> 0 | J29: =I29 -> 0 | K29: =J29 -> 0 | L29: =K29 -> 0 | ... O29: =N29 -> 0 | P29: =SUM(D29:O29) -> 0 | Q29: =P29*(1+'[2]Assumption (Advisory)'!E$46) -> 0 | R29: =Q29*(1+'[2]Assumption (Advisory)'!F$46) -> 0 | S29: =R29*(1+'[2]Assumption (Advisory)'!G$46) -> 0 | T29: =S29*(1+'[2]Assumption (Advisory)'!H$46) -> 0
B30: Electricity | D30: =VLOOKUP($B30,'Assumption (Corp Clinic)'!$B:$P,3,FALSE) -> 0 | E30: =D30 -> 0 | F30: =E30 -> 0 | G30: =F30 -> 0 | H30: =G30 -> 0 | I30: =H30 -> 0 | J30: =I30 -> 0 | K30: =J30 -> 0 | L30: =K30 -> 0 | ... O30: =N30 -> 0 | P30: =SUM(D30:O30) -> 0 | Q30: =P30*(1+'[2]Assumption (Advisory)'!E$46) -> 0 | R30: =Q30*(1+'[2]Assumption (Advisory)'!F$46) -> 0 | S30: =R30*(1+'[2]Assumption (Advisory)'!G$46) -> 0 | T30: =S30*(1+'[2]Assumption (Advisory)'!H$46) -> 0
B31: Security | D31: =VLOOKUP($B31,'Assumption (Corp Clinic)'!$B:$P,3,FALSE) -> 0 | E31: =D31 -> 0 | F31: =E31 -> 0 | G31: =F31 -> 0 | H31: =G31 -> 0 | I31: =H31 -> 0 | J31: =I31 -> 0 | K31: =J31 -> 0 | L31: =K31 -> 0 | ... O31: =N31 -> 0 | P31: =SUM(D31:O31) -> 0 | Q31: =P31*(1+'[2]Assumption (Advisory)'!E$46) -> 0 | R31: =Q31*(1+'[2]Assumption (Advisory)'!F$46) -> 0 | S31: =R31*(1+'[2]Assumption (Advisory)'!G$46) -> 0 | T31: =S31*(1+'[2]Assumption (Advisory)'!H$46) -> 0
B32: Local Govt Levies & Charges | D32: =VLOOKUP($B32,'Assumption (Corp Clinic)'!$B:$P,3,FALSE) -> 200000 | E32: =D32 -> 200000 | F32: =E32 -> 200000 | G32: =F32 -> 200000 | H32: =G32 -> 200000 | I32: =H32 -> 200000 | J32: =I32 -> 200000 | K32: =J32 -> 200000 | L32: =K32 -> 200000 | ... O32: =N32 -> 200000 | P32: =SUM(D32:O32) -> 2400000 | Q32: =P32*(1+'[2]Assumption (Advisory)'!E$46) -> 2760000 | R32: =Q32*(1+'[2]Assumption (Advisory)'!F$46) -> 3174000 | S32: =R32*(1+'[2]Assumption (Advisory)'!G$46) -> 3650100 | T32: =S32*(1+'[2]Assumption (Advisory)'!H$46) -> 4197615
B33: Insurance Expenses | D33: =VLOOKUP($B33,'Assumption (Corp Clinic)'!$B:$P,3,FALSE) -> 120000 | E33: =D33 -> 120000 | F33: =E33 -> 120000 | G33: =F33 -> 120000 | H33: =G33 -> 120000 | I33: =H33 -> 120000 | J33: =I33 -> 120000 | K33: =J33 -> 120000 | L33: =K33 -> 120000 | ... O33: =N33 -> 120000 | P33: =SUM(D33:O33) -> 1440000 | Q33: =P33*(1+'[2]Assumption (Advisory)'!E$46) -> 1656000 | R33: =Q33*(1+'[2]Assumption (Advisory)'!F$46) -> 1904400 | S33: =R33*(1+'[2]Assumption (Advisory)'!G$46) -> 2190060 | T33: =S33*(1+'[2]Assumption (Advisory)'!H$46) -> 2518569
B34: Depreciation Expenses | D34: =VLOOKUP($B34,'Assumption (Corp Clinic)'!$B:$P,3,FALSE) -> 125000 | E34: =D34 -> 125000 | F34: =E34 -> 125000 | G34: =F34 -> 125000 | H34: =G34 -> 125000 | I34: =H34 -> 125000 | J34: =I34 -> 125000 | K34: =J34 -> 125000 | L34: =K34 -> 125000 | ... O34: =N34 -> 125000 | P34: =SUM(D34:O34) -> 1500000 | Q34: =P34*(1+'[2]Assumption (Advisory)'!E$46) -> 1725000 | R34: =Q34*(1+'[2]Assumption (Advisory)'!F$46) -> 1983750 | S34: =R34*(1+'[2]Assumption (Advisory)'!G$46) -> 2281312.5 | T34: =S34*(1+'[2]Assumption (Advisory)'!H$46) -> 2623509.4
B35: Contribution | D35: =VLOOKUP($B35,'Assumption (Corp Clinic)'!$B:$P,3,FALSE) -> 700000 | E35: =D35 -> 700000 | F35: =E35 -> 700000 | G35: =F35 -> 700000 | H35: =G35 -> 700000 | I35: =H35 -> 700000 | J35: =I35 -> 700000 | K35: =J35 -> 700000 | L35: =K35 -> 700000 | ... O35: =N35 -> 700000 | P35: =SUM(D35:O35) -> 8400000 | Q35: =P35*(1+'[2]Assumption (Advisory)'!E$46) -> 9660000 | R35: =Q35*(1+'[2]Assumption (Advisory)'!F$46) -> 11109000 | S35: =R35*(1+'[2]Assumption (Advisory)'!G$46) -> 12775350 | T35: =S35*(1+'[2]Assumption (Advisory)'!H$46) -> 14691652
B37: Total Opex | D37: =SUM(D22:D35) -> 1491822.8 | E37: =SUM(E22:E35) -> 1491822.8 | F37: =SUM(F22:F35) -> 1491822.8 | G37: =SUM(G22:G35) -> 1491822.8 | H37: =SUM(H22:H35) -> 1491822.8 | I37: =SUM(I22:I35) -> 1491822.8 | J37: =SUM(J22:J35) -> 1491822.8 | K37: =SUM(K22:K35) -> 1491822.8 | ... T37: =SUM(T22:T35) -> 31310488
B39: EBITDA | D39: =D19-D37 -> 10862313 | E39: =E19-E37 -> 13212313 | F39: =F19-F37 -> 10862313 | G39: =G19-G37 -> 13212313 | H39: =H19-H37 -> 10862313 | I39: =I19-I37 -> 13212313 | J39: =J19-J37 -> 10862313 | K39: =K19-K37 -> 13212313 | ... T39: =T19-T37 -> 8.899006e+08
B41: Depreciation Expenses | D41: =VLOOKUP($B41,'Assumption (Corp Clinic)'!$B:$P,3,FALSE) -> 125000 | E41: =D41 -> 125000 | F41: =E41 -> 125000 | G41: =F41 -> 125000 | H41: =G41 -> 125000 | I41: =H41 -> 125000 | J41: =I41 -> 125000 | K41: =J41 -> 125000 | L41: =K41 -> 125000 | ... O41: =N41 -> 125000 | P41: =SUM(D41:O41) -> 1500000 | Q41: =P41*(1+'[2]Assumption (Advisory)'!E$46) -> 1725000 | R41: =Q41*(1+'[2]Assumption (Advisory)'!F$46) -> 1983750 | S41: =R41*(1+'[2]Assumption (Advisory)'!G$46) -> 2281312.5 | T41: =S41*(1+'[2]Assumption (Advisory)'!H$46) -> 2623509.4
B43: Net Profit/(Loss) | D43: =D39-D41 -> 10737313 | E43: =E39-E41 -> 13087313 | F43: =F39-F41 -> 10737313 | G43: =G39-G41 -> 13087313 | H43: =H39-H41 -> 10737313 | I43: =I39-I41 -> 13087313 | J43: =J39-J41 -> 10737313 | K43: =K39-K41 -> 13087313 | ... T43: =T39-T41 -> 8.8727709e+08
B45: Accumulated EBITDA | D45: =D43 -> 10737313 | E45: =D45+E43 -> 23824626 | F45: =E45+F43 -> 34561938 | G45: =F45+G43 -> 47649251 | H45: =G45+H43 -> 58386564 | I45: =H45+I43 -> 71473877 | J45: =I45+J43 -> 82211190 | K45: =J45+K43 -> 95298503 | L45: =K45+L43 -> 1.0603582e+08 | ... O45: =N45+O43 -> 1.4294775e+08 | P45: =P43 -> 1.4294775e+08 | Q45: =P45+Q39 -> 4.7288794e+08 | R45: =Q45+R39 -> 9.3294044e+08 | S45: =R45+S39 -> 1.5732582e+09 | T45: =S45+T39 -> 2.4631588e+09
B47: Total Investment
B49: Pay back Balance | D49: =D45-D47 -> 10737313 | E49: =E45-E47 -> 23824626 | F49: =F45-F47 -> 34561938 | G49: =G45-G47 -> 47649251 | H49: =H45-H47 -> 58386564 | I49: =I45-I47 -> 71473877 | J49: =J45-J47 -> 82211190 | K49: =K45-K47 -> 95298503 | ... T49: =T45-T47 -> 2.4631588e+09
B51: Pay back Period | P51: =IF(P49>0,"1 Year"," ") -> 1 Year | Q51: =IF(Q49>0,"2 Year"," ") -> 2 Year | R51: =IF(R49>0,"3 Year"," ") -> 3 Year | S51: =IF(S49>0,"4 Year"," ") -> 4 Year | T51: =IF(T49>0,"5 Year"," ") -> 5 Year

Sheet Sheet1
B1: Medsupply | D1: MedFit | F1: MedClinic | H1: MedAvisory | J1: MedAssistance | L1: Travel Clinic | N1: MedProject
B2: ₦ | D2: ₦ | F2: ₦ | H2: ₦ | J2: ₦ | L2: ₦ | N2: ₦
A3: Revenue | B3: ='[3]Computations-(MedSupplies)'!$P$8 -> 1280000000 | D3: ='[4]Computations-(MedFit)'!$P$8 -> 1.1588628e+09 | F3: ='[5]Computations (MedClinic)'!$P$9 -> 2.5762134e+09 | H3: ='[5]Computations (Advisory)'!$P$9 -> 7.37e+08 | J3: ='[6]Computations-Outputs'!$P$11 -> 123285000 | L3: ='[7]Computations-(OH)'!$P$9 -> 127965000 | N3: ='[8]Computations-(MedFit)'!$P$8 -> 4.8233915e+08
A5: Cost of Sales | B5: =-'[3]Computations-(MedSupplies)'!$P$16 -> -697200000 | D5: =-'[4]Computations-(MedFit)'!$P$16 -> -5.7255422e+08 | F5: =-'[5]Computations (MedClinic)'!$P$17 -> -9.3268617e+08 | H5: =-'[5]Computations (Advisory)'!$P$17 -> -4.1247e+08 | J5: =-'[6]Computations-Outputs'!$P$19 -> -46848300 | L5: =-'[7]Computations-(OH)'!$P$17 -> -65973372 | N5: =-'[8]Computations-(MedFit)'!$P$16 -> 0
A6: COS on Revenue (%) | B6: =-IFERROR(B5/B3,0) -> 0.5446875 | D6: =-IFERROR(D5/D3,0) -> 0.4940656 | F6: =-IFERROR(F5/F3,0) -> 0.36203762 | H6: =-IFERROR(H5/H3,0) -> 0.55966079 | J6: =-IFERROR(J5/J3,0) -> 0.38 | L6: =-IFERROR(L5/L3,0) -> 0.51555794 | N6: =-IFERROR(N5/N3,0) -> 0
A8: Gross Profit | B8: =SUM(B3:B5) -> 582800000 | D8: =SUM(D3:D5) -> 5.8630854e+08 | F8: =SUM(F3:F5) -> 1.6435272e+09 | H8: =SUM(H3:H5) -> 324530000 | J8: =SUM(J3:J5) -> 76436700 | L8: =SUM(L3:L5) -> 61991628 | N8: =SUM(N3:N5) -> 4.8233915e+08
A9: Gross Margin (%) | B9: =IFERROR(B8/B3,0) -> 0.4553125 | D9: =IFERROR(D8/D3,0) -> 0.5059344 | F9: =IFERROR(F8/F3,0) -> 0.63796238 | H9: =IFERROR(H8/H3,0) -> 0.44033921 | J9: =IFERROR(J8/J3,0) -> 0.62 | L9: =IFERROR(L8/L3,0) -> 0.48444206 | N9: =IFERROR(N8/N3,0) -> 1
A11: Operational Expenses | B11: =-'[3]Computations-(MedSupplies)'!$P$37-'[3]Computations-(MedSupplies)'!$P$41 -> -48493254 | D11: =-'[4]Computations-(MedFit)'!$P$37-'[4]Computations-(MedFit)'!$P$41 -> -89750617 | F11: =-'[5]Computations (MedClinic)'!$P$39-'[5]Computations (MedClinic)'!$P$43 -> -2.8272297e+08 | H11: =-'[5]Computations (Advisory)'!$P$36-'[5]Computations (Advisory)'!$P$40 -> -15942400 | J11: =-'[6]Computations-Outputs'!$P$38-'[6]Computations-Outputs'!$P$42 -> -31556135 | L11: =-'[7]Computations-(OH)'!$P$35-'[7]Computations-(OH)'!$P$39 -> -7475332 | N11: =-'[8]Computations-(MedFit)'!$P$37-'[8]Computations-(MedFit)'!$P$41 -> 0
A12: Opex on Revenue (%) | B12: =-IFERROR(B11/B3,0) -> 0.037885355 | D12: =-IFERROR(D11/D3,0) -> 0.07744715 | F12: =-IFERROR(F11/F3,0) -> 0.10974361 | H12: =-IFERROR(H11/H3,0) -> 0.021631479 | J12: =-IFERROR(J11/J3,0) -> 0.25596086 | L12: =-IFERROR(L11/L3,0) -> 0.058417005 | N12: =-IFERROR(N11/N3,0) -> 0
A14: Net Profit | B14: =SUM(B8:B11) -> 5.3430675e+08 | D14: =SUM(D8:D11) -> 4.9655792e+08 | F14: =SUM(F8:F11) -> 1.3608043e+09 | H14: =SUM(H8:H11) -> 3.085876e+08 | J14: =SUM(J8:J11) -> 44880566 | L14: =SUM(L8:L11) -> 54516296 | N14: =SUM(N8:N11) -> 4.8233915e+08

Sheet Assumption (MedClinic-Oando)
B1: MedClinic
B2: Live_Case | D2: Jan | E2: Feb | F2: Mar | G2: Apr | H2: May | I2: Jun | J2: Jul | K2: Aug | L2: Sep | M2: Oct | N2: Nov | O2: Dec | P2: Total
B3: Medstaffing | D3: =SUM(D4:D5) -> 0 | E3: =SUM(E4:E5) -> 0 | F3: =SUM(F4:F5) -> 0 | G3: =SUM(G4:G5) -> 0 | H3: =SUM(H4:H5) -> 0 | I3: =SUM(I4:I5) -> 0 | J3: =SUM(J4:J5) -> 0 | K3: =SUM(K4:K5) -> 0 | ... P3: =SUM(P4:P5) -> 0
B4: Onshore Medical Doctor | D4: =D27*D47 -> 0 | E4: =E27*E47 -> 0 | F4: =F27*F47 -> 0 | G4: =G27*G47 -> 0 | H4: =H27*H47 -> 0 | I4: =I27*I47 -> 0 | J4: =J27*J47 -> 0 | K4: =K27*K47 -> 0 | ... O4: =O27*O47 -> 0 | P4: =SUM(D4:O4) -> 0
B5: Onshore Nurses | D5: =D28*D48 -> 0 | E5: =E28*E48 -> 0 | F5: =F28*F48 -> 0 | G5: =G28*G48 -> 0 | H5: =H28*H48 -> 0 | I5: =I28*I48 -> 0 | J5: =J28*J48 -> 0 | K5: =K28*K48 -> 0 | ... O5: =O28*O48 -> 0 | P5: =SUM(D5:O5) -> 0
B6: Onshore Pharm Technician | D6: =D29*D49 -> 0 | E6: =E29*E49 -> 0 | F6: =F29*F49 -> 0 | G6: =G29*G49 -> 0 | H6: =H29*H49 -> 0 | I6: =I29*I49 -> 0 | J6: =J29*J49 -> 0 | K6: =K29*K49 -> 0 | ... O6: =O29*O49 -> 0 | P6: =SUM(D6:O6) -> 0
B7: Onshore Pharmacist | D7: =D30*D50 -> 0 | E7: =E30*E50 -> 0 | F7: =F30*F50 -> 0 | G7: =G30*G50 -> 0 | H7: =H30*H50 -> 0 | I7: =I30*I50 -> 0 | J7: =J30*J50 -> 0 | K7: =K30*K50 -> 0 | ... O7: =O30*O50 -> 0 | P7: =SUM(D7:O7) -> 0
B8: Offshore Medical Doctor | D8: =D31*D51 -> 0 | E8: =E31*E51 -> 0 | F8: =F31*F51 -> 0 | G8: =G31*G51 -> 0 | H8: =H31*H51 -> 0 | I8: =I31*I51 -> 0 | J8: =J31*J51 -> 0 | K8: =K31*K51 -> 0 | ... O8: =O31*O51 -> 0 | P8: =SUM(D8:O8) -> 0
B9: Offshore Nurses | D9: =D32*D52 -> 0 | E9: =E32*E52 -> 0 | F9: =F32*F52 -> 0 | G9: =G32*G52 -> 0 | H9: =H32*H52 -> 0 | I9: =I32*I52 -> 0 | J9: =J32*J52 -> 0 | K9: =K32*K52 -> 0 | ... O9: =O32*O52 -> 0 | P9: =SUM(D9:O9) -> 0
B10: Offshore Pharm Technician | D10: =D33*D53 -> 0 | E10: =E33*E53 -> 0 | F10: =F33*F53 -> 0 | G10: =G33*G53 -> 0 | H10: =H33*H53 -> 0 | I10: =I33*I53 -> 0 | J10: =J33*J53 -> 0 | K10: =K33*K53 -> 0 | ... O10: =O33*O53 -> 0 | P10: =SUM(D10:O10) -> 0
B11: Offshore Pharm acist | D11: =D34*D54 -> 0 | E11: =E34*E54 -> 0 | F11: =F34*F54 -> 0 | G11: =G34*G54 -> 0 | H11: =H34*H54 -> 0 | I11: =I34*I54 -> 0 | J11: =J34*J54 -> 0 | K11: =K34*K54 -> 0 | ... O11: =O34*O54 -> 0 | P11: =SUM(D11:O11) -> 0
B14: Outsourced Corporate Clinics | D14: =SUM(D15:D21) -> 1.9916667e+08 | E14: =SUM(E15:E21) -> 1.9916667e+08 | F14: =SUM(F15:F21) -> 1.9916667e+08 | G14: =SUM(G15:G21) -> 1.9916667e+08 | H14: =SUM(H15:H21) -> 1.9916667e+08 | I14: =SUM(I15:I21) -> 1.9916667e+08 | J14: =SUM(J15:J21) -> 1.9916667e+08 | K14: =SUM(K15:K21) -> 1.9916667e+08 | ... P14: =SUM(P15:P21) -> 2.39e+09
B15: APM Terminals | D15: =D37*D57 -> 0 | E15: =D15 -> 0 | F15: =E15 -> 0 | G15: =F15 -> 0 | H15: =G15 -> 0 | I15: =H15 -> 0 | J15: =I15 -> 0 | K15: =J15 -> 0 | L15: =K15 -> 0 | ... O15: =N15 -> 0 | P15: =SUM(D15:O15) -> 0 | Q15: Clinic Outsourcing
B16: Guiness Plc | D16: =D38*D58 -> 0 | E16: =E38*E58 -> 0 | F16: =F38*F58 -> 0 | G16: =G38*G58 -> 0 | H16: =H38*H58 -> 0 | I16: =I38*I58 -> 0 | J16: =J38*J58 -> 0 | K16: =K38*K58 -> 0 | ... O16: =O38*O58 -> 0 | P16: =SUM(D16:O16) -> 0 | Q16: Clinic Outsourcing
B17: Pipe Coaters Tenaris | D17: =D39*D59 -> 0 | E17: =E39*E59 -> 0 | F17: =F39*F59 -> 0 | G17: =G39*G59 -> 0 | H17: =H39*H59 -> 0 | I17: =I39*I59 -> 0 | J17: =J39*J59 -> 0 | K17: =K39*K59 -> 0 | ... O17: =O39*O59 -> 0 | P17: =SUM(D17:O17) -> 0 | Q17: Clinic Outsourcing
B18: BATN | D18: =(D40*D60) -> 0 | E18: =D18 -> 0 | F18: =E18 -> 0 | G18: =F18 -> 0 | H18: =G18 -> 0 | I18: =H18 -> 0 | J18: =I18 -> 0 | K18: =J18 -> 0 | L18: =K18 -> 0 | ... O18: =N18 -> 0 | P18: =SUM(D18:O18) -> 0 | Q18: Quarterly Clinic outsourcing
B19: Shell IA | D19: =(D41*D61) -> 0 | E19: =D19 -> 0 | F19: =E19 -> 0 | G19: =F19 -> 0 | H19: =G19 -> 0 | I19: =H19 -> 0 | J19: =I19 -> 0 | K19: =J19 -> 0 | L19: =K19 -> 0 | ... O19: =N19 -> 0 | P19: =SUM(D19:O19) -> 0
B20: Oando | D20: =(D42*D62) -> 1.9616667e+08 | E20: =D20 -> 1.9616667e+08 | F20: =E20 -> 1.9616667e+08 | G20: =F20 -> 1.9616667e+08 | H20: =G20 -> 1.9616667e+08 | I20: =H20 -> 1.9616667e+08 | J20: =I20 -> 1.9616667e+08 | K20: =J20 -> 1.9616667e+08 | L20: =K20 -> 1.9616667e+08 | ... O20: =N20 -> 1.9616667e+08 | P20: =SUM(D20:O20) -> 2.354e+09
B21: Others | D21: 3000000 | E21: =D21 -> 3000000 | F21: =E21 -> 3000000 | G21: =F21 -> 3000000 | H21: =G21 -> 3000000 | I21: =H21 -> 3000000 | J21: =I21 -> 3000000 | K21: =J21 -> 3000000 | L21: =K21 -> 3000000 | ... O21: =N21 -> 3000000 | P21: =SUM(D21:O21) -> 36000000
B23: Total Revenue | D23: =D3+D14 -> 1.9916667e+08 | E23: =E3+E14 -> 1.9916667e+08 | F23: =F3+F14 -> 1.9916667e+08 | G23: =G3+G14 -> 1.9916667e+08 | H23: =H3+H14 -> 1.9916667e+08 | I23: =I3+I14 -> 1.9916667e+08 | J23: =J3+J14 -> 1.9916667e+08 | K23: =K3+K14 -> 1.9916667e+08 | ... P23: =P3+P14 -> 2.39e+09
B25: Average no Staff
B26: Medstaffing | D26: =SUM(D27:D34) -> 0 | E26: =SUM(E27:E34) -> 0 | F26: =SUM(F27:F34) -> 0 | G26: =SUM(G27:G34) -> 0 | H26: =SUM(H27:H34) -> 0 | I26: =SUM(I27:I34) -> 0 | J26: =SUM(J27:J34) -> 0 | K26: =SUM(K27:K34) -> 0 | ... P26: =SUM(P27:P34) -> 0
B27: Onshore Medical Doctor | P27: =SUM(D27:O27) -> 0
B28: Onshore Nurses | P28: =SUM(D28:O28) -> 0
B29: Onshore Pharm Technician | P29: =SUM(D29:O29) -> 0
B30: Onshore Pharmacist | P30: =SUM(D30:O30) -> 0
B31: Offshore Medical Doctor | P31: =SUM(D31:O31) -> 0
B32: Offshore Nurses | P32: =SUM(D32:O32) -> 0
B33: Offshore Pharm Technician | P33: =SUM(D33:O33) -> 0
B34: Offshore Pharmacist | P34: =SUM(D34:O34) -> 0
B36: Outsourced Corporate Clinics | D36: =SUM(D37:D40) -> 0 | E36: =SUM(E37:E40) -> 0 | F36: =SUM(F37:F40) -> 0 | G36: =SUM(G37:G40) -> 0 | H36: =SUM(H37:H40) -> 0 | I36: =SUM(I37:I40) -> 0 | J36: =SUM(J37:J40) -> 0 | K36: =SUM(K37:K40) -> 0 | ... P36: =SUM(P37:P40) -> 0
B37: APM Terminals | P37: =SUM(D37:O37) -> 0 | Q37: Per negotiated contract
B38: Guiness Plc | P38: =SUM(D38:O38) -> 0 | Q38: Per negotiated contract
B39: Pipe Coaters | P39: =SUM(D39:O39) -> 0 | Q39: Per negotiated contract
B40: BATN | P40: =SUM(D40:O40) -> 0 | Q40: Per negotiated contract
B41: Shell IA | P41: =SUM(D41:O41) -> 0
B42: Oando | D42: 2200 | E42: 2200 | F42: 2200 | G42: 2200 | H42: 2200 | I42: 2200 | J42: 2200 | K42: 2200 | L42: 2200 | M42: 2200 | N42: 2200 | O42: 2200 | P42: =SUM(D42:O42) -> 26400
B43: Others | P43: =SUM(D43:O43) -> 0
B45: Average case - Price
B46: Medstaffing
...

Sheet Computations (MedClinic-Oando)
B2: Computations-Outputs
D3: Jan | E3: Feb | F3: Mar | G3: Apr | H3: May | I3: Jun | J3: Jul | K3: Aug | L3: Sep | M3: Oct | N3: Nov | O3: Dec | P3: FY 1 | Q3: FY 2 | R3: FY 3 | S3: FY 4 | T3: FY 5
D4: ₦ | E4: ₦ | F4: ₦ | G4: ₦ | H4: ₦ | I4: ₦ | J4: ₦ | K4: ₦ | L4: ₦ | M4: ₦ | N4: ₦ | O4: ₦ | P4: NGN | Q4: NGN | R4: NGN | S4: NGN | T4: NGN
B5: Revenue
B6: Medstaffing | D6: =VLOOKUP($B6,'Assumption (MedClinic-Oando)'!$B:$P,3,FALSE) -> 0 | E6: =VLOOKUP($B6,'Assumption (MedClinic-Oando)'!$B:$P,4,FALSE) -> 0 | F6: =VLOOKUP($B6,'Assumption (MedClinic-Oando)'!$B:$P,5,FALSE) -> 0 | G6: =VLOOKUP($B6,'Assumption (MedClinic-Oando)'!$B:$P,6,FALSE) -> 0 | H6: =VLOOKUP($B6,'Assumption (MedClinic-Oando)'!$B:$P,7,FALSE) -> 0 | I6: =VLOOKUP($B6,'Assumption (MedClinic-Oando)'!$B:$P,8,FALSE) -> 0 | J6: =VLOOKUP($B6,'Assumption (MedClinic-Oando)'!$B:$P,9,FALSE) -> 0 | K6: =VLOOKUP($B6,'Assumption (MedClinic-Oando)'!$B:$P,10,FALSE) -> 0 | L6: =VLOOKUP($B6,'Assumption (MedClinic-Oando)'!$B:$P,11,FALSE) -> 0 | M6: =VLOOKUP($B6,'Assumption (MedClinic-Oando)'!$B:$P,12,FALSE) -> 0 | N6: =VLOOKUP($B6,'Assumption (MedClinic-Oando)'!$B:$P,13,FALSE) -> 0 | O6: =VLOOKUP($B6,'Assumption (MedClinic-Oando)'!$B:$P,14,FALSE) -> 0 | P6: =SUM(D6:O6) -> 0 | Q6: =P6*(1+'[2]Assumption (Advisory)'!E$45)*(1+'[2]Assumption (Advisory)'!E$48) -> 0 | R6: =Q6*(1+'[2]Assumption (Advisory)'!F$45)*(1+'[2]Assumption (Advisory)'!F$48) -> 0 | S6: =R6*(1+'[2]Assumption (Advisory)'!G$45)*(1+'[2]Assumption (Advisory)'!G$48) -> 0 | T6: =S6*(1+'[2]Assumption (Advisory)'!H$45)*(1+'[2]Assumption (Advisory)'!H$48) -> 0
B7: Outsourced Corporate Clinics | D7: =VLOOKUP($B7,'Assumption (MedClinic-Oando)'!$B:$P,3,FALSE) -> 1.9916667e+08 | E7: =VLOOKUP($B7,'Assumption (MedClinic-Oando)'!$B:$P,4,FALSE) -> 1.9916667e+08 | F7: =VLOOKUP($B7,'Assumption (MedClinic-Oando)'!$B:$P,5,FALSE) -> 1.9916667e+08 | G7: =VLOOKUP($B7,'Assumption (MedClinic-Oando)'!$B:$P,6,FALSE) -> 1.9916667e+08 | H7: =VLOOKUP($B7,'Assumption (MedClinic-Oando)'!$B:$P,7,FALSE) -> 1.9916667e+08 | I7: =VLOOKUP($B7,'Assumption (MedClinic-Oando)'!$B:$P,8,FALSE) -> 1.9916667e+08 | J7: =VLOOKUP($B7,'Assumption (MedClinic-Oando)'!$B:$P,9,FALSE) -> 1.9916667e+08 | K7: =VLOOKUP($B7,'Assumption (MedClinic-Oando)'!$B:$P,10,FALSE) -> 1.9916667e+08 | L7: =VLOOKUP($B7,'Assumption (MedClinic-Oando)'!$B:$P,11,FALSE) -> 1.9916667e+08 | M7: =VLOOKUP($B7,'Assumption (MedClinic-Oando)'!$B:$P,12,FALSE) -> 1.9916667e+08 | N7: =VLOOKUP($B7,'Assumption (MedClinic-Oando)'!$B:$P,13,FALSE) -> 1.9916667e+08 | O7: =VLOOKUP($B7,'Assumption (MedClinic-Oando)'!$B:$P,14,FALSE) -> 1.9916667e+08 | P7: =SUM(D7:O7) -> 2.39e+09 | Q7: =P7*(1+'[2]Assumption (Advisory)'!E$45)*(1+'[2]Assumption (Advisory)'!E$48) -> 3.2982e+09 | R7: =Q7*(1+'[2]Assumption (Advisory)'!F$45)*(1+'[2]Assumption (Advisory)'!F$48) -> 4551516000 | S7: =R7*(1+'[2]Assumption (Advisory)'!G$45)*(1+'[2]Assumption (Advisory)'!G$48) -> 6281092080 | T7: =S7*(1+'[2]Assumption (Advisory)'!H$45)*(1+'[2]Assumption (Advisory)'!H$48) -> 8.6679071e+09
B9: Total Revenue | D9: =SUM(D6:D7) -> 1.9916667e+08 | E9: =SUM(E6:E7) -> 1.9916667e+08 | F9: =SUM(F6:F7) -> 1.9916667e+08 | G9: =SUM(G6:G7) -> 1.9916667e+08 | H9: =SUM(H6:H7) -> 1.9916667e+08 | I9: =SUM(I6:I7) -> 1.9916667e+08 | J9: =SUM(J6:J7) -> 1.9916667e+08 | K9: =SUM(K6:K7) -> 1.9916667e+08 | ... T9: =SUM(T6:T7) -> 8.6679071e+09
B11: Cost of Revenue
B12: Direct Cost - Consumables | D12: =VLOOKUP($B12,'Assumption (MedClinic-Oando)'!$B:$P,3,FALSE) -> 19916667 | E12: =D12 -> 19916667 | F12: =E12 -> 19916667 | G12: =F12 -> 19916667 | H12: =G12 -> 19916667 | I12: =H12 -> 19916667 | J12: =I12 -> 19916667 | K12: =J12 -> 19916667 | L12: =K12 -> 19916667 | ... O12: =N12 -> 19916667 | P12: =SUM(D12:O12) -> 2.39e+08
B13: Direct Cost - Staff | D13: =VLOOKUP($B13,'Assumption (MedClinic-Oando)'!$B:$P,3,FALSE) -> 5249350 | E13: =D13 -> 5249350 | F13: =E13 -> 5249350 | G13: =F13 -> 5249350 | H13: =G13 -> 5249350 | I13: =H13 -> 5249350 | J13: =I13 -> 5249350 | K13: =J13 -> 5249350 | L13: =K13 -> 5249350 | ... O13: =N13 -> 5249350 | P13: =SUM(D13:O13) -> 62992200 | Q13: =P13*(1+'[2]Assumption (Advisory)'!E$45)*(1+'[2]Assumption (Advisory)'!E$48) -> 86929236 | R13: =Q13*(1+'[2]Assumption (Advisory)'!F$45)*(1+'[2]Assumption (Advisory)'!F$48) -> 1.1996235e+08 | S13: =R13*(1+'[2]Assumption (Advisory)'!G$45)*(1+'[2]Assumption (Advisory)'!G$48) -> 1.6554804e+08 | T13: =S13*(1+'[2]Assumption (Advisory)'!H$45)*(1+'[2]Assumption (Advisory)'!H$48) -> 2.2845629e+08
B14: Direct Cost - Sales Commission | D14: =VLOOKUP($B14,'Assumption (MedClinic-Oando)'!$B:$P,3,FALSE) -> 1991666.7 | E14: =D14 -> 1991666.7 | F14: =E14 -> 1991666.7 | G14: =F14 -> 1991666.7 | H14: =G14 -> 1991666.7 | I14: =H14 -> 1991666.7 | J14: =I14 -> 1991666.7 | K14: =J14 -> 1991666.7 | L14: =K14 -> 1991666.7 | ... O14: =N14 -> 1991666.7 | P14: =SUM(D14:O14) -> 23900000 | Q14: =P14*(1+'[2]Assumption (Advisory)'!E$45)*(1+'[2]Assumption (Advisory)'!E$48) -> 32982000 | R14: =Q14*(1+'[2]Assumption (Advisory)'!F$45)*(1+'[2]Assumption (Advisory)'!F$48) -> 45515160 | S14: =R14*(1+'[2]Assumption (Advisory)'!G$45)*(1+'[2]Assumption (Advisory)'!G$48) -> 62810921 | T14: =S14*(1+'[2]Assumption (Advisory)'!H$45)*(1+'[2]Assumption (Advisory)'!H$48) -> 86679071
B15: Direct Cost - Overheads & Others | D15: =VLOOKUP($B15,'Assumption (MedClinic-Oando)'!$B:$P,3,FALSE) -> 49791667 | E15: =D15 -> 49791667 | F15: =E15 -> 49791667 | G15: =F15 -> 49791667 | H15: =G15 -> 49791667 | I15: =H15 -> 49791667 | J15: =I15 -> 49791667 | K15: =J15 -> 49791667 | L15: =K15 -> 49791667 | ... O15: =N15 -> 49791667 | P15: =SUM(D15:O15) -> 5.975e+08 | R15: =Q15*(1+'[2]Assumption (Advisory)'!F$45)*(1+'[2]Assumption (Advisory)'!F$48) -> 0 | S15: =R15*(1+'[2]Assumption (Advisory)'!G$45)*(1+'[2]Assumption (Advisory)'!G$48) -> 0 | T15: =S15*(1+'[2]Assumption (Advisory)'!H$45)*(1+'[2]Assumption (Advisory)'!H$48) -> 0
B17: Total Direct Cost | D17: =SUM(D12:D15) -> 76949350 | E17: =SUM(E12:E15) -> 76949350 | F17: =SUM(F12:F15) -> 76949350 | G17: =SUM(G12:G15) -> 76949350 | H17: =SUM(H12:H15) -> 76949350 | I17: =SUM(I12:I15) -> 76949350 | J17: =SUM(J12:J15) -> 76949350 | K17: =SUM(K12:K15) -> 76949350 | ... T17: =SUM(T12:T15) -> 3.1513536e+08
B19: Gross Profit | D19: =D9-D17 -> 1.2221732e+08 | E19: =E9-E17 -> 1.2221732e+08 | F19: =F9-F17 -> 1.2221732e+08 | G19: =G9-G17 -> 1.2221732e+08 | H19: =H9-H17 -> 1.2221732e+08 | I19: =I9-I17 -> 1.2221732e+08 | J19: =J9-J17 -> 1.2221732e+08 | K19: =K9-K17 -> 1.2221732e+08 | ... T19: =T9-T17 -> 8.3527717e+09
B21: Operating expenses
B22: Indirect Staff Cost | D22: =IFERROR(VLOOKUP($B22,'Assumption (MedClinic-Oando)'!$B:$P,3,FALSE),0) -> 39833333 | E22: =IFERROR(VLOOKUP($B22,'Assumption (MedClinic-Oando)'!$B:$P,3,FALSE),0) -> 39833333 | F22: =IFERROR(VLOOKUP($B22,'Assumption (MedClinic-Oando)'!$B:$P,3,FALSE),0) -> 39833333 | G22: =IFERROR(VLOOKUP($B22,'Assumption (MedClinic-Oando)'!$B:$P,3,FALSE),0) -> 39833333 | H22: =IFERROR(VLOOKUP($B22,'Assumption (MedClinic-Oando)'!$B:$P,3,FALSE),0) -> 39833333 | I22: =IFERROR(VLOOKUP($B22,'Assumption (MedClinic-Oando)'!$B:$P,3,FALSE),0) -> 39833333 | J22: =IFERROR(VLOOKUP($B22,'Assumption (MedClinic-Oando)'!$B:$P,3,FALSE),0) -> 39833333 | K22: =IFERROR(VLOOKUP($B22,'Assumption (MedClinic-Oando)'!$B:$P,3,FALSE),0) -> 39833333 | ... O22: =IFERROR(VLOOKUP($B22,'Assumption (MedClinic-Oando)'!$B:$P,3,FALSE),0) -> 39833333 | P22: =SUM(D22:O22) -> 4.78e+08 | Q22: =P22*(1+'[2]Assumption (Advisory)'!E$55) -> 5.258e+08 | R22: =Q22*(1+'[2]Assumption (Advisory)'!F$55) -> 5.7838e+08 | S22: =R22*(1+'[2]Assumption (Advisory)'!G$55) -> 6.36218e+08 | T22: =S22*(1+'[2]Assumption (Advisory)'!H$55) -> 6.998398e+08
B23: Repair & Maintenance | D23: =IFERROR(VLOOKUP($B23,'Assumption (MedClinic-Oando)'!$B:$P,3,FALSE),0) -> 1991666.7 | E23: =IFERROR(VLOOKUP($B23,'Assumption (MedClinic-Oando)'!$B:$P,3,FALSE),0) -> 1991666.7 | F23: =IFERROR(VLOOKUP($B23,'Assumption (MedClinic-Oando)'!$B:$P,3,FALSE),0) -> 1991666.7 | G23: =IFERROR(VLOOKUP($B23,'Assumption (MedClinic-Oando)'!$B:$P,3,FALSE),0) -> 1991666.7 | H23: =IFERROR(VLOOKUP($B23,'Assumption (MedClinic-Oando)'!$B:$P,3,FALSE),0) -> 1991666.7 | I23: =IFERROR(VLOOKUP($B23,'Assumption (MedClinic-Oando)'!$B:$P,3,FALSE),0) -> 1991666.7 | J23: =IFERROR(VLOOKUP($B23,'Assumption (MedClinic-Oando)'!$B:$P,3,FALSE),0) -> 1991666.7 | K23: =IFERROR(VLOOKUP($B23,'Assumption (MedClinic-Oando)'!$B:$P,3,FALSE),0) -> 1991666.7 | ... O23: =IFERROR(VLOOKUP($B23,'Assumption (MedClinic-Oando)'!$B:$P,3,FALSE),0) -> 1991666.7 | P23: =SUM(D23:O23) -> 23900000 | Q23: =P23*(1+'[2]Assumption (Advisory)'!E$46) -> 27485000 | R23: =Q23*(1+'[2]Assumption (Advisory)'!F$46) -> 31607750 | S23: =R23*(1+'[2]Assumption (Advisory)'!G$46) -> 36348913 | T23: =S23*(1+'[2]Assumption (Advisory)'!H$46) -> 41801249
B24: Bank Charges | D24: =IFERROR(VLOOKUP($B24,'Assumption (MedClinic-Oando)'!$B:$P,3,FALSE),0) -> 19916.667 | E24: =IFERROR(VLOOKUP($B24,'Assumption (MedClinic-Oando)'!$B:$P,3,FALSE),0) -> 19916.667 | F24: =IFERROR(VLOOKUP($B24,'Assumption (MedClinic-Oando)'!$B:$P,3,FALSE),0) -> 19916.667 | G24: =IFERROR(VLOOKUP($B24,'Assumption (MedClinic-Oando)'!$B:$P,3,FALSE),0) -> 19916.667 | H24: =IFERROR(VLOOKUP($B24,'Assumption (MedClinic-Oando)'!$B:$P,3,FALSE),0) -> 19916.667 | I24: =IFERROR(VLOOKUP($B24,'Assumption (MedClinic-Oando)'!$B:$P,3,FALSE),0) -> 19916.667 | J24: =IFERROR(VLOOKUP($B24,'Assumption (MedClinic-Oando)'!$B:$P,3,FALSE),0) -> 19916.667 | K24: =IFERROR(VLOOKUP($B24,'Assumption (MedClinic-Oando)'!$B:$P,3,FALSE),0) -> 19916.667 | ... O24: =IFERROR(VLOOKUP($B24,'Assumption (MedClinic-Oando)'!$B:$P,3,FALSE),0) -> 19916.667 | P24: =SUM(D24:O24) -> 239000 | Q24: =P24*(1+'[2]Assumption (Advisory)'!E$46) -> 274850 | R24: =Q24*(1+'[2]Assumption (Advisory)'!F$46) -> 316077.5 | S24: =R24*(1+'[2]Assumption (Advisory)'!G$46) -> 363489.13 | T24: =S24*(1+'[2]Assumption (Advisory)'!H$46) -> 418012.49
B25: Advert, Printing & Stationery | D25: =IFERROR(VLOOKUP($B25,'Assumption (MedClinic-Oando)'!$B:$P,3,FALSE),0) -> 200000 | E25: =IFERROR(VLOOKUP($B25,'Assumption (MedClinic-Oando)'!$B:$P,3,FALSE),0) -> 200000 | F25: =IFERROR(VLOOKUP($B25,'Assumption (MedClinic-Oando)'!$B:$P,3,FALSE),0) -> 200000 | G25: =IFERROR(VLOOKUP($B25,'Assumption (MedClinic-Oando)'!$B:$P,3,FALSE),0) -> 200000 | H25: =IFERROR(VLOOKUP($B25,'Assumption (MedClinic-Oando)'!$B:$P,3,FALSE),0) -> 200000 | I25: =IFERROR(VLOOKUP($B25,'Assumption (MedClinic-Oando)'!$B:$P,3,FALSE),0) -> 200000 | J25: =IFERROR(VLOOKUP($B25,'Assumption (MedClinic-Oando)'!$B:$P,3,FALSE),0) -> 200000 | K25: =IFERROR(VLOOKUP($B25,'Assumption (MedClinic-Oando)'!$B:$P,3,FALSE),0) -> 200000 | ... O25: =IFERROR(VLOOKUP($B25,'Assumption (MedClinic-Oando)'!$B:$P,3,FALSE),0) -> 200000 | P25: =SUM(D25:O25) -> 2400000 | Q25: =P25*(1+'[2]Assumption (Advisory)'!E$46) -> 2760000 | R25: =Q25*(1+'[2]Assumption (Advisory)'!F$46) -> 3174000 | S25: =R25*(1+'[2]Assumption (Advisory)'!G$46) -> 3650100 | T25: =S25*(1+'[2]Assumption (Advisory)'!H$46) -> 4197615
B26: Rent | D26: =IFERROR(VLOOKUP($B26,'Assumption (MedClinic-Oando)'!$B:$P,3,FALSE),0) -> 0 | E26: =IFERROR(VLOOKUP($B26,'Assumption (MedClinic-Oando)'!$B:$P,3,FALSE),0) -> 0 | F26: =IFERROR(VLOOKUP($B26,'Assumption (MedClinic-Oando)'!$B:$P,3,FALSE),0) -> 0 | G26: =IFERROR(VLOOKUP($B26,'Assumption (MedClinic-Oando)'!$B:$P,3,FALSE),0) -> 0 | H26: =IFERROR(VLOOKUP($B26,'Assumption (MedClinic-Oando)'!$B:$P,3,FALSE),0) -> 0 | I26: =IFERROR(VLOOKUP($B26,'Assumption (MedClinic-Oando)'!$B:$P,3,FALSE),0) -> 0 | J26: =IFERROR(VLOOKUP($B26,'Assumption (MedClinic-Oando)'!$B:$P,3,FALSE),0) -> 0 | K26: =IFERROR(VLOOKUP($B26,'Assumption (MedClinic-Oando)'!$B:$P,3,FALSE),0) -> 0 | ... O26: =IFERROR(VLOOKUP($B26,'Assumption (MedClinic-Oando)'!$B:$P,3,FALSE),0) -> 0 | P26: =SUM(D26:O26) -> 0 | Q26: =P26*(1+'[2]Assumption (Advisory)'!E$46) -> 0 | R26: =Q26*(1+'[2]Assumption (Advisory)'!F$46) -> 0 | S26: =R26*(1+'[2]Assumption (Advisory)'!G$46) -> 0 | T26: =S26*(1+'[2]Assumption (Advisory)'!H$46) -> 0
B27: Internet | D27: =IFERROR(VLOOKUP($B27,'Assumption (MedClinic-Oando)'!$B:$P,3,FALSE),0) -> 350000 | E27: =IFERROR(VLOOKUP($B27,'Assumption (MedClinic-Oando)'!$B:$P,3,FALSE),0) -> 350000 | F27: =IFERROR(VLOOKUP($B27,'Assumption (MedClinic-Oando)'!$B:$P,3,FALSE),0) -> 350000 | G27: =IFERROR(VLOOKUP($B27,'Assumption (MedClinic-Oando)'!$B:$P,3,FALSE),0) -> 350000 | H27: =IFERROR(VLOOKUP($B27,'Assumption (MedClinic-Oando)'!$B:$P,3,FALSE),0) -> 350000 | I27: =IFERROR(VLOOKUP($B27,'Assumption (MedClinic-Oando)'!$B:$P,3,FALSE),0) -> 350000 | J27: =IFERROR(VLOOKUP($B27,'Assumption (MedClinic-Oando)'!$B:$P,3,FALSE),0) -> 350000 | K27: =IFERROR(VLOOKUP($B27,'Assumption (MedClinic-Oando)'!$B:$P,3,FALSE),0) -> 350000 | ... O27: =IFERROR(VLOOKUP($B27,'Assumption (MedClinic-Oando)'!$B:$P,3,FALSE),0) -> 350000 | P27: =SUM(D27:O27) -> 4200000 | Q27: =P27*(1+'[2]Assumption (Advisory)'!E$46) -> 4830000 | R27: =Q27*(1+'[2]Assumption (Advisory)'!F$46) -> 5554500 | S27: =R27*(1+'[2]Assumption (Advisory)'!G$46) -> 6387675 | T27: =S27*(1+'[2]Assumption (Advisory)'!H$46) -> 7345826.2
B28: Cleaning Services | D28: =IFERROR(VLOOKUP($B28,'Assumption (MedClinic-Oando)'!$B:$P,3,FALSE),0) -> 0 | E28: =IFERROR(VLOOKUP($B28,'Assumption (MedClinic-Oando)'!$B:$P,3,FALSE),0) -> 0 | F28: =IFERROR(VLOOKUP($B28,'Assumption (MedClinic-Oando)'!$B:$P,3,FALSE),0) -> 0 | G28: =IFERROR(VLOOKUP($B28,'Assumption (MedClinic-Oando)'!$B:$P,3,FALSE),0) -> 0 | H28: =IFERROR(VLOOKUP($B28,'Assumption (MedClinic-Oando)'!$B:$P,3,FALSE),0) -> 0 | I28: =IFERROR(VLOOKUP($B28,'Assumption (MedClinic-Oando)'!$B:$P,3,FALSE),0) -> 0 | J28: =IFERROR(VLOOKUP($B28,'Assumption (MedClinic-Oando)'!$B:$P,3,FALSE),0) -> 0 | K28: =IFERROR(VLOOKUP($B28,'Assumption (MedClinic-Oando)'!$B:$P,3,FALSE),0) -> 0 | ... O28: =IFERROR(VLOOKUP($B28,'Assumption (MedClinic-Oando)'!$B:$P,3,FALSE),0) -> 0 | P28: =SUM(D28:O28) -> 0 | Q28: =P28*(1+'[2]Assumption (Advisory)'!E$46) -> 0 | R28: =Q28*(1+'[2]Assumption (Advisory)'!F$46) -> 0 | S28: =R28*(1+'[2]Assumption (Advisory)'!G$46) -> 0 | T28: =S28*(1+'[2]Assumption (Advisory)'!H$46) -> 0
B29: Fuel - Car Pool | D29: =IFERROR(VLOOKUP($B29,'Assumption (MedClinic-Oando)'!$B:$P,3,FALSE),0) -> 0 | E29: =IFERROR(VLOOKUP($B29,'Assumption (MedClinic-Oando)'!$B:$P,3,FALSE),0) -> 0 | F29: =IFERROR(VLOOKUP($B29,'Assumption (MedClinic-Oando)'!$B:$P,3,FALSE),0) -> 0 | G29: =IFERROR(VLOOKUP($B29,'Assumption (MedClinic-Oando)'!$B:$P,3,FALSE),0) -> 0 | H29: =IFERROR(VLOOKUP($B29,'Assumption (MedClinic-Oando)'!$B:$P,3,FALSE),0) -> 0 | I29: =IFERROR(VLOOKUP($B29,'Assumption (MedClinic-Oando)'!$B:$P,3,FALSE),0) -> 0 | J29: =IFERROR(VLOOKUP($B29,'Assumption (MedClinic-Oando)'!$B:$P,3,FALSE),0) -> 0 | K29: =IFERROR(VLOOKUP($B29,'Assumption (MedClinic-Oando)'!$B:$P,3,FALSE),0) -> 0 | ... O29: =IFERROR(VLOOKUP($B29,'Assumption (MedClinic-Oando)'!$B:$P,3,FALSE),0) -> 0 | P29: =SUM(D29:O29) -> 0 | Q29: =P29*(1+'[2]Assumption (Advisory)'!E$46) -> 0 | R29: =Q29*(1+'[2]Assumption (Advisory)'!F$46) -> 0 | S29: =R29*(1+'[2]Assumption (Advisory)'!G$46) -> 0 | T29: =S29*(1+'[2]Assumption (Advisory)'!H$46) -> 0
B30: Electricity | D30: =IFERROR(VLOOKUP($B30,'Assumption (MedClinic-Oando)'!$B:$P,3,FALSE),0) -> 0 | E30: =IFERROR(VLOOKUP($B30,'Assumption (MedClinic-Oando)'!$B:$P,3,FALSE),0) -> 0 | F30: =IFERROR(VLOOKUP($B30,'Assumption (MedClinic-Oando)'!$B:$P,3,FALSE),0) -> 0 | G30: =IFERROR(VLOOKUP($B30,'Assumption (MedClinic-Oando)'!$B:$P,3,FALSE),0) -> 0 | H30: =IFERROR(VLOOKUP($B30,'Assumption (MedClinic-Oando)'!$B:$P,3,FALSE),0) -> 0 | I30: =IFERROR(VLOOKUP($B30,'Assumption (MedClinic-Oando)'!$B:$P,3,FALSE),0) -> 0 | J30: =IFERROR(VLOOKUP($B30,'Assumption (MedClinic-Oando)'!$B:$P,3,FALSE),0) -> 0 | K30: =IFERROR(VLOOKUP($B30,'Assumption (MedClinic-Oando)'!$B:$P,3,FALSE),0) -> 0 | ... O30: =IFERROR(VLOOKUP($B30,'Assumption (MedClinic-Oando)'!$B:$P,3,FALSE),0) -> 0 | P30: =SUM(D30:O30) -> 0 | Q30: =P30*(1+'[2]Assumption (Advisory)'!E$46) -> 0 | R30: =Q30*(1+'[2]Assumption (Advisory)'!F$46) -> 0 | S30: =R30*(1+'[2]Assumption (Advisory)'!G$46) -> 0 | T30: =S30*(1+'[2]Assumption (Advisory)'!H$46) -> 0
B31: Security | D31: =IFERROR(VLOOKUP($B31,'Assumption (MedClinic-Oando)'!$B:$P,3,FALSE),0) -> 0 | E31: =IFERROR(VLOOKUP($B31,'Assumption (MedClinic-Oando)'!$B:$P,3,FALSE),0) -> 0 | F31: =IFERROR(VLOOKUP($B31,'Assumption (MedClinic-Oando)'!$B:$P,3,FALSE),0) -> 0 | G31: =IFERROR(VLOOKUP($B31,'Assumption (MedClinic-Oando)'!$B:$P,3,FALSE),0) -> 0 | H31: =IFERROR(VLOOKUP($B31,'Assumption (MedClinic-Oando)'!$B:$P,3,FALSE),0) -> 0 | I31: =IFERROR(VLOOKUP($B31,'Assumption (MedClinic-Oando)'!$B:$P,3,FALSE),0) -> 0 | J31: =IFERROR(VLOOKUP($B31,'Assumption (MedClinic-Oando)'!$B:$P,3,FALSE),0) -> 0 | K31: =IFERROR(VLOOKUP($B31,'Assumption (MedClinic-Oando)'!$B:$P,3,FALSE),0) -> 0 | ... O31: =IFERROR(VLOOKUP($B31,'Assumption (MedClinic-Oando)'!$B:$P,3,FALSE),0) -> 0 | P31: =SUM(D31:O31) -> 0 | Q31: =P31*(1+'[2]Assumption (Advisory)'!E$46) -> 0 | R31: =Q31*(1+'[2]Assumption (Advisory)'!F$46) -> 0 | S31: =R31*(1+'[2]Assumption (Advisory)'!G$46) -> 0 | T31: =S31*(1+'[2]Assumption (Advisory)'!H$46) -> 0
B32: Local Govt Levies & Charges | D32: =IFERROR(VLOOKUP($B32,'Assumption (MedClinic-Oando)'!$B:$P,3,FALSE),0) -> 400000 | E32: =IFERROR(VLOOKUP($B32,'Assumption (MedClinic-Oando)'!$B:$P,3,FALSE),0) -> 400000 | F32: =IFERROR(VLOOKUP($B32,'Assumption (MedClinic-Oando)'!$B:$P,3,FALSE),0) -> 400000 | G32: =IFERROR(VLOOKUP($B32,'Assumption (MedClinic-Oando)'!$B:$P,3,FALSE),0) -> 400000 | H32: =IFERROR(VLOOKUP($B32,'Assumption (MedClinic-Oando)'!$B:$P,3,FALSE),0) -> 400000 | I32: =IFERROR(VLOOKUP($B32,'Assumption (MedClinic-Oando)'!$B:$P,3,FALSE),0) -> 400000 | J32: =IFERROR(VLOOKUP($B32,'Assumption (MedClinic-Oando)'!$B:$P,3,FALSE),0) -> 400000 | K32: =IFERROR(VLOOKUP($B32,'Assumption (MedClinic-Oando)'!$B:$P,3,FALSE),0) -> 400000 | ... O32: =IFERROR(VLOOKUP($B32,'Assumption (MedClinic-Oando)'!$B:$P,3,FALSE),0) -> 400000 | P32: =SUM(D32:O32) -> 4800000 | Q32: =P32*(1+'[2]Assumption (Advisory)'!E$46) -> 5520000 | R32: =Q32*(1+'[2]Assumption (Advisory)'!F$46) -> 6348000 | S32: =R32*(1+'[2]Assumption (Advisory)'!G$46) -> 7300200 | T32: =S32*(1+'[2]Assumption (Advisory)'!H$46) -> 8395230
B33: Insurance Expenses | D33: =IFERROR(VLOOKUP($B33,'Assumption (MedClinic-Oando)'!$B:$P,3,FALSE),0) -> 1200000 | E33: =IFERROR(VLOOKUP($B33,'Assumption (MedClinic-Oando)'!$B:$P,3,FALSE),0) -> 1200000 | F33: =IFERROR(VLOOKUP($B33,'Assumption (MedClinic-Oando)'!$B:$P,3,FALSE),0) -> 1200000 | G33: =IFERROR(VLOOKUP($B33,'Assumption (MedClinic-Oando)'!$B:$P,3,FALSE),0) -> 1200000 | H33: =IFERROR(VLOOKUP($B33,'Assumption (MedClinic-Oando)'!$B:$P,3,FALSE),0) -> 1200000 | I33: =IFERROR(VLOOKUP($B33,'Assumption (MedClinic-Oando)'!$B:$P,3,FALSE),0) -> 1200000 | J33: =IFERROR(VLOOKUP($B33,'Assumption (MedClinic-Oando)'!$B:$P,3,FALSE),0) -> 1200000 | K33: =IFERROR(VLOOKUP($B33,'Assumption (MedClinic-Oando)'!$B:$P,3,FALSE),0) -> 1200000 | ... O33: =IFERROR(VLOOKUP($B33,'Assumption (MedClinic-Oando)'!$B:$P,3,FALSE),0) -> 1200000 | P33: =SUM(D33:O33) -> 14400000 | Q33: =P33*(1+'[2]Assumption (Advisory)'!E$46) -> 16560000 | R33: =Q33*(1+'[2]Assumption (Advisory)'!F$46) -> 19044000 | S33: =R33*(1+'[2]Assumption (Advisory)'!G$46) -> 21900600 | T33: =S33*(1+'[2]Assumption (Advisory)'!H$46) -> 25185690
B34: Depreciation Expenses | D34: =IFERROR(VLOOKUP($B34,'Assumption (MedClinic-Oando)'!$B:$P,3,FALSE),0) -> 1500000 | E34: =IFERROR(VLOOKUP($B34,'Assumption (MedClinic-Oando)'!$B:$P,3,FALSE),0) -> 1500000 | F34: =IFERROR(VLOOKUP($B34,'Assumption (MedClinic-Oando)'!$B:$P,3,FALSE),0) -> 1500000 | G34: =IFERROR(VLOOKUP($B34,'Assumption (MedClinic-Oando)'!$B:$P,3,FALSE),0) -> 1500000 | H34: =IFERROR(VLOOKUP($B34,'Assumption (MedClinic-Oando)'!$B:$P,3,FALSE),0) -> 1500000 | I34: =IFERROR(VLOOKUP($B34,'Assumption (MedClinic-Oando)'!$B:$P,3,FALSE),0) -> 1500000 | J34: =IFERROR(VLOOKUP($B34,'Assumption (MedClinic-Oando)'!$B:$P,3,FALSE),0) -> 1500000 | K34: =IFERROR(VLOOKUP($B34,'Assumption (MedClinic-Oando)'!$B:$P,3,FALSE),0) -> 1500000 | ... O34: =IFERROR(VLOOKUP($B34,'Assumption (MedClinic-Oando)'!$B:$P,3,FALSE),0) -> 1500000 | P34: =SUM(D34:O34) -> 18000000 | Q34: =P34*(1+'[2]Assumption (Advisory)'!E$46) -> 20700000 | R34: =Q34*(1+'[2]Assumption (Advisory)'!F$46) -> 23805000 | S34: =R34*(1+'[2]Assumption (Advisory)'!G$46) -> 27375750 | T34: =S34*(1+'[2]Assumption (Advisory)'!H$46) -> 31482112
... B36: Shell Admin & Staff Cost | D36: =IFERROR(VLOOKUP($B36,'Assumption (MedClinic-Oando)'!$B:$P,3,FALSE),0) -> 0 | E36: =IFERROR(VLOOKUP($B36,'Assumption (MedClinic-Oando)'!$B:$P,3,FALSE),0) -> 0 | F36: =IFERROR(VLOOKUP($B36,'Assumption (MedClinic-Oando)'!$B:$P,3,FALSE),0) -> 0 | G36: =IFERROR(VLOOKUP($B36,'Assumption (MedClinic-Oando)'!$B:$P,3,FALSE),0) -> 0 | H36: =IFERROR(VLOOKUP($B36,'Assumption (MedClinic-Oando)'!$B:$P,3,FALSE),0) -> 0 | I36: =IFERROR(VLOOKUP($B36,'Assumption (MedClinic-Oando)'!$B:$P,3,FALSE),0) -> 0 | J36: =IFERROR(VLOOKUP($B36,'Assumption (MedClinic-Oando)'!$B:$P,3,FALSE),0) -> 0 | K36: =IFERROR(VLOOKUP($B36,'Assumption (MedClinic-Oando)'!$B:$P,3,FALSE),0) -> 0 | ... O36: =IFERROR(VLOOKUP($B36,'Assumption (MedClinic-Oando)'!$B:$P,3,FALSE),0) -> 0 | P36: =SUM(D36:O36) -> 0 | Q36: =P36*(1+'[2]Assumption (Advisory)'!E$46) -> 0 | R36: =Q36*(1+'[2]Assumption (Advisory)'!F$46) -> 0 | S36: =R36*(1+'[2]Assumption (Advisory)'!G$46) -> 0 | T36: =S36*(1+'[2]Assumption (Advisory)'!H$46) -> 0
D37: =IFERROR(VLOOKUP($B37,'Assumption (MedClinic-Oando)'!$B:$P,3,FALSE),0) -> 0 | E37: =IFERROR(VLOOKUP($B37,'Assumption (MedClinic-Oando)'!$B:$P,3,FALSE),0) -> 0 | F37: =IFERROR(VLOOKUP($B37,'Assumption (MedClinic-Oando)'!$B:$P,3,FALSE),0) -> 0 | G37: =IFERROR(VLOOKUP($B37,'Assumption (MedClinic-Oando)'!$B:$P,3,FALSE),0) -> 0 | H37: =IFERROR(VLOOKUP($B37,'Assumption (MedClinic-Oando)'!$B:$P,3,FALSE),0) -> 0 | I37: =IFERROR(VLOOKUP($B37,'Assumption (MedClinic-Oando)'!$B:$P,3,FALSE),0) -> 0 | J37: =IFERROR(VLOOKUP($B37,'Assumption (MedClinic-Oando)'!$B:$P,3,FALSE),0) -> 0 | K37: =IFERROR(VLOOKUP($B37,'Assumption (MedClinic-Oando)'!$B:$P,3,FALSE),0) -> 0 | ... O37: =IFERROR(VLOOKUP($B37,'Assumption (MedClinic-Oando)'!$B:$P,3,FALSE),0) -> 0 | P37: =SUM(D37:O37) -> 0 | Q37: =P37*(1+'[2]Assumption (Advisory)'!E$46) -> 0 | R37: =Q37*(1+'[2]Assumption (Advisory)'!F$46) -> 0 | S37: =R37*(1+'[2]Assumption (Advisory)'!G$46) -> 0 | T37: =S37*(1+'[2]Assumption (Advisory)'!H$46) -> 0
B39: Total Opex | D39: =SUM(D22:D37) -> 48494917 | E39: =SUM(E22:E37) -> 48494917 | F39: =SUM(F22:F37) -> 48494917 | G39: =SUM(G22:G37) -> 48494917 | H39: =SUM(H22:H37) -> 48494917 | I39: =SUM(I22:I37) -> 48494917 | J39: =SUM(J22:J37) -> 48494917 | K39: =SUM(K22:K37) -> 48494917 | ... T39: =SUM(T22:T37) -> 8.8162976e+08
B41: EBITDA | D41: =D19-D39 -> 73722400 | E41: =E19-E39 -> 73722400 | F41: =F19-F39 -> 73722400 | G41: =G19-G39 -> 73722400 | H41: =H19-H39 -> 73722400 | I41: =I19-I39 -> 73722400 | J41: =J19-J39 -> 73722400 | K41: =K19-K39 -> 73722400 | ... T41: =T19-T39 -> 7.4711419e+09
B43: Depreciation Expenses | D43: =VLOOKUP($B43,'Assumption (MedClinic-Oando)'!$B:$P,3,FALSE) -> 1500000 | E43: =D43 -> 1500000 | F43: =E43 -> 1500000 | G43: =F43 -> 1500000 | H43: =G43 -> 1500000 | I43: =H43 -> 1500000 | J43: =I43 -> 1500000 | K43: =J43 -> 1500000 | L43: =K43 -> 1500000 | ... O43: =N43 -> 1500000 | P43: =SUM(D43:O43) -> 18000000 | Q43: =P43*(1+'[2]Assumption (Advisory)'!E$46) -> 20700000 | R43: =Q43*(1+'[2]Assumption (Advisory)'!F$46) -> 23805000 | S43: =R43*(1+'[2]Assumption (Advisory)'!G$46) -> 27375750 | T43: =S43*(1+'[2]Assumption (Advisory)'!H$46) -> 31482112
B45: Net Profit/(Loss) | D45: =D41-D43 -> 72222400 | E45: =E41-E43 -> 72222400 | F45: =F41-F43 -> 72222400 | G45: =G41-G43 -> 72222400 | H45: =H41-H43 -> 72222400 | I45: =I41-I43 -> 72222400 | J45: =J41-J43 -> 72222400 | K45: =K41-K43 -> 72222400 | ... T45: =T41-T43 -> 7.4396598e+09
