Workbook
Name afril: #REF!
Name BS: #REF!
Name costaa: #REF!
Name F: #REF!
Name fs: #REF!
Name GGGG: #REF!
Name groupincome: #REF!
Name MANS: #REF!
Name OLDMAN: #REF!
Name PAC: #REF!
Name PL: #REF!
Name REGISTRAR: #REF!
Name SCHD3: #REF!
Name SCHED1: #REF!
Name SCHED2: #REF!
Name SCHED3: #REF!
Name SCHED4: #REF!
Name SEMI: #REF!
Name SSES: #REF!
Name SUMMARY: #REF!
Name yyy: #REF!

Sheet Assumption-(MedFit)
B1: Assumptions-Inputs
D3: Jan | E3: Feb | F3: Mar | G3: Apr | H3: May | I3: Jun | J3: Jul | K3: Aug | L3: Sep | M3: Oct | N3: Nov | O3: Dec | P3: Total
B4: Live_Case
B5: Wellness Packages | D5: =SUM(D6:D11) -> 0 | E5: =SUM(E6:E11) -> 0 | F5: =SUM(F6:F11) -> 0 | G5: =SUM(G6:G11) -> 0 | H5: =SUM(H6:H11) -> 0 | I5: =SUM(I6:I11) -> 0 | J5: =SUM(J6:J11) -> 0 | K5: =SUM(K6:K11) -> 0 | ... O5: =SUM(O6:O11) -> 0 | P5: =SUM(D5:O5) -> 0
B6: IV micronutrient Therapy (Vitamins, Amino Acids,(in clinic & Home) | D6: =D28*D49 -> 0 | E6: =E49*E28 -> 0 | F6: =F49*F28 -> 0 | G6: =G49*G28 -> 0 | H6: =H49*H28 -> 0 | I6: =I49*I28 -> 0 | J6: =J49*J28 -> 0 | K6: =K49*K28 -> 0 | L6: =L49*L28 -> 0 | ... O6: =O49*O28 -> 0 | P6: =SUM(D6:O6) -> 0
B7: IV micronutrient Therapy Weight loss (Slim boost(in clinic & Home) | D7: =D29*D50 -> 0 | E7: =E50*E29 -> 0 | F7: =F50*F29 -> 0 | G7: =G50*G29 -> 0 | H7: =H50*H29 -> 0 | I7: =I50*I29 -> 0 | J7: =J50*J29 -> 0 | K7: =K50*K29 -> 0 | L7: =L50*L29 -> 0 | ... O7: =O50*O29 -> 0 | P7: =SUM(D7:O7) -> 0
B8: Weight loss programs (Meal Plans, etc) | D8: =D30*D51 -> 0 | E8: =E51*E30 -> 0 | F8: =F51*F30 -> 0 | G8: =G51*G30 -> 0 | H8: =H51*H30 -> 0 | I8: =I51*I30 -> 0 | J8: =J51*J30 -> 0 | K8: =K51*K30 -> 0 | L8: =L51*L30 -> 0 | ... O8: =O51*O30 -> 0 | P8: =SUM(D8:O8) -> 0
B9: Medical Weight loss programs (Mounjaro, etc) | D9: =D31*D52 -> 0 | E9: =E31*E52 -> 0 | F9: =F31*F52 -> 0 | G9: =G31*G52 -> 0 | H9: =H31*H52 -> 0 | I9: =I31*I52 -> 0 | J9: =J31*J52 -> 0 | K9: =K31*K52 -> 0 | ... O9: =O31*O52 -> 0 | P9: =SUM(D9:O9) -> 0
B13: Occupational health- Project | D13: =SUM(D14:D23) -> 6224208.3 | E13: =SUM(E14:E23) -> 6224208.3 | F13: =SUM(F14:F23) -> 6224208.3 | G13: =SUM(G14:G23) -> 6224208.3 | H13: =SUM(H14:H23) -> 6224208.3 | I13: =SUM(I14:I23) -> 6224208.3 | J13: =SUM(J14:J23) -> 6224208.3 | K13: =SUM(K14:K23) -> 6224208.3 | ... P13: =SUM(P14:P23) -> 74690500
B14: FOOD HANDLERS TEST | D14: =D36*D57 -> 0 | E14: =E36*E57 -> 0 | F14: =F36*F57 -> 0 | G14: =G36*G57 -> 0 | H14: =H36*H57 -> 0 | I14: =I36*I57 -> 0 | J14: =J36*J57 -> 0 | K14: =K36*K57 -> 0 | ... O14: =O36*O57 -> 0 | P14: =SUM(D14:O14) -> 0
B15: CHEMICAL HANDLERS TEST | D15: =D37*D58 -> 808166.67 | E15: =E37*E58 -> 808166.67 | F15: =F37*F58 -> 808166.67 | G15: =G37*G58 -> 808166.67 | H15: =H37*H58 -> 808166.67 | I15: =I37*I58 -> 808166.67 | J15: =J37*J58 -> 808166.67 | K15: =K37*K58 -> 808166.67 | ... O15: =O37*O58 -> 808166.67 | P15: =SUM(D15:O15) -> 9698000
B16: AUDIOMETRY | D16: =D38*D59 -> 779250 | E16: =E38*E59 -> 779250 | F16: =F38*F59 -> 779250 | G16: =G38*G59 -> 779250 | H16: =H38*H59 -> 779250 | I16: =I38*I59 -> 779250 | J16: =J38*J59 -> 779250 | K16: =K38*K59 -> 779250 | ... O16: =O38*O59 -> 779250 | P16: =SUM(D16:O16) -> 9351000
B17: SPIROMETRY | D17: =D39*D60 -> 302041.67 | E17: =E39*E60 -> 302041.67 | F17: =F39*F60 -> 302041.67 | G17: =G39*G60 -> 302041.67 | H17: =H39*H60 -> 302041.67 | I17: =I39*I60 -> 302041.67 | J17: =J39*J60 -> 302041.67 | K17: =K39*K60 -> 302041.67 | ... O17: =O39*O60 -> 302041.67 | P17: =SUM(D17:O17) -> 3624500
B18: WORK AT HEIGHT MEDICALS | D18: =D40*D61 -> 108750 | E18: =E40*E61 -> 108750 | F18: =F40*F61 -> 108750 | G18: =G40*G61 -> 108750 | H18: =H40*H61 -> 108750 | I18: =I40*I61 -> 108750 | J18: =J40*J61 -> 108750 | K18: =K40*K61 -> 108750 | ... O18: =O40*O61 -> 108750 | P18: =SUM(D18:O18) -> 1305000
B19: FITNESS TO DRIVE MEDICAL | D19: =D41*D62 -> 413000 | E19: =E41*E62 -> 413000 | F19: =F41*F62 -> 413000 | G19: =G41*G62 -> 413000 | H19: =H41*H62 -> 413000 | I19: =I41*I62 -> 413000 | J19: =J41*J62 -> 413000 | K19: =K41*K62 -> 413000 | ... O19: =O41*O62 -> 413000 | P19: =SUM(D19:O19) -> 4956000
B20: ANNUAL MEDICAL | D20: =D42*D63 -> 1406833.3 | E20: =E42*E63 -> 1406833.3 | F20: =F42*F63 -> 1406833.3 | G20: =G42*G63 -> 1406833.3 | H20: =H42*H63 -> 1406833.3 | I20: =I42*I63 -> 1406833.3 | J20: =J42*J63 -> 1406833.3 | K20: =K42*K63 -> 1406833.3 | ... O20: =O42*O63 -> 1406833.3 | P20: =SUM(D20:O20) -> 16882000
B21: CHOLERA VACCINATION | D21: =D43*D64 -> 2115000 | E21: =E43*E64 -> 2115000 | F21: =F43*F64 -> 2115000 | G21: =G43*G64 -> 2115000 | H21: =H43*H64 -> 2115000 | I21: =I43*I64 -> 2115000 | J21: =J43*J64 -> 2115000 | K21: =K43*K64 -> 2115000 | ... O21: =O43*O64 -> 2115000 | P21: =SUM(D21:O21) -> 25380000
B22: CHEST XRAY ONLY | D22: =D44*D65 -> 240166.67 | E22: =E44*E65 -> 240166.67 | F22: =F44*F65 -> 240166.67 | G22: =G44*G65 -> 240166.67 | H22: =H44*H65 -> 240166.67 | I22: =I44*I65 -> 240166.67 | J22: =J44*J65 -> 240166.67 | K22: =K44*K65 -> 240166.67 | ... O22: =O44*O65 -> 240166.67 | P22: =SUM(D22:O22) -> 2882000
B23: KNOW-YOUR-NUMBER MEDICALS | D23: =D45*D67 -> 51000 | E23: =E45*E67 -> 51000 | F23: =F45*F67 -> 51000 | G23: =G45*G67 -> 51000 | H23: =H45*H67 -> 51000 | I23: =I45*I67 -> 51000 | J23: =J45*J67 -> 51000 | K23: =K45*K67 -> 51000 | ... O23: =O45*O67 -> 51000 | P23: =SUM(D23:O23) -> 612000
B26: Average no of Patient
B27: Wellness Packages
B28: IV micronutrient Therapy (Vitamins, Amino Acids,(in clinic & Home) | P28: =SUM(D28:O28) -> 0 | R28: 30 | S28: 31 | T28: 32 | V28: 33 | W28: 34 | X28: 35 | Y28: 36 | Z28: 37 | AA28: 38 | AB28: 39 | AC28: 40 | AD28: 41
B29: IV micronutrient Therapy Weight loss (Slim boost(in clinic & Home) | P29: =SUM(D29:O29) -> 0 | R29: 30 | S29: 30 | T29: 30 | V29: 30 | W29: 30 | X29: 30 | Y29: 30 | Z29: 30 | AA29: 30 | AB29: 30 | AC29: 30 | AD29: 30
B30: Weight loss programs (Meal Plans, etc) | P30: =SUM(D30:O30) -> 0 | R30: 30 | S30: 30 | T30: 30 | V30: 30 | W30: 30 | X30: 30 | Y30: 30 | Z30: 30 | AA30: 30 | AB30: 30 | AC30: 30 | AD30: 30
B31: Medical Weight loss programs (Mounjaro, etc) | P31: =SUM(D31:O31) -> 0 | R31: 20 | S31: 20 | T31: 20 | V31: 20 | W31: 20 | X31: 20 | Y31: 20 | Z31: 20 | AA31: 20 | AB31: 20 | AC31: 20 | AD31: 20
B35: Occupational Health- Project
B36: FOOD HANDLERS TEST | D36: 1229.4167 | E36: 1229.4167 | F36: 1229.4167 | G36: 1229.4167 | H36: 1229.4167 | I36: 1229.4167 | J36: 1229.4167 | K36: 1229.4167 | L36: 1229.4167 | M36: 1229.4167 | N36: 1229.4167 | O36: 1229.4167 | P36: =SUM(D36:O36) -> 14753 | R36: =(P36-2358)/2358 -> 5.2565734 | S36: =P36/1.3 -> 11348.462
B37: CHEMICAL HANDLERS TEST | D37: 62.166667 | E37: 62.166667 | F37: 62.166667 | G37: 62.166667 | H37: 62.166667 | I37: 62.166667 | J37: 62.166667 | K37: 62.166667 | L37: 62.166667 | M37: 62.166667 | N37: 62.166667 | O37: 62.166667 | P37: =SUM(D37:O37) -> 746 | R37: =(P37-1729)/1729 -> -0.56853673 | S37: =P37/1.3 -> 573.84615
B38: AUDIOMETRY | D38: 173.16667 | E38: 173.16667 | F38: 173.16667 | G38: 173.16667 | H38: 173.16667 | I38: 173.16667 | J38: 173.16667 | K38: 173.16667 | L38: 173.16667 | M38: 173.16667 | N38: 173.16667 | O38: 173.16667 | P38: =SUM(D38:O38) -> 2078 | R38: =(P38-315)/315 -> 5.5968254 | S38: =P38/1.3 -> 1598.4615
B39: SPIROMETRY | D39: 54.916667 | E39: 54.916667 | F39: 54.916667 | G39: 54.916667 | H39: 54.916667 | I39: 54.916667 | J39: 54.916667 | K39: 54.916667 | L39: 54.916667 | M39: 54.916667 | N39: 54.916667 | O39: 54.916667 | P39: =SUM(D39:O39) -> 659 | S39: =P39/1.3 -> 506.92308 | T39: 50 | V39: 51 | W39: 52 | X39: 53 | Y39: 54 | Z39: 55 | AA39: 56 | AB39: 57 | AC39: 58 | AD39: 59 | AE39: 60 | AF39: 61
B40: WORK AT HEIGHT MEDICALS | D40: 21.75 | E40: 21.75 | F40: 21.75 | G40: 21.75 | H40: 21.75 | I40: 21.75 | J40: 21.75 | K40: 21.75 | L40: 21.75 | M40: 21.75 | N40: 21.75 | O40: 21.75 | P40: =SUM(D40:O40) -> 261 | S40: =P40/1.3 -> 200.76923 | T40: 60 | V40: =T40+$C40 -> 60 | W40: =V40+$C40 -> 60 | X40: =W40+$C40 -> 60 | Y40: =X40+$C40 -> 60 | Z40: =Y40+$C40 -> 60 | AA40: =Z40+$C40 -> 60 | AB40: =AA40+$C40 -> 60 | AC40: =AB40+$C40 -> 60 | AD40: =AC40+$C40 -> 60 | ... AF40: =AE40+$C40 -> 60
B41: FITNESS TO DRIVE MEDICAL | D41: 29.5 | E41: 29.5 | F41: 29.5 | G41: 29.5 | H41: 29.5 | I41: 29.5 | J41: 29.5 | K41: 29.5 | L41: 29.5 | M41: 29.5 | N41: 29.5 | O41: 29.5 | P41: =SUM(D41:O41) -> 354 | R41: =(P41-379)/379 -> -0.065963061 | S41: =P41/1.3 -> 272.30769 | T41: 120 | V41: 121 | W41: 122 | X41: 123 | Y41: 124 | Z41: 125 | AA41: 126 | AB41: 127 | AC41: 128 | AD41: 129 | AE41: 130 | AF41: 131
B42: ANNUAL MEDICAL | D42: 122.33333 | E42: 122.33333 | F42: 122.33333 | G42: 122.33333 | H42: 122.33333 | I42: 122.33333 | J42: 122.33333 | K42: 122.33333 | L42: 122.33333 | M42: 122.33333 | N42: 122.33333 | O42: 122.33333 | P42: =SUM(D42:O42) -> 1468 | S42: =P42/1.3 -> 1129.2308 | T42: 80 | V42: 81 | W42: 82 | X42: 83 | Y42: 84 | Z42: 85 | AA42: 86 | AB42: 87 | AC42: 88 | AD42: 89 | AE42: 90 | AF42: 91
B43: VACCINATION | D43: 70.5 | E43: 70.5 | F43: 70.5 | G43: 70.5 | H43: 70.5 | I43: 70.5 | J43: 70.5 | K43: 70.5 | L43: 70.5 | M43: 70.5 | N43: 70.5 | O43: 70.5 | P43: =SUM(D43:O43) -> 846 | R43: =(P43-1077)/1077 -> -0.21448468 | S43: =P43/1.3 -> 650.76923 | T43: 200 | V43: 201 | W43: 202 | X43: 203 | Y43: 204 | Z43: 205 | AA43: 206 | AB43: 207 | AC43: 208 | AD43: 209 | AE43: 210 | AF43: 211
B44: CHEST XRAY ONLY | D44: 10.916667 | E44: 10.916667 | F44: 10.916667 | G44: 10.916667 | H44: 10.916667 | I44: 10.916667 | J44: 10.916667 | K44: 10.916667 | L44: 10.916667 | M44: 10.916667 | N44: 10.916667 | O44: 10.916667 | P44: =SUM(D44:O44) -> 131 | T44: 150 | V44: 151 | W44: 152 | X44: 153 | Y44: 154 | Z44: 155 | AA44: 156 | AB44: 157 | AC44: 158 | AD44: 159 | AE44: 160 | AF44: 161
B45: KNOW-YOUR-NUMBER MEDICALS | D45: 8.5 | E45: 8.5 | F45: 8.5 | G45: 8.5 | H45: 8.5 | I45: 8.5 | J45: 8.5 | K45: 8.5 | L45: 8.5 | M45: 8.5 | N45: 8.5 | O45: 8.5 | P45: =SUM(D45:O45) -> 102
P46: =SUM(D46:O46) -> 0
B47: Average case - Price | P47: =SUM(D47:O47) -> 0
B48: Corporate | D48: Average price spent per person | P48: =SUM(D48:O48) -> 0
B49: IV micronutrient Therapy (Vitamins, Amino Acids,(in clinic & Home) | P49: =SUM(D49:O49) -> 0 | R49: 200000 | S49: =R49 -> 200000 | T49: =S49 -> 200000 | V49: =T49 -> 200000 | W49: =V49 -> 200000 | X49: =W49 -> 200000 | Y49: =X49 -> 200000 | Z49: =Y49 -> 200000 | AA49: =Z49 -> 200000 | AB49: =AA49 -> 200000 | AC49: =AB49 -> 200000 | AD49: =AC49 -> 200000
...

Sheet Computations-(MedFit)
A2: Computations-Outputs
D3: Jan | E3: Feb | F3: Mar | G3: Apr | H3: May | I3: Jun | J3: Jul | K3: Aug | L3: Sep | M3: Oct | N3: Nov | O3: Dec | P3: FY 1 | Q3: FY 2 | R3: FY 3 | S3: FY 4 | T3: FY 5
D4: ₦ | E4: ₦ | F4: ₦ | G4: ₦ | H4: ₦ | I4: ₦ | J4: ₦ | K4: ₦ | L4: ₦ | M4: ₦ | N4: ₦ | O4: ₦ | P4: NGN | Q4: NGN | R4: NGN | S4: NGN | T4: NGN
B5: Revenue
B6: ='Assumption-(MedFit)'!B13 -> Occupational health- Project | D6: ='Assumption-(MedFit)'!D13 -> 6224208.3 | E6: ='Assumption-(MedFit)'!E13 -> 6224208.3 | F6: ='Assumption-(MedFit)'!F13 -> 6224208.3 | G6: ='Assumption-(MedFit)'!G13 -> 6224208.3 | H6: ='Assumption-(MedFit)'!H13 -> 6224208.3 | I6: ='Assumption-(MedFit)'!I13 -> 6224208.3 | J6: ='Assumption-(MedFit)'!J13 -> 6224208.3 | K6: ='Assumption-(MedFit)'!K13 -> 6224208.3 | ... O6: ='Assumption-(MedFit)'!O13 -> 6224208.3 | P6: =SUM(D6:O6) -> 74690500 | Q6: =P6*(1+'Assumption-(MedFit)'!E$73)*(1+'Assumption-(MedFit)'!E$76) -> 103072890 | R6: =Q6*(1+'Assumption-(MedFit)'!F$73)*(1+'Assumption-(MedFit)'!F$76) -> 1.4224059e+08 | S6: =R6*(1+'Assumption-(MedFit)'!G$73)*(1+'Assumption-(MedFit)'!G$76) -> 1.9629201e+08 | T6: =S6*(1+'Assumption-(MedFit)'!H$73)*(1+'Assumption-(MedFit)'!H$76) -> 2.7088298e+08
B8: Total Revenue | D8: =SUM(D6:D6) -> 6224208.3 | E8: =SUM(E6:E6) -> 6224208.3 | F8: =SUM(F6:F6) -> 6224208.3 | G8: =SUM(G6:G6) -> 6224208.3 | H8: =SUM(H6:H6) -> 6224208.3 | I8: =SUM(I6:I6) -> 6224208.3 | J8: =SUM(J6:J6) -> 6224208.3 | K8: =SUM(K6:K6) -> 6224208.3 | ... T8: =SUM(T6:T6) -> 2.7088298e+08
E9: =(E8-D8)/D8 -> 0 | F9: =(F8-E8)/E8 -> 0 | G9: =(G8-F8)/F8 -> 0 | H9: =(H8-G8)/G8 -> 0 | I9: =(I8-H8)/H8 -> 0 | J9: =(J8-I8)/I8 -> 0 | K9: =(K8-J8)/J8 -> 0 | L9: =(L8-K8)/K8 -> 0 | ... O9: =(O8-N8)/N8 -> 0 | Q9: =(Q8-P8)/P8 -> 0.38 | R9: =(R8-Q8)/Q8 -> 0.38 | S9: =(S8-R8)/R8 -> 0.38 | T9: =(T8-S8)/S8 -> 0.38
B10: Cost of Revenue
B11: Direct Cost - 3rd Party Services | C11: 0.3 | D11: =D$8*$C$11 -> 1867262.5 | E11: =E$8*$C$11 -> 1867262.5 | F11: =F$8*$C$11 -> 1867262.5 | G11: =G$8*$C$11 -> 1867262.5 | H11: =H$8*$C$11 -> 1867262.5 | I11: =I$8*$C$11 -> 1867262.5 | J11: =J$8*$C$11 -> 1867262.5 | K11: =K$8*$C$11 -> 1867262.5 | ... O11: =O$8*$C$11 -> 1867262.5 | P11: =SUM(D11:O11) -> 22407150 | Q11: =P$8*(1+'Assumption-(MedFit)'!E$77)*'Assumption-(MedFit)'!$C$77 -> 24647865 | R11: =Q$8*(1+'Assumption-(MedFit)'!F$77)*'Assumption-(MedFit)'!$C$77 -> 33395616 | S11: =R$8*(1+'Assumption-(MedFit)'!G$77)*'Assumption-(MedFit)'!$C$77 -> 46085951 | T11: =S$8*(1+'Assumption-(MedFit)'!H$77)*'Assumption-(MedFit)'!$C$77 -> 62420860
B12: Direct Cost - Staff | C12: =D12/D8 -> 1.9249436 | D12: ='Assumption-(MedFit)'!V112 -> 11981250 | E12: =D12 -> 11981250 | F12: =E12 -> 11981250 | G12: =F12 -> 11981250 | H12: =G12 -> 11981250 | I12: =H12 -> 11981250 | J12: =I12 -> 11981250 | K12: =J12 -> 11981250 | L12: =K12 -> 11981250 | ... O12: =N12 -> 11981250 | P12: =SUM(D12:O12) -> 143775000 | Q12: =P12 -> 143775000 | R12: =Q12 -> 143775000 | S12: =R12 -> 143775000 | T12: =S12 -> 143775000
B13: Direct Cost - Sales Commission | C13: 0.01 | D13: =$C$13*D8 -> 62242.083 | E13: =$C$13*E8 -> 62242.083 | F13: =$C$13*F8 -> 62242.083 | G13: =$C$13*G8 -> 62242.083 | H13: =$C$13*H8 -> 62242.083 | I13: =$C$13*I8 -> 62242.083 | J13: =$C$13*J8 -> 62242.083 | K13: =$C$13*K8 -> 62242.083 | ... O13: =$C$13*O8 -> 62242.083 | P13: =SUM(D13:O13) -> 746905 | Q13: =Q8*$C$13 -> 1030728.9 | R13: =R8*$C$13 -> 1422405.9 | S13: =S8*$C$13 -> 1962920.1 | T13: =T8*$C$13 -> 2708829.8
B14: Direct Cost - Overheads & Others | C14: 0 | D14: =$C$14*D$8 -> 0 | E14: =$C$14*E$8 -> 0 | F14: =$C$14*F$8 -> 0 | G14: =$C$14*G$8 -> 0 | H14: =$C$14*H$8 -> 0 | I14: =$C$14*I$8 -> 0 | J14: =$C$14*J$8 -> 0 | K14: =$C$14*K$8 -> 0 | ... O14: =$C$14*O$8 -> 0 | P14: =SUM(D14:O14) -> 0 | Q14: =P$8*(1+'Assumption-(MedFit)'!$E80)*'Assumption-(MedFit)'!$C$80 -> 0 | R14: =Q$8*(1+'Assumption-(MedFit)'!$E80)*'Assumption-(MedFit)'!$C$80 -> 0 | S14: =R$8*(1+'Assumption-(MedFit)'!$E80)*'Assumption-(MedFit)'!$C$80 -> 0 | T14: =S$8*(1+'Assumption-(MedFit)'!$E80)*'Assumption-(MedFit)'!$C$80 -> 0
B16: Total Direct Cost | D16: =SUM(D11:D14) -> 13910755 | E16: =SUM(E11:E14) -> 13910755 | F16: =SUM(F11:F14) -> 13910755 | G16: =SUM(G11:G14) -> 13910755 | H16: =SUM(H11:H14) -> 13910755 | I16: =SUM(I11:I14) -> 13910755 | J16: =SUM(J11:J14) -> 13910755 | K16: =SUM(K11:K14) -> 13910755 | ... O16: =SUM(O11:O14) -> 13910755 | P16: =SUM(P11:P15) -> 166929055 | Q16: =SUM(Q11:Q14) -> 1.6945359e+08 | R16: =SUM(R11:R14) -> 1.7859302e+08 | S16: =SUM(S11:S14) -> 1.9182387e+08 | T16: =SUM(T11:T14) -> 2.0890469e+08
B18: Gross Profit | D18: =D8-D16 -> -7686546.3 | E18: =E8-E16 -> -7686546.3 | F18: =F8-F16 -> -7686546.3 | G18: =G8-G16 -> -7686546.3 | H18: =H8-H16 -> -7686546.3 | I18: =I8-I16 -> -7686546.3 | J18: =J8-J16 -> -7686546.3 | K18: =K8-K16 -> -7686546.3 | ... T18: =T8-T16 -> 61978287
B20: Operating expenses
B21: Indirect Staff Cost | D21: ='Assumption-(MedFit)'!V118 -> 0 | E21: =D21 -> 0 | F21: =E21 -> 0 | G21: =F21 -> 0 | H21: =G21 -> 0 | I21: =H21 -> 0 | J21: =I21 -> 0 | K21: =J21 -> 0 | L21: =K21 -> 0 | ... O21: =N21 -> 0 | P21: =SUM(D21:O21) -> 0 | Q21: =P21*(1+'Assumption-(MedFit)'!E$84) -> 0 | R21: =Q21*(1+'Assumption-(MedFit)'!F$84) -> 0 | S21: =R21*(1+'Assumption-(MedFit)'!G$84) -> 0 | T21: =S21*(1+'Assumption-(MedFit)'!H$84) -> 0
B22: Repair&Maintenance | D22: ='Assumption-(MedFit)'!D85 -> 29279.421 | E22: =D22 -> 29279.421 | F22: =E22 -> 29279.421 | G22: =F22 -> 29279.421 | H22: =G22 -> 29279.421 | I22: =H22 -> 29279.421 | J22: =I22 -> 29279.421 | K22: =J22 -> 29279.421 | L22: =K22 -> 29279.421 | ... O22: =N22 -> 29279.421 | P22: =SUM(D22:O22) -> 351353.05 | Q22: =P22*(1+'Assumption-(MedFit)'!E$74) -> 404056.01 | R22: =Q22*(1+'Assumption-(MedFit)'!F$74) -> 464664.41 | S22: =R22*(1+'Assumption-(MedFit)'!G$74) -> 534364.07 | T22: =S22*(1+'Assumption-(MedFit)'!H$74) -> 614518.68
B23: Bank Charges | D23: ='Assumption-(MedFit)'!D86 -> 1463.971 | E23: =D23 -> 1463.971 | F23: =E23 -> 1463.971 | G23: =F23 -> 1463.971 | H23: =G23 -> 1463.971 | I23: =H23 -> 1463.971 | J23: =I23 -> 1463.971 | K23: =J23 -> 1463.971 | L23: =K23 -> 1463.971 | ... O23: =N23 -> 1463.971 | P23: =SUM(D23:O23) -> 17567.653 | Q23: =P23*(1+'Assumption-(MedFit)'!E$74) -> 20202.8 | R23: =Q23*(1+'Assumption-(MedFit)'!F$74) -> 23233.22 | S23: =R23*(1+'Assumption-(MedFit)'!G$74) -> 26718.203 | T23: =S23*(1+'Assumption-(MedFit)'!H$74) -> 30725.934
B24: Advert, Printing & Stationery | D24: ='Assumption-(MedFit)'!$D$87 -> 500000 | E24: =D24 -> 500000 | F24: =E24 -> 500000 | G24: =F24 -> 500000 | H24: =G24 -> 500000 | I24: =H24 -> 500000 | J24: =I24 -> 500000 | K24: =J24 -> 500000 | L24: =K24 -> 500000 | ... O24: =N24 -> 500000 | P24: =SUM(D24:O24) -> 6000000 | Q24: =P24*(1+'Assumption-(MedFit)'!E$74) -> 6900000 | R24: =Q24*(1+'Assumption-(MedFit)'!F$74) -> 7935000 | S24: =R24*(1+'Assumption-(MedFit)'!G$74) -> 9125250 | T24: =S24*(1+'Assumption-(MedFit)'!H$74) -> 10494037
B25: Rent | D25: ='Assumption-(MedFit)'!D88 -> 0 | E25: =D25 -> 0 | F25: =E25 -> 0 | G25: =F25 -> 0 | H25: =G25 -> 0 | I25: =H25 -> 0 | J25: =I25 -> 0 | K25: =J25 -> 0 | L25: =K25 -> 0 | ... O25: =N25 -> 0 | P25: =SUM(D25:O25) -> 0 | Q25: =P25*(1+'Assumption-(MedFit)'!E$74) -> 0 | R25: =Q25*(1+'Assumption-(MedFit)'!F$74) -> 0 | S25: =R25*(1+'Assumption-(MedFit)'!G$74) -> 0 | T25: =S25*(1+'Assumption-(MedFit)'!H$74) -> 0
B26: Internet | D26: ='Assumption-(MedFit)'!$D89 -> 250000 | E26: =D26 -> 250000 | F26: =E26 -> 250000 | G26: =F26 -> 250000 | H26: =G26 -> 250000 | I26: =H26 -> 250000 | J26: =I26 -> 250000 | K26: =J26 -> 250000 | L26: =K26 -> 250000 | ... O26: =N26 -> 250000 | P26: =SUM(D26:O26) -> 3000000 | Q26: =P26*(1+'Assumption-(MedFit)'!E$74) -> 3450000 | R26: =Q26*(1+'Assumption-(MedFit)'!F$74) -> 3967500 | S26: =R26*(1+'Assumption-(MedFit)'!G$74) -> 4562625 | T26: =S26*(1+'Assumption-(MedFit)'!H$74) -> 5247018.7
B27: Call Centre Software Subscription | D27: ='Assumption-(MedFit)'!$D90 -> 83333.333 | E27: =D27 -> 83333.333 | F27: =E27 -> 83333.333 | G27: =F27 -> 83333.333 | H27: =G27 -> 83333.333 | I27: =H27 -> 83333.333 | J27: =I27 -> 83333.333 | K27: =J27 -> 83333.333 | L27: =K27 -> 83333.333 | ... O27: =N27 -> 83333.333 | P27: =SUM(D27:O27) -> 1000000 | Q27: =P27*(1+'Assumption-(MedFit)'!E$74) -> 1150000 | R27: =Q27*(1+'Assumption-(MedFit)'!F$74) -> 1322500 | S27: =R27*(1+'Assumption-(MedFit)'!G$74) -> 1520875 | T27: =S27*(1+'Assumption-(MedFit)'!H$74) -> 1749006.2
B28: Cleaning | D28: ='Assumption-(MedFit)'!$D91 -> 0 | E28: =D28 -> 0 | F28: =E28 -> 0 | G28: =F28 -> 0 | H28: =G28 -> 0 | I28: =H28 -> 0 | J28: =I28 -> 0 | K28: =J28 -> 0 | L28: =K28 -> 0 | ... O28: =N28 -> 0 | P28: =SUM(D28:O28) -> 0 | Q28: =P28*(1+'Assumption-(MedFit)'!E$74) -> 0 | R28: =Q28*(1+'Assumption-(MedFit)'!F$74) -> 0 | S28: =R28*(1+'Assumption-(MedFit)'!G$74) -> 0 | T28: =S28*(1+'Assumption-(MedFit)'!H$74) -> 0
B29: Fuel - Pool Cars | D29: ='Assumption-(MedFit)'!$D92 -> 0 | E29: =D29 -> 0 | F29: =E29 -> 0 | G29: =F29 -> 0 | H29: =G29 -> 0 | I29: =H29 -> 0 | J29: =I29 -> 0 | K29: =J29 -> 0 | L29: =K29 -> 0 | ... O29: =N29 -> 0 | P29: =SUM(D29:O29) -> 0 | Q29: =P29*(1+'Assumption-(MedFit)'!E$74) -> 0 | R29: =Q29*(1+'Assumption-(MedFit)'!F$74) -> 0 | S29: =R29*(1+'Assumption-(MedFit)'!G$74) -> 0 | T29: =S29*(1+'Assumption-(MedFit)'!H$74) -> 0
B30: Electricity | D30: ='Assumption-(MedFit)'!$D93 -> 0 | E30: =D30 -> 0 | F30: =E30 -> 0 | G30: =F30 -> 0 | H30: =G30 -> 0 | I30: =H30 -> 0 | J30: =I30 -> 0 | K30: =J30 -> 0 | L30: =K30 -> 0 | ... O30: =N30 -> 0 | P30: =SUM(D30:O30) -> 0 | Q30: =P30*(1+'Assumption-(MedFit)'!E$74) -> 0 | R30: =Q30*(1+'Assumption-(MedFit)'!F$74) -> 0 | S30: =R30*(1+'Assumption-(MedFit)'!G$74) -> 0 | T30: =S30*(1+'Assumption-(MedFit)'!H$74) -> 0
B31: Car Hire | D31: ='Assumption-(MedFit)'!$D94 -> 100000 | E31: =D31 -> 100000 | F31: =E31 -> 100000 | G31: =F31 -> 100000 | H31: =G31 -> 100000 | I31: =H31 -> 100000 | J31: =I31 -> 100000 | K31: =J31 -> 100000 | L31: =K31 -> 100000 | ... O31: =N31 -> 100000 | P31: =SUM(D31:O31) -> 1200000 | Q31: =P31*(1+'Assumption-(MedFit)'!E$74) -> 1380000 | R31: =Q31*(1+'Assumption-(MedFit)'!F$74) -> 1587000 | S31: =R31*(1+'Assumption-(MedFit)'!G$74) -> 1825050 | T31: =S31*(1+'Assumption-(MedFit)'!H$74) -> 2098807.5
B32: Security | D32: ='Assumption-(MedFit)'!$D95 -> 0 | E32: =D32 -> 0 | F32: =E32 -> 0 | G32: =F32 -> 0 | H32: =G32 -> 0 | I32: =H32 -> 0 | J32: =I32 -> 0 | K32: =J32 -> 0 | L32: =K32 -> 0 | ... O32: =N32 -> 0 | P32: =SUM(D32:O32) -> 0 | Q32: =P32*(1+'Assumption-(MedFit)'!E$74) -> 0 | R32: =Q32*(1+'Assumption-(MedFit)'!F$74) -> 0 | S32: =R32*(1+'Assumption-(MedFit)'!G$74) -> 0 | T32: =S32*(1+'Assumption-(MedFit)'!H$74) -> 0
B33: Local Govt Levies & Charges | D33: ='Assumption-(MedFit)'!$D96 -> 100000 | E33: =D33 -> 100000 | F33: =E33 -> 100000 | G33: =F33 -> 100000 | H33: =G33 -> 100000 | I33: =H33 -> 100000 | J33: =I33 -> 100000 | K33: =J33 -> 100000 | L33: =K33 -> 100000 | ... O33: =N33 -> 100000 | P33: =SUM(D33:O33) -> 1200000 | Q33: =P33*(1+'Assumption-(MedFit)'!E$74) -> 1380000 | R33: =Q33*(1+'Assumption-(MedFit)'!F$74) -> 1587000 | S33: =R33*(1+'Assumption-(MedFit)'!G$74) -> 1825050 | T33: =S33*(1+'Assumption-(MedFit)'!H$74) -> 2098807.5
B34: Insurance Expenses | D34: ='Assumption-(MedFit)'!$D97 -> 50000 | E34: =D34 -> 50000 | F34: =E34 -> 50000 | G34: =F34 -> 50000 | H34: =G34 -> 50000 | I34: =H34 -> 50000 | J34: =I34 -> 50000 | K34: =J34 -> 50000 | L34: =K34 -> 50000 | ... O34: =N34 -> 50000 | P34: =SUM(D34:O34) -> 600000 | Q34: =P34*(1+'Assumption-(MedFit)'!E$74) -> 690000 | R34: =Q34*(1+'Assumption-(MedFit)'!F$74) -> 793500 | S34: =R34*(1+'Assumption-(MedFit)'!G$74) -> 912525 | T34: =S34*(1+'Assumption-(MedFit)'!H$74) -> 1049403.7
B35: Contribution | D35: ='Assumption-(MedFit)'!D99 -> 311210.42 | E35: =D35 -> 311210.42 | F35: =E35 -> 311210.42 | G35: =F35 -> 311210.42 | H35: =G35 -> 311210.42 | I35: =H35 -> 311210.42 | J35: =I35 -> 311210.42 | K35: =J35 -> 311210.42 | L35: =K35 -> 311210.42 | ... O35: =N35 -> 311210.42 | P35: =SUM(D35:O35) -> 3734525 | Q35: =P35*(1+'Assumption-(MedFit)'!E$74) -> 4294703.7 | R35: =Q35*(1+'Assumption-(MedFit)'!F$74) -> 4938909.3 | S35: =R35*(1+'Assumption-(MedFit)'!G$74) -> 5679745.7 | T35: =S35*(1+'Assumption-(MedFit)'!H$74) -> 6531707.6
B37: Total Opex | D37: =SUM(D21:D35) -> 1425287.1 | E37: =SUM(E21:E35) -> 1425287.1 | F37: =SUM(F21:F35) -> 1425287.1 | G37: =SUM(G21:G35) -> 1425287.1 | H37: =SUM(H21:H35) -> 1425287.1 | I37: =SUM(I21:I35) -> 1425287.1 | J37: =SUM(J21:J35) -> 1425287.1 | K37: =SUM(K21:K35) -> 1425287.1 | ... T37: =SUM(T21:T35) -> 29914033
B39: EBITDA | D39: =D18-D37 -> -9111833.4 | E39: =E18-E37 -> -9111833.4 | F39: =F18-F37 -> -9111833.4 | G39: =G18-G37 -> -9111833.4 | H39: =H18-H37 -> -9111833.4 | I39: =I18-I37 -> -9111833.4 | J39: =J18-J37 -> -9111833.4 | K39: =K18-K37 -> -9111833.4 | ... T39: =T18-T37 -> 32064253
B41: Depreciation Expenses | D41: ='Assumption-(MedFit)'!D97 -> 50000 | E41: =D41 -> 50000 | F41: =E41 -> 50000 | G41: =F41 -> 50000 | H41: =G41 -> 50000 | I41: =H41 -> 50000 | J41: =I41 -> 50000 | K41: =J41 -> 50000 | L41: =K41 -> 50000 | ... O41: =N41 -> 50000 | P41: =SUM(D41:O41) -> 600000 | Q41: =P41*(1+'Assumption-(MedFit)'!E$74) -> 690000 | R41: =Q41*(1+'Assumption-(MedFit)'!F$74) -> 793500 | S41: =R41*(1+'Assumption-(MedFit)'!G$74) -> 912525 | T41: =S41*(1+'Assumption-(MedFit)'!H$74) -> 1049403.7
B43: Net Profit/(Loss) | D43: =D39-D41 -> -9161833.4 | E43: =E39-E41 -> -9161833.4 | F43: =F39-F41 -> -9161833.4 | G43: =G39-G41 -> -9161833.4 | H43: =H39-H41 -> -9161833.4 | I43: =I39-I41 -> -9161833.4 | J43: =J39-J41 -> -9161833.4 | K43: =K39-K41 -> -9161833.4 | ... T43: =T39-T41 -> 31014850
P44: =P43/P8 -> -1.4719677 | Q44: =Q43/Q8 -> -0.84153715 | R44: =R43/R8 -> -0.42017009 | S44: =S43/S8 -> -0.11440398 | T44: =T43/T8 -> 0.11449538
B45: Accumulated EBITDA | D45: =D43 -> -9161833.4 | E45: =D45+E43 -> -18323667 | F45: =E45+F43 -> -27485500 | G45: =F45+G43 -> -36647334 | H45: =G45+H43 -> -45809167 | I45: =H45+I43 -> -54971000 | J45: =I45+J43 -> -64132834 | K45: =J45+K43 -> -73294667 | L45: =K45+L43 -> -82456501 | ... O45: =N45+O43 -> -1.09942e+08 | P45: =P43 -> -1.09942e+08 | Q45: =P45+Q39 -> -1.9599167e+08 | R45: =Q45+R39 -> -2.5496341e+08 | S45: =R45+S39 -> -2.7650747e+08 | T45: =S45+T39 -> -2.4444322e+08
B47: Total Investment
B49: Pay back Balance | D49: =D45-D47 -> -9161833.4 | E49: =E45-E47 -> -18323667 | F49: =F45-F47 -> -27485500 | G49: =G45-G47 -> -36647334 | H49: =H45-H47 -> -45809167 | I49: =I45-I47 -> -54971000 | J49: =J45-J47 -> -64132834 | K49: =K45-K47 -> -73294667 | ... T49: =T45-T47 -> -2.4444322e+08
B51: Pay back Period | P51: =IF(P49>0,"1 Year"," ") | Q51: =IF(Q49>0,"2 Year"," ") | R51: =IF(R49>0,"3 Year"," ") | S51: =IF(S49>0,"4 Year"," ") | T51: =IF(T49>0,"5 Year"," ")

Sheet Computations-Outputs
A2: Computations-Outputs
D3: January | E3: February | F3: March | G3: April | H3: May | I3: June | J3: July | K3: August | L3: September | M3: October | N3: November | O3: December | P3: FY 1 | Q3: FY 2 | R3: FY 3 | S3: FY 4 | T3: FY 5
D4: NGN | E4: NGN | F4: NGN | G4: NGN | H4: NGN | I4: NGN | J4: NGN | K4: NGN | L4: NGN | M4: NGN | N4: NGN | O4: NGN | P4: NGN | Q4: NGN | R4: NGN | S4: NGN | T4: NGN
B5: Revenue
B6: ='Assumption-(MedFit)'!B5 -> Wellness Packages | D6: ='Assumption-(MedFit)'!D5 -> 0 | E6: ='Assumption-(MedFit)'!E5 -> 0 | F6: ='Assumption-(MedFit)'!F5 -> 0 | G6: ='Assumption-(MedFit)'!G5 -> 0 | H6: ='Assumption-(MedFit)'!H5 -> 0 | I6: ='Assumption-(MedFit)'!I5 -> 0 | J6: ='Assumption-(MedFit)'!J5 -> 0 | K6: ='Assumption-(MedFit)'!K5 -> 0 | ... O6: ='Assumption-(MedFit)'!O5 -> 0 | P6: =SUM(D6:O6) -> 0 | Q6: =P6*(1+'Assumption-(MedFit)'!E$73)*(1+'Assumption-(MedFit)'!E$76) -> 0 | R6: =Q6*(1+'Assumption-(MedFit)'!F$73)*(1+'Assumption-(MedFit)'!F$76) -> 0 | S6: =R6*(1+'Assumption-(MedFit)'!G$73)*(1+'Assumption-(MedFit)'!G$76) -> 0 | T6: =S6*(1+'Assumption-(MedFit)'!H$73)*(1+'Assumption-(MedFit)'!H$76) -> 0
B7: ='Assumption-(MedFit)'!B13 -> Occupational health- Project | D7: ='Assumption-(MedFit)'!D13 -> 6224208.3 | E7: ='Assumption-(MedFit)'!E13 -> 6224208.3 | F7: ='Assumption-(MedFit)'!F13 -> 6224208.3 | G7: ='Assumption-(MedFit)'!G13 -> 6224208.3 | H7: ='Assumption-(MedFit)'!H13 -> 6224208.3 | I7: ='Assumption-(MedFit)'!I13 -> 6224208.3 | J7: ='Assumption-(MedFit)'!J13 -> 6224208.3 | K7: ='Assumption-(MedFit)'!K13 -> 6224208.3 | ... O7: ='Assumption-(MedFit)'!O13 -> 6224208.3 | P7: =SUM(D7:O7) -> 74690500 | Q7: =P7*(1+'Assumption-(MedFit)'!E$73)*(1+'Assumption-(MedFit)'!E$76) -> 103072890 | R7: =Q7*(1+'Assumption-(MedFit)'!F$73)*(1+'Assumption-(MedFit)'!F$76) -> 1.4224059e+08 | S7: =R7*(1+'Assumption-(MedFit)'!G$73)*(1+'Assumption-(MedFit)'!G$76) -> 1.9629201e+08 | T7: =S7*(1+'Assumption-(MedFit)'!H$73)*(1+'Assumption-(MedFit)'!H$76) -> 2.7088298e+08
B9: Total Revenue | D9: =SUM(D6:D7) -> 6224208.3 | E9: =SUM(E6:E7) -> 6224208.3 | F9: =SUM(F6:F7) -> 6224208.3 | G9: =SUM(G6:G7) -> 6224208.3 | H9: =SUM(H6:H7) -> 6224208.3 | I9: =SUM(I6:I7) -> 6224208.3 | J9: =SUM(J6:J7) -> 6224208.3 | K9: =SUM(K6:K7) -> 6224208.3 | ... T9: =SUM(T6:T7) -> 2.7088298e+08
B11: Cost of Revenue
B12: Direct cost reagent | D12: ='Assumption-(MedFit)'!$C77*D$9 -> 1867262.5 | E12: ='Assumption-(MedFit)'!$C77*E$9 -> 1867262.5 | F12: ='Assumption-(MedFit)'!$C77*F$9 -> 1867262.5 | G12: ='Assumption-(MedFit)'!$C77*G$9 -> 1867262.5 | H12: ='Assumption-(MedFit)'!$C77*H$9 -> 1867262.5 | I12: ='Assumption-(MedFit)'!$C77*I$9 -> 1867262.5 | J12: ='Assumption-(MedFit)'!$C77*J$9 -> 1867262.5 | K12: ='Assumption-(MedFit)'!$C77*K$9 -> 1867262.5 | ... O12: ='Assumption-(MedFit)'!$C77*O$9 -> 1867262.5 | P12: =SUM(D12:O12) -> 22407150 | Q12: =P$9*(1+'Assumption-(MedFit)'!E$77)*'Assumption-(MedFit)'!$C$77 -> 24647865 | R12: =Q$9*(1+'Assumption-(MedFit)'!F$77)*'Assumption-(MedFit)'!$C$77 -> 33395616 | S12: =R$9*(1+'Assumption-(MedFit)'!G$77)*'Assumption-(MedFit)'!$C$77 -> 46085951 | T12: =S$9*(1+'Assumption-(MedFit)'!H$77)*'Assumption-(MedFit)'!$C$77 -> 62420860
B13: Other direct cost | D13: ='Assumption-(MedFit)'!$C80*D$9 -> 0 | E13: ='Assumption-(MedFit)'!$C80*E$9 -> 0 | F13: ='Assumption-(MedFit)'!$C80*F$9 -> 0 | G13: ='Assumption-(MedFit)'!$C80*G$9 -> 0 | H13: ='Assumption-(MedFit)'!$C80*H$9 -> 0 | I13: ='Assumption-(MedFit)'!$C80*I$9 -> 0 | J13: ='Assumption-(MedFit)'!$C80*J$9 -> 0 | K13: ='Assumption-(MedFit)'!$C80*K$9 -> 0 | ... O13: ='Assumption-(MedFit)'!$C80*O$9 -> 0 | P13: =SUM(D13:O13) -> 0 | Q13: =P$9*(1+'Assumption-(MedFit)'!$E80)*'Assumption-(MedFit)'!$C$80 -> 0 | R13: =Q$9*(1+'Assumption-(MedFit)'!$E80)*'Assumption-(MedFit)'!$C$80 -> 0 | S13: =R$9*(1+'Assumption-(MedFit)'!$E80)*'Assumption-(MedFit)'!$C$80 -> 0 | T13: =S$9*(1+'Assumption-(MedFit)'!$E80)*'Assumption-(MedFit)'!$C$80 -> 0
B15: Total Direct Cost | D15: =SUM(D12:D13) -> 1867262.5 | E15: =SUM(E12:E13) -> 1867262.5 | F15: =SUM(F12:F13) -> 1867262.5 | G15: =SUM(G12:G13) -> 1867262.5 | H15: =SUM(H12:H13) -> 1867262.5 | I15: =SUM(I12:I13) -> 1867262.5 | J15: =SUM(J12:J13) -> 1867262.5 | K15: =SUM(K12:K13) -> 1867262.5 | ... T15: =SUM(T12:T13) -> 62420860
B17: Gross Profit | D17: =D9-D15 -> 4356945.8 | E17: =E9-E15 -> 4356945.8 | F17: =F9-F15 -> 4356945.8 | G17: =G9-G15 -> 4356945.8 | H17: =H9-H15 -> 4356945.8 | I17: =I9-I15 -> 4356945.8 | J17: =J9-J15 -> 4356945.8 | K17: =K9-K15 -> 4356945.8 | ... T17: =T9-T15 -> 2.0846212e+08
B19: Operating expenses
B20: Staff cost | D20: ='Assumption-(MedFit)'!$D$84/12 -> 0 | E20: ='Assumption-(MedFit)'!$D$84/12 -> 0 | F20: ='Assumption-(MedFit)'!$D$84/12 -> 0 | G20: ='Assumption-(MedFit)'!$D$84/12 -> 0 | H20: ='Assumption-(MedFit)'!$D$84/12 -> 0 | I20: ='Assumption-(MedFit)'!$D$84/12 -> 0 | J20: ='Assumption-(MedFit)'!$D$84/12 -> 0 | K20: ='Assumption-(MedFit)'!$D$84/12 -> 0 | ... O20: ='Assumption-(MedFit)'!$D$84/12 -> 0 | P20: =SUM(D20:O20) -> 0 | Q20: =P20*(1+'Assumption-(MedFit)'!E$84) -> 0 | R20: =Q20*(1+'Assumption-(MedFit)'!F$84) -> 0 | S20: =R20*(1+'Assumption-(MedFit)'!G$84) -> 0 | T20: =S20*(1+'Assumption-(MedFit)'!H$84) -> 0
B21: Repair&Maintenance | D21: ='Computations-Outputs'!$D$9*'Assumption-(MedFit)'!$C$85 -> 62242.083 | E21: ='Computations-Outputs'!$D$9*'Assumption-(MedFit)'!$C$85 -> 62242.083 | F21: ='Computations-Outputs'!$D$9*'Assumption-(MedFit)'!$C$85 -> 62242.083 | G21: ='Computations-Outputs'!$D$9*'Assumption-(MedFit)'!$C$85 -> 62242.083 | H21: ='Computations-Outputs'!$D$9*'Assumption-(MedFit)'!$C$85 -> 62242.083 | I21: ='Computations-Outputs'!$D$9*'Assumption-(MedFit)'!$C$85 -> 62242.083 | J21: ='Computations-Outputs'!$D$9*'Assumption-(MedFit)'!$C$85 -> 62242.083 | K21: ='Computations-Outputs'!$D$9*'Assumption-(MedFit)'!$C$85 -> 62242.083 | ... O21: ='Computations-Outputs'!$D$9*'Assumption-(MedFit)'!$C$85 -> 62242.083 | P21: =SUM(D21:O21) -> 746905 | Q21: =P21*(1+'Assumption-(MedFit)'!E$74) -> 858940.75 | R21: =Q21*(1+'Assumption-(MedFit)'!F$74) -> 987781.86 | S21: =R21*(1+'Assumption-(MedFit)'!G$74) -> 1135949.1 | T21: =S21*(1+'Assumption-(MedFit)'!H$74) -> 1306341.5
B22: Bank Charges | D22: ='Assumption-(MedFit)'!$C$86*'Computations-Outputs'!$D$9 -> 3112.1042 | E22: ='Assumption-(MedFit)'!$C$86*'Computations-Outputs'!$D$9 -> 3112.1042 | F22: ='Assumption-(MedFit)'!$C$86*'Computations-Outputs'!$D$9 -> 3112.1042 | G22: ='Assumption-(MedFit)'!$C$86*'Computations-Outputs'!$D$9 -> 3112.1042 | H22: ='Assumption-(MedFit)'!$C$86*'Computations-Outputs'!$D$9 -> 3112.1042 | I22: ='Assumption-(MedFit)'!$C$86*'Computations-Outputs'!$D$9 -> 3112.1042 | J22: ='Assumption-(MedFit)'!$C$86*'Computations-Outputs'!$D$9 -> 3112.1042 | K22: ='Assumption-(MedFit)'!$C$86*'Computations-Outputs'!$D$9 -> 3112.1042 | ... O22: ='Assumption-(MedFit)'!$C$86*'Computations-Outputs'!$D$9 -> 3112.1042 | P22: =SUM(D22:O22) -> 37345.25 | Q22: =P22*(1+'Assumption-(MedFit)'!E$74) -> 42947.037 | R22: =Q22*(1+'Assumption-(MedFit)'!F$74) -> 49389.093 | S22: =R22*(1+'Assumption-(MedFit)'!G$74) -> 56797.457 | T22: =S22*(1+'Assumption-(MedFit)'!H$74) -> 65317.076
B23: Printing & Stationery | D23: ='Assumption-(MedFit)'!$D$87/12 -> 41666.667 | E23: ='Assumption-(MedFit)'!$D$87/12 -> 41666.667 | F23: ='Assumption-(MedFit)'!$D$87/12 -> 41666.667 | G23: ='Assumption-(MedFit)'!$D$87/12 -> 41666.667 | H23: ='Assumption-(MedFit)'!$D$87/12 -> 41666.667 | I23: ='Assumption-(MedFit)'!$D$87/12 -> 41666.667 | J23: ='Assumption-(MedFit)'!$D$87/12 -> 41666.667 | K23: ='Assumption-(MedFit)'!$D$87/12 -> 41666.667 | ... O23: ='Assumption-(MedFit)'!$D$87/12 -> 41666.667 | P23: =SUM(D23:O23) -> 500000 | Q23: =P23*(1+'Assumption-(MedFit)'!E$74) -> 575000 | R23: =Q23*(1+'Assumption-(MedFit)'!F$74) -> 661250 | S23: =R23*(1+'Assumption-(MedFit)'!G$74) -> 760437.5 | T23: =S23*(1+'Assumption-(MedFit)'!H$74) -> 874503.12
B24: Internet | D24: ='Assumption-(MedFit)'!$D89/12 -> 20833.333 | E24: ='Assumption-(MedFit)'!$D89/12 -> 20833.333 | F24: ='Assumption-(MedFit)'!$D89/12 -> 20833.333 | G24: ='Assumption-(MedFit)'!$D89/12 -> 20833.333 | H24: ='Assumption-(MedFit)'!$D89/12 -> 20833.333 | I24: ='Assumption-(MedFit)'!$D89/12 -> 20833.333 | J24: ='Assumption-(MedFit)'!$D89/12 -> 20833.333 | K24: ='Assumption-(MedFit)'!$D89/12 -> 20833.333 | ... O24: ='Assumption-(MedFit)'!$D89/12 -> 20833.333 | P24: =SUM(D24:O24) -> 250000 | Q24: =P24*(1+'Assumption-(MedFit)'!E$74) -> 287500 | R24: =Q24*(1+'Assumption-(MedFit)'!F$74) -> 330625 | S24: =R24*(1+'Assumption-(MedFit)'!G$74) -> 380218.75 | T24: =S24*(1+'Assumption-(MedFit)'!H$74) -> 437251.56
B25: Cleaning | D25: ='Assumption-(MedFit)'!$D91/12 -> 0 | E25: ='Assumption-(MedFit)'!$D91/12 -> 0 | F25: ='Assumption-(MedFit)'!$D91/12 -> 0 | G25: ='Assumption-(MedFit)'!$D91/12 -> 0 | H25: ='Assumption-(MedFit)'!$D91/12 -> 0 | I25: ='Assumption-(MedFit)'!$D91/12 -> 0 | J25: ='Assumption-(MedFit)'!$D91/12 -> 0 | K25: ='Assumption-(MedFit)'!$D91/12 -> 0 | ... O25: ='Assumption-(MedFit)'!$D91/12 -> 0 | P25: =SUM(D25:O25) -> 0 | Q25: =P25*(1+'Assumption-(MedFit)'!E$74) -> 0 | R25: =Q25*(1+'Assumption-(MedFit)'!F$74) -> 0 | S25: =R25*(1+'Assumption-(MedFit)'!G$74) -> 0 | T25: =S25*(1+'Assumption-(MedFit)'!H$74) -> 0
B26: Diesel & Fuel | D26: ='Assumption-(MedFit)'!$D92/12 -> 0 | E26: ='Assumption-(MedFit)'!$D92/12 -> 0 | F26: ='Assumption-(MedFit)'!$D92/12 -> 0 | G26: ='Assumption-(MedFit)'!$D92/12 -> 0 | H26: ='Assumption-(MedFit)'!$D92/12 -> 0 | I26: ='Assumption-(MedFit)'!$D92/12 -> 0 | J26: ='Assumption-(MedFit)'!$D92/12 -> 0 | K26: ='Assumption-(MedFit)'!$D92/12 -> 0 | ... O26: ='Assumption-(MedFit)'!$D92/12 -> 0 | P26: =SUM(D26:O26) -> 0 | Q26: =P26*(1+'Assumption-(MedFit)'!E$74) -> 0 | R26: =Q26*(1+'Assumption-(MedFit)'!F$74) -> 0 | S26: =R26*(1+'Assumption-(MedFit)'!G$74) -> 0 | T26: =S26*(1+'Assumption-(MedFit)'!H$74) -> 0
B27: Electricity | D27: ='Assumption-(MedFit)'!$D93/12 -> 0 | E27: ='Assumption-(MedFit)'!$D93/12 -> 0 | F27: ='Assumption-(MedFit)'!$D93/12 -> 0 | G27: ='Assumption-(MedFit)'!$D93/12 -> 0 | H27: ='Assumption-(MedFit)'!$D93/12 -> 0 | I27: ='Assumption-(MedFit)'!$D93/12 -> 0 | J27: ='Assumption-(MedFit)'!$D93/12 -> 0 | K27: ='Assumption-(MedFit)'!$D93/12 -> 0 | ... O27: ='Assumption-(MedFit)'!$D93/12 -> 0 | P27: =SUM(D27:O27) -> 0 | Q27: =P27*(1+'Assumption-(MedFit)'!E$74) -> 0 | R27: =Q27*(1+'Assumption-(MedFit)'!F$74) -> 0 | S27: =R27*(1+'Assumption-(MedFit)'!G$74) -> 0 | T27: =S27*(1+'Assumption-(MedFit)'!H$74) -> 0
B28: Security | D28: ='Assumption-(MedFit)'!$D95/12 -> 0 | E28: ='Assumption-(MedFit)'!$D95/12 -> 0 | F28: ='Assumption-(MedFit)'!$D95/12 -> 0 | G28: ='Assumption-(MedFit)'!$D95/12 -> 0 | H28: ='Assumption-(MedFit)'!$D95/12 -> 0 | I28: ='Assumption-(MedFit)'!$D95/12 -> 0 | J28: ='Assumption-(MedFit)'!$D95/12 -> 0 | K28: ='Assumption-(MedFit)'!$D95/12 -> 0 | ... O28: ='Assumption-(MedFit)'!$D95/12 -> 0 | P28: =SUM(D28:O28) -> 0 | Q28: =P28*(1+'Assumption-(MedFit)'!E$74) -> 0 | R28: =Q28*(1+'Assumption-(MedFit)'!F$74) -> 0 | S28: =R28*(1+'Assumption-(MedFit)'!G$74) -> 0 | T28: =S28*(1+'Assumption-(MedFit)'!H$74) -> 0
B29: Water | D29: ='Assumption-(MedFit)'!$D96/12 -> 8333.3333 | E29: ='Assumption-(MedFit)'!$D96/12 -> 8333.3333 | F29: ='Assumption-(MedFit)'!$D96/12 -> 8333.3333 | G29: ='Assumption-(MedFit)'!$D96/12 -> 8333.3333 | H29: ='Assumption-(MedFit)'!$D96/12 -> 8333.3333 | I29: ='Assumption-(MedFit)'!$D96/12 -> 8333.3333 | J29: ='Assumption-(MedFit)'!$D96/12 -> 8333.3333 | K29: ='Assumption-(MedFit)'!$D96/12 -> 8333.3333 | ... O29: ='Assumption-(MedFit)'!$D96/12 -> 8333.3333 | P29: =SUM(D29:O29) -> 100000 | Q29: =P29*(1+'Assumption-(MedFit)'!E$74) -> 115000 | R29: =Q29*(1+'Assumption-(MedFit)'!F$74) -> 132250 | S29: =R29*(1+'Assumption-(MedFit)'!G$74) -> 152087.5 | T29: =S29*(1+'Assumption-(MedFit)'!H$74) -> 174900.62
B31: Total Opex | D31: =SUM(D20:D29) -> 136187.52 | E31: =SUM(E20:E29) -> 136187.52 | F31: =SUM(F20:F29) -> 136187.52 | G31: =SUM(G20:G29) -> 136187.52 | H31: =SUM(H20:H29) -> 136187.52 | I31: =SUM(I20:I29) -> 136187.52 | J31: =SUM(J20:J29) -> 136187.52 | K31: =SUM(K20:K29) -> 136187.52 | ... T31: =SUM(T20:T29) -> 2858313.9
B33: EBITDA | D33: =D17-D31 -> 4220758.3 | E33: =E17-E31 -> 4220758.3 | F33: =F17-F31 -> 4220758.3 | G33: =G17-G31 -> 4220758.3 | H33: =H17-H31 -> 4220758.3 | I33: =I17-I31 -> 4220758.3 | J33: =J17-J31 -> 4220758.3 | K33: =K17-K31 -> 4220758.3 | ... T33: =T17-T31 -> 2.056038e+08
B35: Accumulated EBITDA | D35: =D33 -> 4220758.3 | E35: =D35+E33 -> 8441516.6 | F35: =E35+F33 -> 12662275 | G35: =F35+G33 -> 16883033 | H35: =G35+H33 -> 21103792 | I35: =H35+I33 -> 25324550 | J35: =I35+J33 -> 29545308 | K35: =J35+K33 -> 33766066 | L35: =K35+L33 -> 37986825 | ... O35: =N35+O33 -> 50649100 | P35: =P33 -> 50649100 | Q35: =P35+Q33 -> 1.2719474e+08 | R35: =Q35+R33 -> 2.3387841e+08 | S35: =R35+S33 -> 3.8159898e+08 | T35: =S35+T33 -> 5.8720279e+08
B37: Total Investment
B39: Pay back Balance | D39: =D35-D37 -> 4220758.3 | E39: =E35-E37 -> 8441516.6 | F39: =F35-F37 -> 12662275 | G39: =G35-G37 -> 16883033 | H39: =H35-H37 -> 21103792 | I39: =I35-I37 -> 25324550 | J39: =J35-J37 -> 29545308 | K39: =K35-K37 -> 33766066 | ... T39: =T35-T37 -> 5.8720279e+08
B41: Pay back Period | P41: =IF(P39>0,"1 Year"," ") -> 1 Year | Q41: =IF(Q39>0,"2 Year"," ") -> 2 Year | R41: =IF(R39>0,"3 Year"," ") -> 3 Year | S41: =IF(S39>0,"4 Year"," ") -> 4 Year | T41: =IF(T39>0,"5 Year"," ") -> 5 Year
